Workbook

Sheet Recomendaciones
C4: RECOMENDACIONES PARA LA PLANIFICACIÓN 2026-1
B5: 1 | C5: Verificar y validar la Planificación 2026-1 según los Planes de Estudio vigentes antes de iniciar el trabajo.
B6: 2 | C6: Copiar los apellidos y nombres del docente de la columna D de [Docentes] a la columna W de [Planificación 2026-1]
B7: 3 | C7: Se sugiere ubicar las horas de sus docentes TC para mantenerlos en el 2026-1 y si es posible aumentar más docentes de TP a TC.
B8: 4 | C8: Cada Director de Escuela debe considerar a sus docentes adscritos actualmente y GARANTIZAR un mínimo de 27 % de docentes TC por Escuela y por cada local (Chincha, Ica, Huaura)
B9: 5 | C9: Al realizar el procedimiento del punto 4, se irá totalizando la cantidad de horas lectivas del docente en la columna P de la hoja
B10: 6 | C10: Mantener los mismos responsables de unidades hasta 28 horas lectivas, en caso de considerar un cambio, debe ser coordinado y autorizado por su decanatura.
B11: 7 | C11: Los docentes que se asignen a cursos deben tener título Profesional, Bachiller, Maestría y cumplir con el Perfil del curso
B12: 8 | C12: El docente TC puede tener hasta 32 horas lectivas
B13: 9 | C13: El docente TP puede tener hasta 19 horas lectivas
B14: 10 | C14: El docente TP no pueden tener menos de 12 horas lectivas
B15: 11 | C15: Los Directores de Escuela pueden asignarse hasta 10 horas lectivas
B16: 12 | C16: Los Coordinadores Académicos pueden tener hasta 15 horas lectivas
... B28: 24 | C28: Los docentes TC presenciales obligatoriamente deben tener HORAS LECTIVAS y NO LECTIVAS presenciales.
B29: 25

Sheet Planes y aulas 2026
B2: RESUMEN PLANIFICACIÓN X CICLOS Y SECCIONES 2025-1 | K2: RESUMEN PLANIFICACIÓN X CICLOS Y SECCIONES 2025-2 | T2: RESUMEN PLANIFICACIÓN X CICLOS Y SECCIONES 2026-1
B4: SEMESTRE | C4: PLAN DE ESTUDIOS | D4: CODIGO DE PLAN | E4: LOCAL | F4: COD FACU | G4: PROGRAMA ACADÉMICO | H4: CICLO | I4: SECCIÓN | K4: SEMESTRE | L4: PLAN DE ESTUDIOS | M4: CODIGO DE PLAN | N4: LOCAL | O4: COD FACU | P4: PROGRAMA ACADÉMICO | Q4: CICLO | R4: SECCIÓN | T4: SEMESTRE | U4: PLAN DE ESTUDIOS | V4: CODIGO DE PLAN | W4: LOCAL | X4: COD FACU | Y4: PROGRAMA ACADÉMICO | Z4: CICLO | AA4: SECCIÓN
B5: 2025-1 | C5: RCU N° 344-2024-UAI-CU/P | D5: 20242 | E5: FILIAL | F5: I | G5: AF | H5: 3 | I5: A | K5: 2025-2 | L5: RCU Nº 354-2024-UAI-CU/P | M5: 20242 | N5: HUAURA | O5: FICA | P5: AE | Q5: 2 | R5: A | T5: 2025-2 | U5: RCU Nº 354-2024-UAI-CU/P | V5: 20242 | W5: HUAURA | X5: FICA | Y5: AE | Z5: =+Q5+1 -> 3 | AA5: A
B6: 2025-1 | C6: RCU N° 249-2019-UAI-CU/P | D6: 202011 | E6: FILIAL | F6: I | G6: AF | H6: 6 | I6: A | K6: 2025-2 | L6: RCU Nº 354-2024-UAI-CU/P | M6: 20242 | N6: HUAURA | O6: FICA | P6: AE | Q6: 3 | R6: A | T6: 2025-2 | U6: RCU Nº 354-2024-UAI-CU/P | V6: 20242 | W6: HUAURA | X6: FICA | Y6: AE | Z6: =+Q6+1 -> 4 | AA6: A
B7: 2025-1 | C7: RCU N° 249-2019-UAI-CU/P | D7: 202011 | E7: FILIAL | F7: I | G7: AF | H7: 7 | I7: A | K7: 2025-2 | L7: RCU Nº 354-2024-UAI-CU/P | M7: 20242 | N7: PRINCIPAL | O7: FICA | P7: AE | Q7: 2 | R7: A | T7: 2025-2 | U7: RCU Nº 354-2024-UAI-CU/P | V7: 20242 | W7: PRINCIPAL | X7: FICA | Y7: AE | Z7: =+Q7+1 -> 3 | AA7: A
B8: 2025-1 | C8: RCU N° 533-2024-UAI-CU/P | D8: 20251 | E8: FILIAL | F8: I | G8: CA | H8: 1 | I8: A | K8: 2025-2 | L8: RCU Nº 354-2024-UAI-CU/P | M8: 20242 | N8: PRINCIPAL | O8: FICA | P8: AE | Q8: 2 | R8: B | T8: 2025-2 | U8: RCU Nº 354-2024-UAI-CU/P | V8: 20242 | W8: PRINCIPAL | X8: FICA | Y8: AE | Z8: =+Q8+1 -> 3 | AA8: B
B9: 2025-1 | C9: RCU Nº 018-2021-UAI-CU/P | D9: 201722 | E9: FILIAL | F9: I | G9: CA | H9: 9 | I9: A | K9: 2025-2 | L9: RCU Nº 354-2024-UAI-CU/P | M9: 20242 | N9: PRINCIPAL | O9: FICA | P9: AE | Q9: 3 | R9: A | T9: 2025-2 | U9: RCU Nº 354-2024-UAI-CU/P | V9: 20242 | W9: PRINCIPAL | X9: FICA | Y9: AE | Z9: =+Q9+1 -> 4 | AA9: A
B10: 2025-1 | C10: RCU N° 348-2024-UAI-CU/P | D10: 20242 | E10: FILIAL | F10: I | G10: CA | H10: 9 | I10: B | K10: 2025-2 | L10: RCU Nº 354-2024-UAI-CU/P | M10: 20242 | N10: PRINCIPAL | O10: FICA | P10: AE | Q10: 3 | R10: B | T10: 2025-2 | U10: RCU Nº 354-2024-UAI-CU/P | V10: 20242 | W10: PRINCIPAL | X10: FICA | Y10: AE | Z10: =+Q10+1 -> 4 | AA10: B
B11: 2025-1 | C11: RCU N° 349-2024-UAI-CU/P | D11: 20242 | E11: FILIAL | F11: I | G11: DE | H11: 1 | I11: A | K11: 2025-2 | L11: RCU Nº 532-2024-UAI-CU/P | M11: 20251 | N11: PRINCIPAL | O11: FICA | P11: AE | Q11: 3 | R11: C | T11: 2025-2 | U11: RCU Nº 532-2024-UAI-CU/P | V11: 20251 | W11: PRINCIPAL | X11: FICA | Y11: AE | Z11: =+Q11+1 -> 4 | AA11: C
B12: 2025-1 | C12: RCU N° 349-2024-UAI-CU/P | D12: 20242 | E12: FILIAL | F12: I | G12: DE | H12: 1 | I12: B | K12: 2025-2 | L12: RCU Nº 354-2024-UAI-CU/P | M12: 20242 | N12: PRINCIPAL | O12: FICA | P12: AE | Q12: 4 | R12: A | T12: 2025-2 | U12: RCU Nº 354-2024-UAI-CU/P | V12: 20242 | W12: PRINCIPAL | X12: FICA | Y12: AE | Z12: =+Q12+1 -> 5 | AA12: A
B13: 2025-1 | C13: RCU N° 349-2024-UAI-CU/P | D13: 20242 | E13: FILIAL | F13: I | G13: DE | H13: 2 | I13: A | K13: 2025-2 | L13: RCU Nº 344-2024-UAI-CU/P | M13: 20242 | N13: FILIAL | O13: FICA | P13: AF | Q13: 5 | R13: A | T13: 2025-2 | U13: RCU Nº 344-2024-UAI-CU/P | V13: 20242 | W13: FILIAL | X13: FICA | Y13: AF | Z13: =+Q13+1 -> 6 | AA13: A
B14: 2025-1 | C14: RCU N° 349-2024-UAI-CU/P | D14: 20242 | E14: FILIAL | F14: I | G14: DE | H14: 3 | I14: A | K14: 2025-2 | L14: RCU Nº 249-2019-UAI-CU/P | M14: 202011 | N14: FILIAL | O14: FICA | P14: AF | Q14: 8 | R14: A | T14: 2025-2 | U14: RCU Nº 249-2019-UAI-CU/P | V14: 202011 | W14: FILIAL | X14: FICA | Y14: AF | Z14: =+Q14+1 -> 9 | AA14: A
B15: 2025-1 | C15: RCU N° 349-2024-UAI-CU/P | D15: 20242 | E15: FILIAL | F15: I | G15: DE | H15: 3 | I15: B | K15: 2025-2 | L15: RCU Nº 249-2019-UAI-CU/P | M15: 202011 | N15: FILIAL | O15: FICA | P15: AF | Q15: 9 | R15: A | T15: 2025-2 | U15: RCU Nº 249-2019-UAI-CU/P | V15: 202011 | W15: FILIAL | X15: FICA | Y15: AF | Z15: =+Q15+1 -> 10 | AA15: A
B16: 2025-1 | C16: RCU N° 032-2023-UAI-CU/P | D16: 202312 | E16: FILIAL | F16: I | G16: DE | H16: 5 | I16: A | K16: 2025-2 | L16: RCU Nº 344-2024-UAI-CU/P | M16: 20242 | N16: PRINCIPAL | O16: FICA | P16: AF | Q16: 5 | R16: A | T16: 2025-2 | U16: RCU Nº 344-2024-UAI-CU/P | V16: 20242 | W16: PRINCIPAL | X16: FICA | Y16: AF | Z16: =+Q16+1 -> 6 | AA16: A
... B24: 2025-1 | C24: RCU N° 032-2023-UAI-CU/P | D24: 202312 | E24: FILIAL | F24: I | G24: DE | H24: 11 | I24: A | K24: 2025-2 | L24: RCU Nº 344-2024-UAI-CU/P | M24: 20242 | N24: PRINCIPAL | O24: FICA | P24: AF | Q24: 9 | R24: B | T24: 2025-2 | U24: RCU Nº 344-2024-UAI-CU/P | V24: 20242 | W24: PRINCIPAL | X24: FICA | Y24: AF | Z24: =+Q24+1 -> 10 | AA24: B
B25: 2025-1 | C25: RCU Nº 353-2024-UAI-CU/P | D25: 20242 | E25: FILIAL | F25: S | G25: EN | H25: 1 | I25: A | K25: 2025-2 | L25: RCU Nº 249-2019-UAI-CU/P | M25: 202011 | N25: PRINCIPAL | O25: FICA | P25: AF | Q25: 10 | R25: A | T25: 2025-2 | U25: RCU Nº 249-2019-UAI-CU/P | V25: 202011 | W25: PRINCIPAL | X25: FICA | Y25: AF
B26: 2025-1 | C26: RCU Nº 353-2024-UAI-CU/P | D26: 20242 | E26: FILIAL | F26: S | G26: EN | H26: 1 | I26: B | K26: 2025-2 | L26: RCU Nº 344-2024-UAI-CU/P | M26: 20242 | N26: PRINCIPAL | O26: FICA | P26: AF | Q26: 10 | R26: B | T26: 2025-2 | U26: RCU Nº 344-2024-UAI-CU/P | V26: 20242 | W26: PRINCIPAL | X26: FICA | Y26: AF
B27: 2025-1 | C27: RCU Nº 353-2024-UAI-CU/P | D27: 20242 | E27: FILIAL | F27: S | G27: EN | H27: 1 | I27: C | K27: 2025-2 | L27: RCU Nº 398-2024-UAI-CU/P | M27: 20251 | N27: PRINCIPAL | O27: FICA | P27: AR | Q27: 2 | R27: A | T27: 2025-2 | U27: RCU Nº 398-2024-UAI-CU/P | V27: 20251 | W27: PRINCIPAL | X27: FICA | Y27: AR | Z27: =+Q27+1 -> 3 | AA27: A
B28: 2025-1 | C28: RCU Nº 353-2024-UAI-CU/P | D28: 20242 | E28: FILIAL | F28: S | G28: EN | H28: 1 | I28: D | K28: 2025-2 | L28: RCU Nº 398-2024-UAI-CU/P | M28: 20251 | N28: PRINCIPAL | O28: FICA | P28: AR | Q28: 3 | R28: A | T28: 2025-2 | U28: RCU Nº 398-2024-UAI-CU/P | V28: 20251 | W28: PRINCIPAL | X28: FICA | Y28: AR | Z28: =+Q28+1 -> 4 | AA28: A
B29: 2025-1 | C29: RCU Nº 353-2024-UAI-CU/P | D29: 20242 | E29: FILIAL | F29: S | G29: EN | H29: 2 | I29: A | K29: 2025-2 | L29: RCU Nº 533-2024-UAI-CU/P | M29: 20251 | N29: FILIAL | O29: FICA | P29: CA | Q29: 2 | R29: A | T29: 2025-2 | U29: RCU Nº 533-2024-UAI-CU/P | V29: 20251 | W29: FILIAL | X29: FICA | Y29: CA | Z29: =+Q29+1 -> 3 | AA29: A
B30: 2025-1 | C30: RCU Nº 353-2024-UAI-CU/P | D30: 20242 | E30: FILIAL | F30: S | G30: EN | H30: 2 | I30: B | K30: 2025-2 | L30: RCU Nº 533-2024-UAI-CU/P | M30: 20251 | N30: FILIAL | O30: FICA | P30: CA | Q30: 3 | R30: A | T30: 2025-2 | U30: RCU Nº 533-2024-UAI-CU/P | V30: 20251 | W30: FILIAL | X30: FICA | Y30: CA | Z30: =+Q30+1 -> 4 | AA30: A
B31: 2025-1 | C31: RCU Nº 353-2024-UAI-CU/P | D31: 20242 | E31: FILIAL | F31: S | G31: EN | H31: 3 | I31: A | K31: 2025-2 | L31: RCU Nº 348-2024-UAI-CU/P | M31: 20242 | N31: FILIAL | O31: FICA | P31: CA | Q31: 8 | R31: A | T31: 2025-2 | U31: RCU Nº 348-2024-UAI-CU/P | V31: 20242 | W31: FILIAL | X31: FICA | Y31: CA | Z31: =+Q31+1 -> 9 | AA31: A
B32: 2025-1 | C32: RCU Nº 353-2024-UAI-CU/P | D32: 20242 | E32: FILIAL | F32: S | G32: EN | H32: 3 | I32: B | K32: 2025-2 | L32: RCU Nº 349-2024-UAI-CU/P | M32: 20242 | N32: FILIAL | O32: FICA | P32: DE | Q32: 2 | R32: A | T32: 2025-2 | U32: RCU Nº 349-2024-UAI-CU/P | V32: 20242 | W32: FILIAL | X32: FICA | Y32: DE | Z32: =+Q32+1 -> 3 | AA32: A
B33: 2025-1 | C33: RCU Nº 353-2024-UAI-CU/P | D33: 20242 | E33: FILIAL | F33: S | G33: EN | H33: 3 | I33: C | K33: 2025-2 | L33: RCU Nº 349-2024-UAI-CU/P | M33: 20242 | N33: FILIAL | O33: FICA | P33: DE | Q33: 2 | R33: B | T33: 2025-2 | U33: RCU Nº 349-2024-UAI-CU/P | V33: 20242 | W33: FILIAL | X33: FICA | Y33: DE | Z33: =+Q33+1 -> 3 | AA33: B
B34: 2025-1 | C34: RCU Nº 353-2024-UAI-CU/P | D34: 20242 | E34: FILIAL | F34: S | G34: EN | H34: 3 | I34: D | K34: 2025-2 | L34: RCU Nº 349-2024-UAI-CU/P | M34: 20242 | N34: FILIAL | O34: FICA | P34: DE | Q34: 3 | R34: A | T34: 2025-2 | U34: RCU Nº 349-2024-UAI-CU/P | V34: 20242 | W34: FILIAL | X34: FICA | Y34: DE | Z34: =+Q34+1 -> 4 | AA34: A
B35: 2025-1 | C35: RCU Nº 353-2024-UAI-CU/P | D35: 20242 | E35: FILIAL | F35: S | G35: EN | H35: 3 | I35: X | K35: 2025-2 | L35: RCU Nº 349-2024-UAI-CU/P | M35: 20242 | N35: FILIAL | O35: FICA | P35: DE | Q35: 3 | R35: B | T35: 2025-2 | U35: RCU Nº 349-2024-UAI-CU/P | V35: 20242 | W35: FILIAL | X35: FICA | Y35: DE | Z35: =+Q35+1 -> 4 | AA35: B
B36: 2025-1 | C36: RCU Nº 353-2024-UAI-CU/P | D36: 20242 | E36: FILIAL | F36: S | G36: EN | H36: 3 | I36: Y | K36: 2025-2 | L36: RCU Nº 349-2024-UAI-CU/P | M36: 20242 | N36: FILIAL | O36: FICA | P36: DE | Q36: 4 | R36: A | T36: 2025-2 | U36: RCU Nº 349-2024-UAI-CU/P | V36: 20242 | W36: FILIAL | X36: FICA | Y36: DE | Z36: =+Q36+1 -> 5 | AA36: A
B37: 2025-1 | C37: RCU Nº 353-2024-UAI-CU/P | D37: 20242 | E37: FILIAL | F37: S | G37: EN | H37: 3 | I37: Z | K37: 2025-2 | L37: RCU Nº 349-2024-UAI-CU/P | M37: 20242 | N37: FILIAL | O37: FICA | P37: DE | Q37: 5 | R37: A | T37: 2025-2 | U37: RCU Nº 349-2024-UAI-CU/P | V37: 20242 | W37: FILIAL | X37: FICA | Y37: DE | Z37: =+Q37+1 -> 6 | AA37: A
B38: 2025-1 | C38: RCU Nº 353-2024-UAI-CU/P | D38: 20242 | E38: FILIAL | F38: S | G38: EN | H38: 4 | I38: A | K38: 2025-2 | L38: RCU Nº 349-2024-UAI-CU/P | M38: 20242 | N38: FILIAL | O38: FICA | P38: DE | Q38: 5 | R38: B | T38: 2025-2 | U38: RCU Nº 349-2024-UAI-CU/P | V38: 20242 | W38: FILIAL | X38: FICA | Y38: DE | Z38: =+Q38+1 -> 6 | AA38: B
... B46: 2025-1 | C46: RCU Nº 353-2024-UAI-CU/P | D46: 20242 | E46: FILIAL | F46: S | G46: EN | H46: 5 | I46: D | K46: 2025-2 | L46: RCU Nº 032-2023-UAI-CU/P | M46: 202312 | N46: FILIAL | O46: FICA | P46: DE | Q46: 11 | R46: B | T46: 2025-2 | U46: RCU Nº 032-2023-UAI-CU/P | V46: 202312 | W46: FILIAL | X46: FICA | Y46: DE | Z46: =+Q46+1 -> 12 | AA46: B
B47: 2025-1 | C47: RCU Nº249-2019-UAI-CU/P | D47: 202011 | E47: FILIAL | F47: S | G47: EN | H47: 6 | I47: A | K47: 2025-2 | L47: RCU Nº 032-2023-UAI-CU/P | M47: 202312 | N47: FILIAL | O47: FICA | P47: DE | Q47: 12 | R47: A | T47: 2025-2 | U47: RCU Nº 032-2023-UAI-CU/P | V47: 202312 | W47: FILIAL | X47: FICA | Y47: DE
B48: 2025-1 | C48: RCU Nº249-2019-UAI-CU/P | D48: 202011 | E48: FILIAL | F48: S | G48: EN | H48: 6 | I48: B | K48: 2025-2 | L48: RCU Nº 349-2024-UAI-CU/P | M48: 20242 | N48: HUAURA | O48: FICA | P48: DE | Q48: 2 | R48: A | T48: 2025-2 | U48: RCU Nº 349-2024-UAI-CU/P | V48: 20242 | W48: HUAURA | X48: FICA | Y48: DE | Z48: =+Q48+1 -> 3 | AA48: A
B49: 2025-1 | C49: RCU Nº249-2019-UAI-CU/P | D49: 202011 | E49: FILIAL | F49: S | G49: EN | H49: 6 | I49: C | K49: 2025-2 | L49: RCU Nº 349-2024-UAI-CU/P | M49: 20242 | N49: HUAURA | O49: FICA | P49: DE | Q49: 2 | R49: B | T49: 2025-2 | U49: RCU Nº 349-2024-UAI-CU/P | V49: 20242 | W49: HUAURA | X49: FICA | Y49: DE | Z49: =+Q49+1 -> 3 | AA49: B
B50: 2025-1 | C50: RCU Nº249-2019-UAI-CU/P | D50: 202011 | E50: FILIAL | F50: S | G50: EN | H50: 6 | I50: D | K50: 2025-2 | L50: RCU Nº 349-2024-UAI-CU/P | M50: 20242 | N50: HUAURA | O50: FICA | P50: DE | Q50: 3 | R50: A | T50: 2025-2 | U50: RCU Nº 349-2024-UAI-CU/P | V50: 20242 | W50: HUAURA | X50: FICA | Y50: DE | Z50: =+Q50+1 -> 4 | AA50: A
B51: 2025-1 | C51: RCU Nº249-2019-UAI-CU/P | D51: 202011 | E51: FILIAL | F51: S | G51: EN | H51: 7 | I51: A | K51: 2025-2 | L51: RCU Nº 349-2024-UAI-CU/P | M51: 20242 | N51: HUAURA | O51: FICA | P51: DE | Q51: 3 | R51: B | T51: 2025-2 | U51: RCU Nº 349-2024-UAI-CU/P | V51: 20242 | W51: HUAURA | X51: FICA | Y51: DE | Z51: =+Q51+1 -> 4 | AA51: B
B52: 2025-1 | C52: RCU Nº249-2019-UAI-CU/P | D52: 202011 | E52: FILIAL | F52: S | G52: EN | H52: 7 | I52: B | K52: 2025-2 | L52: RCU Nº 349-2024-UAI-CU/P | M52: 20242 | N52: HUAURA | O52: FICA | P52: DE | Q52: 3 | R52: C | T52: 2025-2 | U52: RCU Nº 349-2024-UAI-CU/P | V52: 20242 | W52: HUAURA | X52: FICA | Y52: DE | Z52: =+Q52+1 -> 4 | AA52: C
B53: 2025-1 | C53: RCU Nº249-2019-UAI-CU/P | D53: 202011 | E53: FILIAL | F53: S | G53: EN | H53: 7 | I53: C | K53: 2025-2 | L53: RCU Nº 349-2024-UAI-CU/P | M53: 20242 | N53: PRINCIPAL | O53: FICA | P53: DE | Q53: 2 | R53: A | T53: 2025-2 | U53: RCU Nº 349-2024-UAI-CU/P | V53: 20242 | W53: PRINCIPAL | X53: FICA | Y53: DE | Z53: =+Q53+1 -> 3 | AA53: A
B54: 2025-1 | C54: RCU Nº249-2019-UAI-CU/P | D54: 202011 | E54: FILIAL | F54: S | G54: EN | H54: 8 | I54: A | K54: 2025-2 | L54: RCU Nº 349-2024-UAI-CU/P | M54: 20242 | N54: PRINCIPAL | O54: FICA | P54: DE | Q54: 2 | R54: B | T54: 2025-2 | U54: RCU Nº 349-2024-UAI-CU/P | V54: 20242 | W54: PRINCIPAL | X54: FICA | Y54: DE | Z54: =+Q54+1 -> 3 | AA54: B
B55: 2025-1 | C55: RCU Nº249-2019-UAI-CU/P | D55: 202011 | E55: FILIAL | F55: S | G55: EN | H55: 8 | I55: B | K55: 2025-2 | L55: RCU Nº 534-2024-UAI-CU/P | M55: 20251 | N55: PRINCIPAL | O55: FICA | P55: DE | Q55: 2 | R55: C | T55: 2025-2 | U55: RCU Nº 534-2024-UAI-CU/P | V55: 20251 | W55: PRINCIPAL | X55: FICA | Y55: DE | Z55: =+Q55+1 -> 3 | AA55: C
B56: 2025-1 | C56: RCU Nº249-2019-UAI-CU/P | D56: 202011 | E56: FILIAL | F56: S | G56: EN | H56: 9 | I56: A | K56: 2025-2 | L56: RCU Nº 534-2024-UAI-CU/P | M56: 20251 | N56: PRINCIPAL | O56: FICA | P56: DE | Q56: 2 | R56: D | T56: 2025-2 | U56: RCU Nº 534-2024-UAI-CU/P | V56: 20251 | W56: PRINCIPAL | X56: FICA | Y56: DE | Z56: =+Q56+1 -> 3 | AA56: D
...

Sheet EDITABLE
L2: SEDE | AC2: FILIAL | AT2: SUNAMPE | BK2: HUAURA | CB2: HORAS POR CARRERA | CR2: HORAS POR CARRERA EEGG | EF2: EEGG
B3: N° | C3: DOCENTES UAI | D3: DNI | E3: HORAS | F3: DEDICACIÓN | G3: CONDICIÓN | H3: LOCAL 2025-2 | I3: PROGRAMA ACADÉMICO 2025-2 | J3: LOCAL 2026-1 | K3: PROGRAMA ACADÉMICO 2026-1 | L3: ADM | M3: ENF | N3: ING SIS | O3: PS | P3: IND AL | Q3: IND | R3: CONT | S3: DE | T3: OBS | U3: MEDICINA | V3: ING CIVIL | W3: ARQUI | X3: LAB. CLIN | Y3: TERAPIA FIS. | Z3: TERAPIA LEN. | AA3: ADM. EMP | AB3: OPTOM. | AC3: ADM | AD3: ENF | AE3: ING SIS | AF3: PS | AG3: IND AL | AH3: IND | AI3: CONT | AJ3: DE | AK3: OBS | AL3: MEDICINA | AM3: ING CIVIL | AN3: ARQUI | AO3: LAB. CLIN | AP3: TERAPIA FIS. | AQ3: TERAPIA LEN. | AR3: ADM. EMP | AS3: OPTOM. | AT3: ADM | AU3: ENF | AV3: ING SIS | AW3: PS | AX3: IND AL | AY3: IND | AZ3: CONT | BA3: DE | BB3: OBS | BC3: MEDICINA | BD3: ING CIVIL | BE3: ARQUI | BF3: LAB. CLIN | BG3: TERAPIA FIS. | BH3: TERAPIA LEN. | BI3: ADM. EMP | BJ3: OPTOM. | BK3: ADM | BL3: ENF | BM3: ING SIS | BN3: PS | BO3: IND AL | BP3: IND | BQ3: CONT | BR3: DE | BS3: OBS | BT3: MEDICINA | BU3: ING CIVIL | BV3: ARQUI | BW3: LAB. CLIN | BX3: TERAPIA FIS. | BY3: TERAPIA LEN. | BZ3: ADM. EMP | CA3: OPTOM. | CB3: ADMINISTRACIÓN Y FINANZAS | CC3: ENFERMERÍA | CD3: INGENIERÍA DE SISTEMAS | CE3: PSICOLOGÍA | CF3: INGENIERÍA INDUSTRIAL | CG3: CONTABILIDAD | CH3: DERECHO | CI3: OBSTETRICIA | CJ3: MEDICINA HUMANA | CK3: INGENIERÍA CIVIL | CL3: ARQUITECTURA | CM3: ADMINISTRACIÓN DE EMPRESAS | CN3: TECNOLOGÍA MEDICA EN LABORATORIO CLÍNICO Y ANATOMÍA PATOLÓGICA | CO3: TECNOLOGÍA MEDICA EN TERAPIA FÍSICA Y REHABILITACIÓN | CP3: TECNOLOGÍA MEDICA EN TERAPIA DE LENGUAJE | CQ3: TECNOLOGÍA MEDICA EN OPTOMETRÍA | CR3: ADMINISTRACIÓN Y FINANZAS - EEGG | CS3: ENFERMERÍA - EEGG | CT3: INGENIERÍA DE SISTEMAS - EEGG | CU3: PSICOLOGÍA - EEGG | CV3: INGENIERÍA INDUSTRIAL - EEGG | CW3: CONTABILIDAD - EEGG | CX3: DERECHO - EEGG | CY3: OBSTETRICIA - EEGG | CZ3: MEDICINA HUMANA - EEGG | DA3: INGENIERÍA CIVIL - EEGG | DB3: ARQUITECTURA - EEGG | DC3: ADMINISTRACIÓN DE EMPRESAS - EEGG | DD3: TECNOLOGÍA MEDICA EN LABORATORIO CLÍNICO Y ANATOMÍA PATOLÓGICA - EEGG | DE3: TECNOLOGÍA MEDICA EN TERAPIA FÍSICA Y REHABILITACIÓN - EEGG | DF3: TECNOLOGÍA MEDICA EN TERAPIA DE LENGUAJE - EEGG | DG3: TECNOLOGÍA MEDICA EN OPTOMETRÍA - EEGG | DH3: SEDE | DI3: HORAS VIRTUAL | DJ3: HORAS PRESENCIAL | DK3: HORAS HIBRIDAS | DL3: FILIAL | DM3: HORAS VIRTUAL | DN3: HORAS PRESENCIAL | DO3: HORAS HIBRIDAS | DP3: SUNAMPE | DQ3: HORAS VIRTUAL | DR3: HORAS PRESENCIAL | DS3: HUAURA | DT3: HORAS VIRTUAL | DU3: HORAS PRESENCIAL | DV3: SEDE-VIRTUAL | DW3: SEDE-PRESENCIAL | DX3: SUNAMPE-VIRTUAL | DY3: SUNAMPE-PRESENCIAL | DZ3: FILIAL-VIRTUAL | EA3: FILIAL-PRESENCIAL | EB3: PORUMA-VIRTUAL | EC3: PORUMA-PRESENCIAL | ED3: HUAURA-VIRTUAL | EE3: HUAURA-PRESENCIAL | EF3: SEDE-VIRTUAL | EG3: SEDE-PRESENCIAL | EH3: SUNAMPE-VIRTUAL | EI3: SUNAMPE-PRESENCIAL | EJ3: FILIAL-VIRTUAL | EK3: FILIAL-PRESENCIAL | EL3: PORUMA-VIRTUAL | EM3: PORUMA-PRESENCIAL | EN3: HUAURA-VIRTUAL | EO3: HUAURA-PRESENCIAL | EP3: FILIAL | EQ3: HUAURA | ER3: PORUMA | ES3: SEDE | ET3: SUNAMPE | EX3: VIRTUAL | EY3: PRESENCIAL
B4: 1 | C4: ACHARTE CHAMPI WALTER JESUS | D4: 45549528 | E4: =SUMIF('Planificación 2026-1'!X:X,C4,'Planificación 2026-1'!S:S) -> 40 | F4: TC | G4: RENOVACIÓN | H4: SEDE | I4: ENFERMERÍA | J4: SEDE | K4: ENFERMERÍA | L4: =IF(SUM(COUNTIFS('Planificación 2026-1'!F:F,"PRINCIPAL",'Planificación 2026-1'!X:X,C4,'Planificación 2026-1'!H:H,"AF"))>0,"P01"," ") | M4: =IF(SUM(COUNTIFS('Planificación 2026-1'!F:F,"PRINCIPAL",'Planificación 2026-1'!X:X,C4,'Planificación 2026-1'!H:H,"EN"))>0,"P02"," ") -> P02 | N4: =IF(SUM(COUNTIFS('Planificación 2026-1'!F:F,"PRINCIPAL",'Planificación 2026-1'!X:X,C4,'Planificación 2026-1'!H:H,"IS"))>0,"P03"," ") | O4: =IF(SUM(COUNTIFS('Planificación 2026-1'!F:F,"PRINCIPAL",'Planificación 2026-1'!X:X,C4,'Planificación 2026-1'!H:H,"PS"))>0,"P04"," ") | Q4: =IF(SUM(COUNTIFS('Planificación 2026-1'!F:F,"PRINCIPAL",'Planificación 2026-1'!X:X,C4,'Planificación 2026-1'!H:H,"IN"))>0,"P06"," ") | R4: =IF(SUM(COUNTIFS('Planificación 2026-1'!F:F,"PRINCIPAL",'Planificación 2026-1'!X:X,C4,'Planificación 2026-1'!H:H,"CA"))>0,"P07"," ") | S4: =IF(SUM(COUNTIFS('Planificación 2026-1'!F:F,"PRINCIPAL",'Planificación 2026-1'!X:X,C4,'Planificación 2026-1'!H:H,"DE"))>0,"P08"," ") | T4: =IF(SUM(COUNTIFS('Planificación 2026-1'!F:F,"PRINCIPAL",'Planificación 2026-1'!X:X,C4,'Planificación 2026-1'!H:H,"OB"))>0,"P09"," ") | U4: =IF(SUM(COUNTIFS('Planificación 2026-1'!F:F,"PRINCIPAL",'Planificación 2026-1'!X:X,C4,'Planificación 2026-1'!H:H,"MH"))>0,"P31"," ") | V4: =IF(SUM(COUNTIFS('Planificación 2026-1'!F:F,"PRINCIPAL",'Planificación 2026-1'!X:X,C4,'Planificación 2026-1'!H:H,"IC"))>0,"P32"," ") | W4: =IF(SUM(COUNTIFS('Planificación 2026-1'!F:F,"PRINCIPAL",'Planificación 2026-1'!X:X,C4,'Planificación 2026-1'!H:H,"AR"))>0,"P34"," ") | X4: =IF(SUM(COUNTIFS('Planificación 2026-1'!F:F,"PRINCIPAL",'Planificación 2026-1'!X:X,C4,'Planificación 2026-1'!H:H,"T1"))>0,"P35"," ") | Y4: =IF(SUM(COUNTIFS('Planificación 2026-1'!F:F,"PRINCIPAL",'Planificación 2026-1'!X:X,C4,'Planificación 2026-1'!H:H,"T3"))>0,"P36"," ") | Z4: =IF(SUM(COUNTIFS('Planificación 2026-1'!F:F,"PRINCIPAL",'Planificación 2026-1'!X:X,C4,'Planificación 2026-1'!H:H,"T2"))>0,"P37"," ") | AA4: =IF(SUM(COUNTIFS('Planificación 2026-1'!F:F,"PRINCIPAL",'Planificación 2026-1'!X:X,C4,'Planificación 2026-1'!H:H,"AE"))>0,"P38"," ") | AB4: =IF(SUM(COUNTIFS('Planificación 2026-1'!F:F,"PRINCIPAL",'Planificación 2026-1'!X:X,C4,'Planificación 2026-1'!H:H,"T4"))>0,"P55"," ") | AC4: =IF(SUM(COUNTIFS('Planificación 2026-1'!F:F,"FILIAL",'Planificación 2026-1'!X:X,C4,'Planificación 2026-1'!H:H,"AF"))>0," P01"," ") | AD4: =IF(SUM(COUNTIFS('Planificación 2026-1'!F:F,"FILIAL",'Planificación 2026-1'!X:X,C4,'Planificación 2026-1'!H:H,"EN"))>0,"P02"," ") -> P02 | AE4: =IF(SUM(COUNTIFS('Planificación 2026-1'!F:F,"FILIAL",'Planificación 2026-1'!X:X,C4,'Planificación 2026-1'!H:H,"IS"))>0,"P03"," ") | AF4: =IF(SUM(COUNTIFS('Planificación 2026-1'!F:F,"FILIAL",'Planificación 2026-1'!X:X,C4,'Planificación 2026-1'!H:H,"PS"))>0,"P04"," ") | AH4: =IF(SUM(COUNTIFS('Planificación 2026-1'!F:F,"FILIAL",'Planificación 2026-1'!X:X,C4,'Planificación 2026-1'!H:H,"IN"))>0,"P06"," ") | AI4: =IF(SUM(COUNTIFS('Planificación 2026-1'!F:F,"FILIAL",'Planificación 2026-1'!X:X,C4,'Planificación 2026-1'!H:H,"CA"))>0,"P07"," ") | AJ4: =IF(SUM(COUNTIFS('Planificación 2026-1'!F:F,"FILIAL",'Planificación 2026-1'!X:X,C4,'Planificación 2026-1'!H:H,"DE"))>0,"P08"," ") | AK4: =IF(SUM(COUNTIFS('Planificación 2026-1'!F:F,"FILIAL",'Planificación 2026-1'!X:X,C4,'Planificación 2026-1'!H:H,"OB"))>0,"P09"," ") | AL4: =IF(SUM(COUNTIFS('Planificación 2026-1'!F:F,"FILIAL",'Planificación 2026-1'!X:X,C4,'Planificación 2026-1'!H:H,"MH"))>0,"P31"," ") | AM4: =IF(SUM(COUNTIFS('Planificación 2026-1'!F:F,"FILIAL",'Planificación 2026-1'!X:X,C4,'Planificación 2026-1'!H:H,"IC"))>0,"P32"," ") | AN4: =IF(SUM(COUNTIFS('Planificación 2026-1'!F:F,"FILIAL",'Planificación 2026-1'!X:X,C4,'Planificación 2026-1'!H:H,"AR"))>0,"P34"," ") | AO4: =IF(SUM(COUNTIFS('Planificación 2026-1'!F:F,"FILIAL",'Planificación 2026-1'!X:X,C4,'Planificación 2026-1'!H:H,"T1"))>0,"P35"," ") | AP4: =IF(SUM(COUNTIFS('Planificación 2026-1'!F:F,"FILIAL",'Planificación 2026-1'!X:X,C4,'Planificación 2026-1'!H:H,"T3"))>0,"P36"," ") | AQ4: =IF(SUM(COUNTIFS('Planificación 2026-1'!F:F,"FILIAL",'Planificación 2026-1'!X:X,C4,'Planificación 2026-1'!H:H,"T2"))>0,"P37"," ") | AR4: =IF(SUM(COUNTIFS('Planificación 2026-1'!F:F,"FILIAL",'Planificación 2026-1'!X:X,C4,'Planificación 2026-1'!H:H,"AE"))>0,"P38"," ") | AS4: =IF(SUM(COUNTIFS('Planificación 2026-1'!F:F,"FILIAL",'Planificación 2026-1'!X:X,C4,'Planificación 2026-1'!H:H,"T4"))>0,"P55"," ") | AT4: =IF(SUM(COUNTIFS('Planificación 2026-1'!F:F,"SUNAMPE",'Planificación 2026-1'!X:X,C4,'Planificación 2026-1'!H:H,"AF"))>0," P01"," ") | AU4: =IF(SUM(COUNTIFS('Planificación 2026-1'!F:F,"SUNAMPE",'Planificación 2026-1'!X:X,C4,'Planificación 2026-1'!H:H,"EN"))>0,"P02"," ") | AV4: =IF(SUM(COUNTIFS('Planificación 2026-1'!F:F,"SUNAMPE",'Planificación 2026-1'!X:X,C4,'Planificación 2026-1'!H:H,"IS"))>0,"P03"," ") | AW4: =IF(SUM(COUNTIFS('Planificación 2026-1'!F:F,"SUNAMPE",'Planificación 2026-1'!X:X,C4,'Planificación 2026-1'!H:H,"PS"))>0,"P04"," ") | AY4: =IF(SUM(COUNTIFS('Planificación 2026-1'!F:F,"SUNAMPE",'Planificación 2026-1'!X:X,C4,'Planificación 2026-1'!H:H,"IN"))>0,"P06"," ") | AZ4: =IF(SUM(COUNTIFS('Planificación 2026-1'!F:F,"SUNAMPE",'Planificación 2026-1'!X:X,C4,'Planificación 2026-1'!H:H,"CA"))>0,"P07"," ") | BA4: =IF(SUM(COUNTIFS('Planificación 2026-1'!F:F,"SUNAMPE",'Planificación 2026-1'!X:X,C4,'Planificación 2026-1'!H:H,"DE"))>0,"P08"," ") | BB4: =IF(SUM(COUNTIFS('Planificación 2026-1'!F:F,"SUNAMPE",'Planificación 2026-1'!X:X,C4,'Planificación 2026-1'!H:H,"OB"))>0,"P09"," ") | BC4: =IF(SUM(COUNTIFS('Planificación 2026-1'!F:F,"SUNAMPE",'Planificación 2026-1'!X:X,C4,'Planificación 2026-1'!H:H,"MH"))>0,"P31"," ") | BD4: =IF(SUM(COUNTIFS('Planificación 2026-1'!F:F,"SUNAMPE",'Planificación 2026-1'!X:X,C4,'Planificación 2026-1'!H:H,"IC"))>0,"P32"," ") | BE4: =IF(SUM(COUNTIFS('Planificación 2026-1'!F:F,"SUNAMPE",'Planificación 2026-1'!X:X,C4,'Planificación 2026-1'!H:H,"AR"))>0,"P34"," ") | BF4: =IF(SUM(COUNTIFS('Planificación 2026-1'!F:F,"SUNAMPE",'Planificación 2026-1'!X:X,C4,'Planificación 2026-1'!H:H,"T1"))>0,"P35"," ") | BG4: =IF(SUM(COUNTIFS('Planificación 2026-1'!F:F,"SUNAMPE",'Planificación 2026-1'!X:X,C4,'Planificación 2026-1'!H:H,"T3"))>0,"P36"," ") | BH4: =IF(SUM(COUNTIFS('Planificación 2026-1'!F:F,"SUNAMPE",'Planificación 2026-1'!X:X,C4,'Planificación 2026-1'!H:H,"T2"))>0,"P37"," ") | BI4: =IF(SUM(COUNTIFS('Planificación 2026-1'!F:F,"SUNAMPE",'Planificación 2026-1'!X:X,C4,'Planificación 2026-1'!H:H,"AE"))>0,"P38"," ") | BJ4: =IF(SUM(COUNTIFS('Planificación 2026-1'!F:F,"SUNAMPE",'Planificación 2026-1'!X:X,C4,'Planificación 2026-1'!H:H,"T4"))>0,"P55"," ") | BK4: =IF(SUM(COUNTIFS('Planificación 2026-1'!F:F,"HUAURA",'Planificación 2026-1'!X:X,C4,'Planificación 2026-1'!H:H,"AF"))>0," P01"," ") | BL4: =IF(SUM(COUNTIFS('Planificación 2026-1'!F:F,"HUAURA",'Planificación 2026-1'!X:X,C4,'Planificación 2026-1'!H:H,"EN"))>0,"P02"," ") | BM4: =IF(SUM(COUNTIFS('Planificación 2026-1'!F:F,"HUAURA",'Planificación 2026-1'!X:X,C4,'Planificación 2026-1'!H:H,"IS"))>0,"P03"," ") | BN4: =IF(SUM(COUNTIFS('Planificación 2026-1'!F:F,"HUAURA",'Planificación 2026-1'!X:X,C4,'Planificación 2026-1'!H:H,"PS"))>0,"P04"," ") | BP4: =IF(SUM(COUNTIFS('Planificación 2026-1'!F:F,"HUAURA",'Planificación 2026-1'!X:X,C4,'Planificación 2026-1'!H:H,"IN"))>0,"P06"," ") | BQ4: =IF(SUM(COUNTIFS('Planificación 2026-1'!F:F,"HUAURA",'Planificación 2026-1'!X:X,C4,'Planificación 2026-1'!H:H,"CA"))>0,"P07"," ") | BR4: =IF(SUM(COUNTIFS('Planificación 2026-1'!F:F,"HUAURA",'Planificación 2026-1'!X:X,C4,'Planificación 2026-1'!H:H,"DE"))>0,"P08"," ") | BS4: =IF(SUM(COUNTIFS('Planificación 2026-1'!F:F,"HUAURA",'Planificación 2026-1'!X:X,C4,'Planificación 2026-1'!H:H,"OB"))>0,"P09"," ") | BT4: =IF(SUM(COUNTIFS('Planificación 2026-1'!F:F,"HUAURA",'Planificación 2026-1'!X:X,C4,'Planificación 2026-1'!H:H,"MH"))>0,"P31"," ") | BU4: =IF(SUM(COUNTIFS('Planificación 2026-1'!F:F,"HUAURA",'Planificación 2026-1'!X:X,C4,'Planificación 2026-1'!H:H,"IC"))>0,"P32"," ") | BV4: =IF(SUM(COUNTIFS('Planificación 2026-1'!F:F,"HUAURA",'Planificación 2026-1'!X:X,C4,'Planificación 2026-1'!H:H,"AR"))>0,"P34"," ") | BW4: =IF(SUM(COUNTIFS('Planificación 2026-1'!F:F,"HUAURA",'Planificación 2026-1'!X:X,C4,'Planificación 2026-1'!H:H,"T1"))>0,"P35"," ") | BX4: =IF(SUM(COUNTIFS('Planificación 2026-1'!F:F,"HUAURA",'Planificación 2026-1'!X:X,C4,'Planificación 2026-1'!H:H,"T3"))>0,"P36"," ") | BY4: =IF(SUM(COUNTIFS('Planificación 2026-1'!F:F,"HUAURA",'Planificación 2026-1'!X:X,C4,'Planificación 2026-1'!H:H,"T2"))>0,"P37"," ") | BZ4: =IF(SUM(COUNTIFS('Planificación 2026-1'!F:F,"HUAURA",'Planificación 2026-1'!X:X,C4,'Planificación 2026-1'!H:H,"AE"))>0,"P38"," ") | CA4: =IF(SUM(COUNTIFS('Planificación 2026-1'!F:F,"HUAURA",'Planificación 2026-1'!X:X,C4,'Planificación 2026-1'!H:H,"T4"))>0,"P55"," ") | CB4: =SUMIFS('Planificación 2026-1'!S:S,'Planificación 2026-1'!X:X,C4,'Planificación 2026-1'!H:H,"AF",'Planificación 2026-1'!I:I,">2") -> 0 | CC4: =SUMIFS('Planificación 2026-1'!S:S,'Planificación 2026-1'!X:X,C4,'Planificación 2026-1'!H:H,"EN",'Planificación 2026-1'!I:I,">2") -> 40 | CD4: =SUMIFS('Planificación 2026-1'!S:S,'Planificación 2026-1'!X:X,C4,'Planificación 2026-1'!H:H,"IS",'Planificación 2026-1'!I:I,">2") -> 0 | CE4: =SUMIFS('Planificación 2026-1'!S:S,'Planificación 2026-1'!X:X,C4,'Planificación 2026-1'!H:H,"PS",'Planificación 2026-1'!I:I,">2") -> 0 | CF4: =SUMIFS('Planificación 2026-1'!S:S,'Planificación 2026-1'!X:X,C4,'Planificación 2026-1'!H:H,"IN",'Planificación 2026-1'!I:I,">2") -> 0 | CG4: =SUMIFS('Planificación 2026-1'!S:S,'Planificación 2026-1'!X:X,C4,'Planificación 2026-1'!H:H,"CA",'Planificación 2026-1'!I:I,">2") -> 0 | CH4: =SUMIFS('Planificación 2026-1'!S:S,'Planificación 2026-1'!X:X,C4,'Planificación 2026-1'!H:H,"DE",'Planificación 2026-1'!I:I,">2") -> 0 | CI4: =SUMIFS('Planificación 2026-1'!S:S,'Planificación 2026-1'!X:X,C4,'Planificación 2026-1'!H:H,"OB",'Planificación 2026-1'!I:I,">2") -> 0 | CJ4: =SUMIFS('Planificación 2026-1'!S:S,'Planificación 2026-1'!X:X,C4,'Planificación 2026-1'!H:H,"MH",'Planificación 2026-1'!I:I,">2") -> 0 | CK4: =SUMIFS('Planificación 2026-1'!S:S,'Planificación 2026-1'!X:X,C4,'Planificación 2026-1'!H:H,"IC",'Planificación 2026-1'!I:I,">2") -> 0 | CL4: =SUMIFS('Planificación 2026-1'!S:S,'Planificación 2026-1'!X:X,C4,'Planificación 2026-1'!H:H,"AR",'Planificación 2026-1'!I:I,">2") -> 0 | CM4: =SUMIFS('Planificación 2026-1'!S:S,'Planificación 2026-1'!X:X,C4,'Planificación 2026-1'!H:H,"AE",'Planificación 2026-1'!I:I,">2") -> 0 | CN4: =SUMIFS('Planificación 2026-1'!S:S,'Planificación 2026-1'!X:X,C4,'Planificación 2026-1'!H:H,"T1",'Planificación 2026-1'!I:I,">2") -> 0 | CO4: =SUMIFS('Planificación 2026-1'!S:S,'Planificación 2026-1'!X:X,C4,'Planificación 2026-1'!H:H,"T3",'Planificación 2026-1'!I:I,">2") -> 0 | CP4: =SUMIFS('Planificación 2026-1'!S:S,'Planificación 2026-1'!X:X,C4,'Planificación 2026-1'!H:H,"T2",'Planificación 2026-1'!I:I,">2") -> 0 | CQ4: =SUMIFS('Planificación 2026-1'!S:S,'Planificación 2026-1'!X:X,C4,'Planificación 2026-1'!H:H,"T4",'Planificación 2026-1'!I:I,">2") -> 0 | CR4: =SUMIFS('Planificación 2026-1'!S:S,'Planificación 2026-1'!X:X,C4,'Planificación 2026-1'!H:H,"AF",'Planificación 2026-1'!I:I,"<3") -> 0 | CS4: =SUMIFS('Planificación 2026-1'!S:S,'Planificación 2026-1'!X:X,C4,'Planificación 2026-1'!H:H,"EN",'Planificación 2026-1'!I:I,"<3") -> 0 | CT4: =SUMIFS('Planificación 2026-1'!S:S,'Planificación 2026-1'!X:X,C4,'Planificación 2026-1'!H:H,"IS",'Planificación 2026-1'!I:I,"<3") -> 0 | CU4: =SUMIFS('Planificación 2026-1'!S:S,'Planificación 2026-1'!X:X,C4,'Planificación 2026-1'!H:H,"PS",'Planificación 2026-1'!I:I,"<3") -> 0 | CV4: =SUMIFS('Planificación 2026-1'!S:S,'Planificación 2026-1'!X:X,C4,'Planificación 2026-1'!H:H,"IN",'Planificación 2026-1'!I:I,"<3") -> 0 | CW4: =SUMIFS('Planificación 2026-1'!S:S,'Planificación 2026-1'!X:X,C4,'Planificación 2026-1'!H:H,"CA",'Planificación 2026-1'!I:I,"<3") -> 0 | CX4: =SUMIFS('Planificación 2026-1'!S:S,'Planificación 2026-1'!X:X,C4,'Planificación 2026-1'!H:H,"DE",'Planificación 2026-1'!I:I,"<3") -> 0 | CY4: =SUMIFS('Planificación 2026-1'!S:S,'Planificación 2026-1'!X:X,C4,'Planificación 2026-1'!H:H,"OB",'Planificación 2026-1'!I:I,"<3") -> 0 | CZ4: =SUMIFS('Planificación 2026-1'!S:S,'Planificación 2026-1'!X:X,C4,'Planificación 2026-1'!H:H,"MH",'Planificación 2026-1'!I:I,"<3") -> 0 | DA4: =SUMIFS('Planificación 2026-1'!S:S,'Planificación 2026-1'!X:X,C4,'Planificación 2026-1'!H:H,"IC",'Planificación 2026-1'!I:I,"<3") -> 0 | DB4: =SUMIFS('Planificación 2026-1'!S:S,'Planificación 2026-1'!X:X,C4,'Planificación 2026-1'!H:H,"AR",'Planificación 2026-1'!I:I,"<3") -> 0 | DC4: =SUMIFS('Planificación 2026-1'!S:S,'Planificación 2026-1'!X:X,C4,'Planificación 2026-1'!H:H,"AE",'Planificación 2026-1'!I:I,"<3") -> 0 | DD4: =SUMIFS('Planificación 2026-1'!S:S,'Planificación 2026-1'!X:X,C4,'Planificación 2026-1'!H:H,"T1",'Planificación 2026-1'!I:I,"<3") -> 0 | DE4: =SUMIFS('Planificación 2026-1'!S:S,'Planificación 2026-1'!X:X,C4,'Planificación 2026-1'!H:H,"T3",'Planificación 2026-1'!I:I,"<3") -> 0 | DF4: =SUMIFS('Planificación 2026-1'!S:S,'Planificación 2026-1'!X:X,C4,'Planificación 2026-1'!H:H,"T2",'Planificación 2026-1'!I:I,"<3") -> 0 | DG4: =SUMIFS('Planificación 2026-1'!S:S,'Planificación 2026-1'!X:X,C4,'Planificación 2026-1'!H:H,"T4",'Planificación 2026-1'!I:I,"<3") -> 0 | DH4: =TRIM(CONCATENATE(L4,M4,N4,O4,P4,Q4,R4,S4,T4,U4,V4,W4,X4,Y4,Z4,AA4,AB4)) -> P02 | DI4: =IF(C4="","",SUMIFS('Planificación 2026-1'!S:S,'Planificación 2026-1'!X:X,C4,'Planificación 2026-1'!F:F,"PRINCIPAL",'Planificación 2026-1'!Y:Y,"VIRTUAL")) -> 32 | DJ4: =IF(C4="","",SUMIFS('Planificación 2026-1'!S:S,'Planificación 2026-1'!X:X,C4,'Planificación 2026-1'!F:F,"PRINCIPAL",'Planificación 2026-1'!Y:Y,"PRESENCIAL")) -> 0 | DK4: =IF(C4="","",SUMIFS('Planificación 2026-1'!S:S,'Planificación 2026-1'!X:X,C4,'Planificación 2026-1'!F:F,"PRINCIPAL",'Planificación 2026-1'!Y:Y,"HIBRIDO PRESENCIAL")) -> 0 | DL4: =TRIM(CONCATENATE(AC4,AD4,AE4,AF4,AG4,AH4,AI4,AJ4,AK4,AL4,AM4,AN4,AO4,AP4,AQ4,AR4,AS4)) -> P02 | DM4: =IF(C4="","",SUMIFS('Planificación 2026-1'!S:S,'Planificación 2026-1'!X:X,C4,'Planificación 2026-1'!F:F,"FILIAL",'Planificación 2026-1'!Y:Y,"VIRTUAL")) -> 8 | DN4: =IF(C4="","",SUMIFS('Planificación 2026-1'!S:S,'Planificación 2026-1'!X:X,C4,'Planificación 2026-1'!F:F,"FILIAL",'Planificación 2026-1'!Y:Y,"PRESENCIAL")) -> 0 | DO4: =IF(C4="","",SUMIFS('Planificación 2026-1'!S:S,'Planificación 2026-1'!X:X,C4,'Planificación 2026-1'!F:F,"FILIAL",'Planificación 2026-1'!Y:Y,"HIBRIDO PRESENCIAL")) -> 0 | DP4: =TRIM(CONCATENATE(AT4,AU4,AV4,AW4,AX4,AY4,AZ4,BA4,BB4,BC4,BD4,BE4,BF4,BG4,BH4,BI4,BJ4)) | DQ4: =IF(C4="","",SUMIFS('Planificación 2026-1'!S:S,'Planificación 2026-1'!X:X,C4,'Planificación 2026-1'!F:F,"SUNAMPE",'Planificación 2026-1'!Y:Y,"VIRTUAL")) -> 0 | DR4: =IF(C4="","",SUMIFS('Planificación 2026-1'!S:S,'Planificación 2026-1'!X:X,C4,'Planificación 2026-1'!F:F,"SUNAMPE",'Planificación 2026-1'!Y:Y,"PRESENCIAL")) -> 0 | DS4: =TRIM(CONCATENATE(BK4,BL4,BM4,BN4,BO4,BP4,BQ4,BR4,BS4,BT4,BU4,BV4,BW4,BX4,BY4,BZ4,CA4)) | DT4: =IF(C4="","",SUMIFS('Planificación 2026-1'!S:S,'Planificación 2026-1'!X:X,C4,'Planificación 2026-1'!F:F,"HUAURA",'Planificación 2026-1'!Y:Y,"VIRTUAL")) -> 0 | DU4: =IF(C4="","",SUMIFS('Planificación 2026-1'!S:S,'Planificación 2026-1'!X:X,C4,'Planificación 2026-1'!F:F,"HUAURA",'Planificación 2026-1'!Y:Y,"PRESENCIAL")) -> 0 | DV4: =SUMIFS('Planificación 2026-1'!S:S,'Planificación 2026-1'!X:X,C4,'Planificación 2026-1'!F:F,"PRINCIPAL",'Planificación 2026-1'!Y:Y,"VIRTUAL",'Planificación 2026-1'!I:I,">2") -> 32 | DW4: =SUMIFS('Planificación 2026-1'!S:S,'Planificación 2026-1'!X:X,C4,'Planificación 2026-1'!F:F,"PRINCIPAL",'Planificación 2026-1'!Y:Y,"<>VIRTUAL",'Planificación 2026-1'!I:I,">2") -> 0 | DX4: =SUMIFS('Planificación 2026-1'!S:S,'Planificación 2026-1'!X:X,C4,'Planificación 2026-1'!F:F,"SUNAMPE",'Planificación 2026-1'!Y:Y,"VIRTUAL",'Planificación 2026-1'!I:I,">2") -> 0 | DY4: =SUMIFS('Planificación 2026-1'!S:S,'Planificación 2026-1'!X:X,C4,'Planificación 2026-1'!F:F,"SUNAMPE",'Planificación 2026-1'!Y:Y,"<>VIRTUAL",'Planificación 2026-1'!I:I,">2") -> 0 | DZ4: =SUMIFS('Planificación 2026-1'!S:S,'Planificación 2026-1'!X:X,C4,'Planificación 2026-1'!F:F,"FILIAL",'Planificación 2026-1'!Y:Y,"VIRTUAL",'Planificación 2026-1'!I:I,">2") -> 8 | EA4: =SUMIFS('Planificación 2026-1'!S:S,'Planificación 2026-1'!X:X,C4,'Planificación 2026-1'!F:F,"FILIAL",'Planificación 2026-1'!Y:Y,"<>VIRTUAL",'Planificación 2026-1'!I:I,">2") -> 0 | EB4: =SUMIFS('Planificación 2026-1'!S:S,'Planificación 2026-1'!X:X,C4,'Planificación 2026-1'!F:F,"PORUMA",'Planificación 2026-1'!Y:Y,"VIRTUAL",'Planificación 2026-1'!I:I,">2") -> 0 | EC4: =SUMIFS('Planificación 2026-1'!S:S,'Planificación 2026-1'!X:X,C4,'Planificación 2026-1'!F:F,"PORUMA",'Planificación 2026-1'!Y:Y,"<>VIRTUAL",'Planificación 2026-1'!I:I,">2") -> 0 | ED4: =SUMIFS('Planificación 2026-1'!S:S,'Planificación 2026-1'!X:X,C4,'Planificación 2026-1'!F:F,"HUAURA",'Planificación 2026-1'!Y:Y,"VIRTUAL",'Planificación 2026-1'!I:I,">2") -> 0 | EE4: =SUMIFS('Planificación 2026-1'!S:S,'Planificación 2026-1'!X:X,C4,'Planificación 2026-1'!F:F,"HUAURA",'Planificación 2026-1'!Y:Y,"<>VIRTUAL",'Planificación 2026-1'!I:I,">2") -> 0 | EF4: =SUMIFS('Planificación 2026-1'!S:S,'Planificación 2026-1'!X:X,C4,'Planificación 2026-1'!F:F,"PRINCIPAL",'Planificación 2026-1'!Y:Y,"VIRTUAL",'Planificación 2026-1'!I:I,"<3") -> 0 | EG4: =SUMIFS('Planificación 2026-1'!S:S,'Planificación 2026-1'!X:X,C4,'Planificación 2026-1'!F:F,"PRINCIPAL",'Planificación 2026-1'!Y:Y,"<>VIRTUAL",'Planificación 2026-1'!I:I,"<3") -> 0 | EH4: =SUMIFS('Planificación 2026-1'!S:S,'Planificación 2026-1'!X:X,C4,'Planificación 2026-1'!F:F,"SUNAMPE",'Planificación 2026-1'!Y:Y,"VIRTUAL",'Planificación 2026-1'!I:I,"<3") -> 0 | EI4: =SUMIFS('Planificación 2026-1'!S:S,'Planificación 2026-1'!X:X,C4,'Planificación 2026-1'!F:F,"SUNAMPE",'Planificación 2026-1'!Y:Y,"<>VIRTUAL",'Planificación 2026-1'!I:I,"<3") -> 0 | EJ4: =SUMIFS('Planificación 2026-1'!S:S,'Planificación 2026-1'!X:X,C4,'Planificación 2026-1'!F:F,"FILIAL",'Planificación 2026-1'!Y:Y,"VIRTUAL",'Planificación 2026-1'!I:I,"<3") -> 0 | EK4: =SUMIFS('Planificación 2026-1'!S:S,'Planificación 2026-1'!X:X,C4,'Planificación 2026-1'!F:F,"FILIAL",'Planificación 2026-1'!Y:Y,"<>VIRTUAL",'Planificación 2026-1'!I:I,"<3") -> 0 | EL4: =SUMIFS('Planificación 2026-1'!S:S,'Planificación 2026-1'!X:X,C4,'Planificación 2026-1'!F:F,"PORUMA",'Planificación 2026-1'!Y:Y,"VIRTUAL",'Planificación 2026-1'!I:I,"<3") -> 0 | EM4: =SUMIFS('Planificación 2026-1'!S:S,'Planificación 2026-1'!X:X,C4,'Planificación 2026-1'!F:F,"PORUMA",'Planificación 2026-1'!Y:Y,"<>VIRTUAL",'Planificación 2026-1'!I:I,"<3") -> 0 | EN4: =SUMIFS('Planificación 2026-1'!S:S,'Planificación 2026-1'!X:X,C4,'Planificación 2026-1'!F:F,"HUAURA",'Planificación 2026-1'!Y:Y,"VIRTUAL",'Planificación 2026-1'!I:I,"<3") -> 0 | EO4: =SUMIFS('Planificación 2026-1'!S:S,'Planificación 2026-1'!X:X,C4,'Planificación 2026-1'!F:F,"HUAURA",'Planificación 2026-1'!Y:Y,"<>VIRTUAL",'Planificación 2026-1'!I:I,"<3") -> 0 | EP4: =EJ4+DZ4+EA4+EK4 -> 8 | EQ4: =EO4+EN4+EE4+ED4 -> 0 | ER4: =EL4+EM4+EC4+EB4 -> 0 | ES4: =EG4+EF4+DW4+DV4 -> 32 | ET4: =EI4+EH4+DY4+DX4 -> 0 | EU4: =SUM(EP4:ET4) -> 40 | EV4: =EXACT(EU4,E4) -> TRUE | EX4: =DV4+DZ4+ED4+EF4+EJ4+EN4+DX4+EH4 -> 40 | EY4: =DW4+EA4+EE4+EG4+EK4+EO4+DY4+EI4 -> 0 | EZ4: =EXACT(SUM(EX4:EY4),E4) -> TRUE | FA4: =IF(AND(DW4=0,EA4=0,EE4=0),"",IF(COUNTIF(DV4:EE4,">0")=1,IF(DW4+DV4>0,"SEDE",IF(EA4+DZ4>0,"FILIAL","HUAURA")),IF(COUNTIF(DV4:EE4,">0")=2,IF(AND(DW4+DV4>0,EA4+DZ4>0),"SEDE-FILIAL",IF(AND(DW4>0,EE4>0),"SEDE-HUAURA","FILIAL-HUAURA")),"SEDE-FILIAL-HUAURA"))) | FB4: =IF(EX4=0,"PRESENCIAL",IF(EY4=0,"VIRTUAL",IF(EX4>EY4,"MAS VIRTUAL",IF(EY4>EX4,"MAS PRESENCIAL","AMBOS")))) -> VIRTUAL
B5: 2 | C5: ACOSTA VILLAVICENCIO BLANCA AURORA | D5: 40364065 | E5: =SUMIF('Planificación 2026-1'!X:X,C5,'Planificación 2026-1'!S:S) -> 40 | F5: TC | G5: RENOVACIÓN | H5: SEDE | I5: PSICOLOGÍA - EEGG | J5: SEDE | K5: OBSTETRICIA - EEGG | L5: =IF(SUM(COUNTIFS('Planificación 2026-1'!F:F,"PRINCIPAL",'Planificación 2026-1'!X:X,C5,'Planificación 2026-1'!H:H,"AF"))>0,"P01"," ") | M5: =IF(SUM(COUNTIFS('Planificación 2026-1'!F:F,"PRINCIPAL",'Planificación 2026-1'!X:X,C5,'Planificación 2026-1'!H:H,"EN"))>0,"P02"," ") -> P02 | N5: =IF(SUM(COUNTIFS('Planificación 2026-1'!F:F,"PRINCIPAL",'Planificación 2026-1'!X:X,C5,'Planificación 2026-1'!H:H,"IS"))>0,"P03"," ") | O5: =IF(SUM(COUNTIFS('Planificación 2026-1'!F:F,"PRINCIPAL",'Planificación 2026-1'!X:X,C5,'Planificación 2026-1'!H:H,"PS"))>0,"P04"," ") | Q5: =IF(SUM(COUNTIFS('Planificación 2026-1'!F:F,"PRINCIPAL",'Planificación 2026-1'!X:X,C5,'Planificación 2026-1'!H:H,"IN"))>0,"P06"," ") | R5: =IF(SUM(COUNTIFS('Planificación 2026-1'!F:F,"PRINCIPAL",'Planificación 2026-1'!X:X,C5,'Planificación 2026-1'!H:H,"CA"))>0,"P07"," ") | S5: =IF(SUM(COUNTIFS('Planificación 2026-1'!F:F,"PRINCIPAL",'Planificación 2026-1'!X:X,C5,'Planificación 2026-1'!H:H,"DE"))>0,"P08"," ") | T5: =IF(SUM(COUNTIFS('Planificación 2026-1'!F:F,"PRINCIPAL",'Planificación 2026-1'!X:X,C5,'Planificación 2026-1'!H:H,"OB"))>0,"P09"," ") | U5: =IF(SUM(COUNTIFS('Planificación 2026-1'!F:F,"PRINCIPAL",'Planificación 2026-1'!X:X,C5,'Planificación 2026-1'!H:H,"MH"))>0,"P31"," ") | V5: =IF(SUM(COUNTIFS('Planificación 2026-1'!F:F,"PRINCIPAL",'Planificación 2026-1'!X:X,C5,'Planificación 2026-1'!H:H,"IC"))>0,"P32"," ") | W5: =IF(SUM(COUNTIFS('Planificación 2026-1'!F:F,"PRINCIPAL",'Planificación 2026-1'!X:X,C5,'Planificación 2026-1'!H:H,"AR"))>0,"P34"," ") | X5: =IF(SUM(COUNTIFS('Planificación 2026-1'!F:F,"PRINCIPAL",'Planificación 2026-1'!X:X,C5,'Planificación 2026-1'!H:H,"T1"))>0,"P35"," ") | Y5: =IF(SUM(COUNTIFS('Planificación 2026-1'!F:F,"PRINCIPAL",'Planificación 2026-1'!X:X,C5,'Planificación 2026-1'!H:H,"T3"))>0,"P36"," ") | Z5: =IF(SUM(COUNTIFS('Planificación 2026-1'!F:F,"PRINCIPAL",'Planificación 2026-1'!X:X,C5,'Planificación 2026-1'!H:H,"T2"))>0,"P37"," ") | AA5: =IF(SUM(COUNTIFS('Planificación 2026-1'!F:F,"PRINCIPAL",'Planificación 2026-1'!X:X,C5,'Planificación 2026-1'!H:H,"AE"))>0,"P38"," ") | AB5: =IF(SUM(COUNTIFS('Planificación 2026-1'!F:F,"PRINCIPAL",'Planificación 2026-1'!X:X,C5,'Planificación 2026-1'!H:H,"T4"))>0,"P55"," ") | AC5: =IF(SUM(COUNTIFS('Planificación 2026-1'!F:F,"FILIAL",'Planificación 2026-1'!X:X,C5,'Planificación 2026-1'!H:H,"AF"))>0," P01"," ") | AD5: =IF(SUM(COUNTIFS('Planificación 2026-1'!F:F,"FILIAL",'Planificación 2026-1'!X:X,C5,'Planificación 2026-1'!H:H,"EN"))>0,"P02"," ") | AE5: =IF(SUM(COUNTIFS('Planificación 2026-1'!F:F,"FILIAL",'Planificación 2026-1'!X:X,C5,'Planificación 2026-1'!H:H,"IS"))>0,"P03"," ") | AF5: =IF(SUM(COUNTIFS('Planificación 2026-1'!F:F,"FILIAL",'Planificación 2026-1'!X:X,C5,'Planificación 2026-1'!H:H,"PS"))>0,"P04"," ") | AH5: =IF(SUM(COUNTIFS('Planificación 2026-1'!F:F,"FILIAL",'Planificación 2026-1'!X:X,C5,'Planificación 2026-1'!H:H,"IN"))>0,"P06"," ") | AI5: =IF(SUM(COUNTIFS('Planificación 2026-1'!F:F,"FILIAL",'Planificación 2026-1'!X:X,C5,'Planificación 2026-1'!H:H,"CA"))>0,"P07"," ") | AJ5: =IF(SUM(COUNTIFS('Planificación 2026-1'!F:F,"FILIAL",'Planificación 2026-1'!X:X,C5,'Planificación 2026-1'!H:H,"DE"))>0,"P08"," ") | AK5: =IF(SUM(COUNTIFS('Planificación 2026-1'!F:F,"FILIAL",'Planificación 2026-1'!X:X,C5,'Planificación 2026-1'!H:H,"OB"))>0,"P09"," ") | AL5: =IF(SUM(COUNTIFS('Planificación 2026-1'!F:F,"FILIAL",'Planificación 2026-1'!X:X,C5,'Planificación 2026-1'!H:H,"MH"))>0,"P31"," ") | AM5: =IF(SUM(COUNTIFS('Planificación 2026-1'!F:F,"FILIAL",'Planificación 2026-1'!X:X,C5,'Planificación 2026-1'!H:H,"IC"))>0,"P32"," ") | AN5: =IF(SUM(COUNTIFS('Planificación 2026-1'!F:F,"FILIAL",'Planificación 2026-1'!X:X,C5,'Planificación 2026-1'!H:H,"AR"))>0,"P34"," ") | AO5: =IF(SUM(COUNTIFS('Planificación 2026-1'!F:F,"FILIAL",'Planificación 2026-1'!X:X,C5,'Planificación 2026-1'!H:H,"T1"))>0,"P35"," ") | AP5: =IF(SUM(COUNTIFS('Planificación 2026-1'!F:F,"FILIAL",'Planificación 2026-1'!X:X,C5,'Planificación 2026-1'!H:H,"T3"))>0,"P36"," ") | AQ5: =IF(SUM(COUNTIFS('Planificación 2026-1'!F:F,"FILIAL",'Planificación 2026-1'!X:X,C5,'Planificación 2026-1'!H:H,"T2"))>0,"P37"," ") | AR5: =IF(SUM(COUNTIFS('Planificación 2026-1'!F:F,"FILIAL",'Planificación 2026-1'!X:X,C5,'Planificación 2026-1'!H:H,"AE"))>0,"P38"," ") | AS5: =IF(SUM(COUNTIFS('Planificación 2026-1'!F:F,"FILIAL",'Planificación 2026-1'!X:X,C5,'Planificación 2026-1'!H:H,"T4"))>0,"P55"," ") | AT5: =IF(SUM(COUNTIFS('Planificación 2026-1'!F:F,"SUNAMPE",'Planificación 2026-1'!X:X,C5,'Planificación 2026-1'!H:H,"AF"))>0," P01"," ") | AU5: =IF(SUM(COUNTIFS('Planificación 2026-1'!F:F,"SUNAMPE",'Planificación 2026-1'!X:X,C5,'Planificación 2026-1'!H:H,"EN"))>0,"P02"," ") | AV5: =IF(SUM(COUNTIFS('Planificación 2026-1'!F:F,"SUNAMPE",'Planificación 2026-1'!X:X,C5,'Planificación 2026-1'!H:H,"IS"))>0,"P03"," ") | AW5: =IF(SUM(COUNTIFS('Planificación 2026-1'!F:F,"SUNAMPE",'Planificación 2026-1'!X:X,C5,'Planificación 2026-1'!H:H,"PS"))>0,"P04"," ") -> P04 | AY5: =IF(SUM(COUNTIFS('Planificación 2026-1'!F:F,"SUNAMPE",'Planificación 2026-1'!X:X,C5,'Planificación 2026-1'!H:H,"IN"))>0,"P06"," ") | AZ5: =IF(SUM(COUNTIFS('Planificación 2026-1'!F:F,"SUNAMPE",'Planificación 2026-1'!X:X,C5,'Planificación 2026-1'!H:H,"CA"))>0,"P07"," ") | BA5: =IF(SUM(COUNTIFS('Planificación 2026-1'!F:F,"SUNAMPE",'Planificación 2026-1'!X:X,C5,'Planificación 2026-1'!H:H,"DE"))>0,"P08"," ") | BB5: =IF(SUM(COUNTIFS('Planificación 2026-1'!F:F,"SUNAMPE",'Planificación 2026-1'!X:X,C5,'Planificación 2026-1'!H:H,"OB"))>0,"P09"," ") -> P09 | BC5: =IF(SUM(COUNTIFS('Planificación 2026-1'!F:F,"SUNAMPE",'Planificación 2026-1'!X:X,C5,'Planificación 2026-1'!H:H,"MH"))>0,"P31"," ") -> P31 | BD5: =IF(SUM(COUNTIFS('Planificación 2026-1'!F:F,"SUNAMPE",'Planificación 2026-1'!X:X,C5,'Planificación 2026-1'!H:H,"IC"))>0,"P32"," ") | BE5: =IF(SUM(COUNTIFS('Planificación 2026-1'!F:F,"SUNAMPE",'Planificación 2026-1'!X:X,C5,'Planificación 2026-1'!H:H,"AR"))>0,"P34"," ") | BF5: =IF(SUM(COUNTIFS('Planificación 2026-1'!F:F,"SUNAMPE",'Planificación 2026-1'!X:X,C5,'Planificación 2026-1'!H:H,"T1"))>0,"P35"," ") -> P35 | BG5: =IF(SUM(COUNTIFS('Planificación 2026-1'!F:F,"SUNAMPE",'Planificación 2026-1'!X:X,C5,'Planificación 2026-1'!H:H,"T3"))>0,"P36"," ") | BH5: =IF(SUM(COUNTIFS('Planificación 2026-1'!F:F,"SUNAMPE",'Planificación 2026-1'!X:X,C5,'Planificación 2026-1'!H:H,"T2"))>0,"P37"," ") | BI5: =IF(SUM(COUNTIFS('Planificación 2026-1'!F:F,"SUNAMPE",'Planificación 2026-1'!X:X,C5,'Planificación 2026-1'!H:H,"AE"))>0,"P38"," ") | BJ5: =IF(SUM(COUNTIFS('Planificación 2026-1'!F:F,"SUNAMPE",'Planificación 2026-1'!X:X,C5,'Planificación 2026-1'!H:H,"T4"))>0,"P55"," ") | BK5: =IF(SUM(COUNTIFS('Planificación 2026-1'!F:F,"HUAURA",'Planificación 2026-1'!X:X,C5,'Planificación 2026-1'!H:H,"AF"))>0," P01"," ") | BL5: =IF(SUM(COUNTIFS('Planificación 2026-1'!F:F,"HUAURA",'Planificación 2026-1'!X:X,C5,'Planificación 2026-1'!H:H,"EN"))>0,"P02"," ") | BM5: =IF(SUM(COUNTIFS('Planificación 2026-1'!F:F,"HUAURA",'Planificación 2026-1'!X:X,C5,'Planificación 2026-1'!H:H,"IS"))>0,"P03"," ") | BN5: =IF(SUM(COUNTIFS('Planificación 2026-1'!F:F,"HUAURA",'Planificación 2026-1'!X:X,C5,'Planificación 2026-1'!H:H,"PS"))>0,"P04"," ") | BP5: =IF(SUM(COUNTIFS('Planificación 2026-1'!F:F,"HUAURA",'Planificación 2026-1'!X:X,C5,'Planificación 2026-1'!H:H,"IN"))>0,"P06"," ") | BQ5: =IF(SUM(COUNTIFS('Planificación 2026-1'!F:F,"HUAURA",'Planificación 2026-1'!X:X,C5,'Planificación 2026-1'!H:H,"CA"))>0,"P07"," ") | BR5: =IF(SUM(COUNTIFS('Planificación 2026-1'!F:F,"HUAURA",'Planificación 2026-1'!X:X,C5,'Planificación 2026-1'!H:H,"DE"))>0,"P08"," ") | BS5: =IF(SUM(COUNTIFS('Planificación 2026-1'!F:F,"HUAURA",'Planificación 2026-1'!X:X,C5,'Planificación 2026-1'!H:H,"OB"))>0,"P09"," ") | BT5: =IF(SUM(COUNTIFS('Planificación 2026-1'!F:F,"HUAURA",'Planificación 2026-1'!X:X,C5,'Planificación 2026-1'!H:H,"MH"))>0,"P31"," ") | BU5: =IF(SUM(COUNTIFS('Planificación 2026-1'!F:F,"HUAURA",'Planificación 2026-1'!X:X,C5,'Planificación 2026-1'!H:H,"IC"))>0,"P32"," ") | BV5: =IF(SUM(COUNTIFS('Planificación 2026-1'!F:F,"HUAURA",'Planificación 2026-1'!X:X,C5,'Planificación 2026-1'!H:H,"AR"))>0,"P34"," ") | BW5: =IF(SUM(COUNTIFS('Planificación 2026-1'!F:F,"HUAURA",'Planificación 2026-1'!X:X,C5,'Planificación 2026-1'!H:H,"T1"))>0,"P35"," ") | BX5: =IF(SUM(COUNTIFS('Planificación 2026-1'!F:F,"HUAURA",'Planificación 2026-1'!X:X,C5,'Planificación 2026-1'!H:H,"T3"))>0,"P36"," ") | BY5: =IF(SUM(COUNTIFS('Planificación 2026-1'!F:F,"HUAURA",'Planificación 2026-1'!X:X,C5,'Planificación 2026-1'!H:H,"T2"))>0,"P37"," ") | BZ5: =IF(SUM(COUNTIFS('Planificación 2026-1'!F:F,"HUAURA",'Planificación 2026-1'!X:X,C5,'Planificación 2026-1'!H:H,"AE"))>0,"P38"," ") | CA5: =IF(SUM(COUNTIFS('Planificación 2026-1'!F:F,"HUAURA",'Planificación 2026-1'!X:X,C5,'Planificación 2026-1'!H:H,"T4"))>0,"P55"," ") | CB5: =SUMIFS('Planificación 2026-1'!S:S,'Planificación 2026-1'!X:X,C5,'Planificación 2026-1'!H:H,"AF",'Planificación 2026-1'!I:I,">2") -> 0 | CC5: =SUMIFS('Planificación 2026-1'!S:S,'Planificación 2026-1'!X:X,C5,'Planificación 2026-1'!H:H,"EN",'Planificación 2026-1'!I:I,">2") -> 0 | CD5: =SUMIFS('Planificación 2026-1'!S:S,'Planificación 2026-1'!X:X,C5,'Planificación 2026-1'!H:H,"IS",'Planificación 2026-1'!I:I,">2") -> 0 | CE5: =SUMIFS('Planificación 2026-1'!S:S,'Planificación 2026-1'!X:X,C5,'Planificación 2026-1'!H:H,"PS",'Planificación 2026-1'!I:I,">2") -> 0 | CF5: =SUMIFS('Planificación 2026-1'!S:S,'Planificación 2026-1'!X:X,C5,'Planificación 2026-1'!H:H,"IN",'Planificación 2026-1'!I:I,">2") -> 0 | CG5: =SUMIFS('Planificación 2026-1'!S:S,'Planificación 2026-1'!X:X,C5,'Planificación 2026-1'!H:H,"CA",'Planificación 2026-1'!I:I,">2") -> 0 | CH5: =SUMIFS('Planificación 2026-1'!S:S,'Planificación 2026-1'!X:X,C5,'Planificación 2026-1'!H:H,"DE",'Planificación 2026-1'!I:I,">2") -> 0 | CI5: =SUMIFS('Planificación 2026-1'!S:S,'Planificación 2026-1'!X:X,C5,'Planificación 2026-1'!H:H,"OB",'Planificación 2026-1'!I:I,">2") -> 0 | CJ5: =SUMIFS('Planificación 2026-1'!S:S,'Planificación 2026-1'!X:X,C5,'Planificación 2026-1'!H:H,"MH",'Planificación 2026-1'!I:I,">2") -> 0 | CK5: =SUMIFS('Planificación 2026-1'!S:S,'Planificación 2026-1'!X:X,C5,'Planificación 2026-1'!H:H,"IC",'Planificación 2026-1'!I:I,">2") -> 0 | CL5: =SUMIFS('Planificación 2026-1'!S:S,'Planificación 2026-1'!X:X,C5,'Planificación 2026-1'!H:H,"AR",'Planificación 2026-1'!I:I,">2") -> 0 | CM5: =SUMIFS('Planificación 2026-1'!S:S,'Planificación 2026-1'!X:X,C5,'Planificación 2026-1'!H:H,"AE",'Planificación 2026-1'!I:I,">2") -> 0 | CN5: =SUMIFS('Planificación 2026-1'!S:S,'Planificación 2026-1'!X:X,C5,'Planificación 2026-1'!H:H,"T1",'Planificación 2026-1'!I:I,">2") -> 0 | CO5: =SUMIFS('Planificación 2026-1'!S:S,'Planificación 2026-1'!X:X,C5,'Planificación 2026-1'!H:H,"T3",'Planificación 2026-1'!I:I,">2") -> 0 | CP5: =SUMIFS('Planificación 2026-1'!S:S,'Planificación 2026-1'!X:X,C5,'Planificación 2026-1'!H:H,"T2",'Planificación 2026-1'!I:I,">2") -> 0 | CQ5: =SUMIFS('Planificación 2026-1'!S:S,'Planificación 2026-1'!X:X,C5,'Planificación 2026-1'!H:H,"T4",'Planificación 2026-1'!I:I,">2") -> 0 | CR5: =SUMIFS('Planificación 2026-1'!S:S,'Planificación 2026-1'!X:X,C5,'Planificación 2026-1'!H:H,"AF",'Planificación 2026-1'!I:I,"<3") -> 0 | CS5: =SUMIFS('Planificación 2026-1'!S:S,'Planificación 2026-1'!X:X,C5,'Planificación 2026-1'!H:H,"EN",'Planificación 2026-1'!I:I,"<3") -> 8 | CT5: =SUMIFS('Planificación 2026-1'!S:S,'Planificación 2026-1'!X:X,C5,'Planificación 2026-1'!H:H,"IS",'Planificación 2026-1'!I:I,"<3") -> 0 | CU5: =SUMIFS('Planificación 2026-1'!S:S,'Planificación 2026-1'!X:X,C5,'Planificación 2026-1'!H:H,"PS",'Planificación 2026-1'!I:I,"<3") -> 4 | CV5: =SUMIFS('Planificación 2026-1'!S:S,'Planificación 2026-1'!X:X,C5,'Planificación 2026-1'!H:H,"IN",'Planificación 2026-1'!I:I,"<3") -> 0 | CW5: =SUMIFS('Planificación 2026-1'!S:S,'Planificación 2026-1'!X:X,C5,'Planificación 2026-1'!H:H,"CA",'Planificación 2026-1'!I:I,"<3") -> 0 | CX5: =SUMIFS('Planificación 2026-1'!S:S,'Planificación 2026-1'!X:X,C5,'Planificación 2026-1'!H:H,"DE",'Planificación 2026-1'!I:I,"<3") -> 0 | CY5: =SUMIFS('Planificación 2026-1'!S:S,'Planificación 2026-1'!X:X,C5,'Planificación 2026-1'!H:H,"OB",'Planificación 2026-1'!I:I,"<3") -> 16 | CZ5: =SUMIFS('Planificación 2026-1'!S:S,'Planificación 2026-1'!X:X,C5,'Planificación 2026-1'!H:H,"MH",'Planificación 2026-1'!I:I,"<3") -> 8 | DA5: =SUMIFS('Planificación 2026-1'!S:S,'Planificación 2026-1'!X:X,C5,'Planificación 2026-1'!H:H,"IC",'Planificación 2026-1'!I:I,"<3") -> 0 | DB5: =SUMIFS('Planificación 2026-1'!S:S,'Planificación 2026-1'!X:X,C5,'Planificación 2026-1'!H:H,"AR",'Planificación 2026-1'!I:I,"<3") -> 0 | DC5: =SUMIFS('Planificación 2026-1'!S:S,'Planificación 2026-1'!X:X,C5,'Planificación 2026-1'!H:H,"AE",'Planificación 2026-1'!I:I,"<3") -> 0 | DD5: =SUMIFS('Planificación 2026-1'!S:S,'Planificación 2026-1'!X:X,C5,'Planificación 2026-1'!H:H,"T1",'Planificación 2026-1'!I:I,"<3") -> 4 | DE5: =SUMIFS('Planificación 2026-1'!S:S,'Planificación 2026-1'!X:X,C5,'Planificación 2026-1'!H:H,"T3",'Planificación 2026-1'!I:I,"<3") -> 0 | DF5: =SUMIFS('Planificación 2026-1'!S:S,'Planificación 2026-1'!X:X,C5,'Planificación 2026-1'!H:H,"T2",'Planificación 2026-1'!I:I,"<3") -> 0 | DG5: =SUMIFS('Planificación 2026-1'!S:S,'Planificación 2026-1'!X:X,C5,'Planificación 2026-1'!H:H,"T4",'Planificación 2026-1'!I:I,"<3") -> 0 | DH5: =TRIM(CONCATENATE(L5,M5,N5,O5,P5,Q5,R5,S5,T5,U5,V5,W5,X5,Y5,Z5,AA5,AB5)) -> P02 | DI5: =IF(C5="","",SUMIFS('Planificación 2026-1'!S:S,'Planificación 2026-1'!X:X,C5,'Planificación 2026-1'!F:F,"PRINCIPAL",'Planificación 2026-1'!Y:Y,"VIRTUAL")) -> 0 | DJ5: =IF(C5="","",SUMIFS('Planificación 2026-1'!S:S,'Planificación 2026-1'!X:X,C5,'Planificación 2026-1'!F:F,"PRINCIPAL",'Planificación 2026-1'!Y:Y,"PRESENCIAL")) -> 8 | DK5: =IF(C5="","",SUMIFS('Planificación 2026-1'!S:S,'Planificación 2026-1'!X:X,C5,'Planificación 2026-1'!F:F,"PRINCIPAL",'Planificación 2026-1'!Y:Y,"HIBRIDO PRESENCIAL")) -> 0 | DL5: =TRIM(CONCATENATE(AC5,AD5,AE5,AF5,AG5,AH5,AI5,AJ5,AK5,AL5,AM5,AN5,AO5,AP5,AQ5,AR5,AS5)) | DM5: =IF(C5="","",SUMIFS('Planificación 2026-1'!S:S,'Planificación 2026-1'!X:X,C5,'Planificación 2026-1'!F:F,"FILIAL",'Planificación 2026-1'!Y:Y,"VIRTUAL")) -> 0 | DN5: =IF(C5="","",SUMIFS('Planificación 2026-1'!S:S,'Planificación 2026-1'!X:X,C5,'Planificación 2026-1'!F:F,"FILIAL",'Planificación 2026-1'!Y:Y,"PRESENCIAL")) -> 0 | DO5: =IF(C5="","",SUMIFS('Planificación 2026-1'!S:S,'Planificación 2026-1'!X:X,C5,'Planificación 2026-1'!F:F,"FILIAL",'Planificación 2026-1'!Y:Y,"HIBRIDO PRESENCIAL")) -> 0 | DP5: =TRIM(CONCATENATE(AT5,AU5,AV5,AW5,AX5,AY5,AZ5,BA5,BB5,BC5,BD5,BE5,BF5,BG5,BH5,BI5,BJ5)) -> P04 P09P31 P35 | DQ5: =IF(C5="","",SUMIFS('Planificación 2026-1'!S:S,'Planificación 2026-1'!X:X,C5,'Planificación 2026-1'!F:F,"SUNAMPE",'Planificación 2026-1'!Y:Y,"VIRTUAL")) -> 4 | DR5: =IF(C5="","",SUMIFS('Planificación 2026-1'!S:S,'Planificación 2026-1'!X:X,C5,'Planificación 2026-1'!F:F,"SUNAMPE",'Planificación 2026-1'!Y:Y,"PRESENCIAL")) -> 28 | DS5: =TRIM(CONCATENATE(BK5,BL5,BM5,BN5,BO5,BP5,BQ5,BR5,BS5,BT5,BU5,BV5,BW5,BX5,BY5,BZ5,CA5)) | DT5: =IF(C5="","",SUMIFS('Planificación 2026-1'!S:S,'Planificación 2026-1'!X:X,C5,'Planificación 2026-1'!F:F,"HUAURA",'Planificación 2026-1'!Y:Y,"VIRTUAL")) -> 0 | DU5: =IF(C5="","",SUMIFS('Planificación 2026-1'!S:S,'Planificación 2026-1'!X:X,C5,'Planificación 2026-1'!F:F,"HUAURA",'Planificación 2026-1'!Y:Y,"PRESENCIAL")) -> 0 | DV5: =SUMIFS('Planificación 2026-1'!S:S,'Planificación 2026-1'!X:X,C5,'Planificación 2026-1'!F:F,"PRINCIPAL",'Planificación 2026-1'!Y:Y,"VIRTUAL",'Planificación 2026-1'!I:I,">2") -> 0 | DW5: =SUMIFS('Planificación 2026-1'!S:S,'Planificación 2026-1'!X:X,C5,'Planificación 2026-1'!F:F,"PRINCIPAL",'Planificación 2026-1'!Y:Y,"<>VIRTUAL",'Planificación 2026-1'!I:I,">2") -> 0 | DX5: =SUMIFS('Planificación 2026-1'!S:S,'Planificación 2026-1'!X:X,C5,'Planificación 2026-1'!F:F,"SUNAMPE",'Planificación 2026-1'!Y:Y,"VIRTUAL",'Planificación 2026-1'!I:I,">2") -> 0 | DY5: =SUMIFS('Planificación 2026-1'!S:S,'Planificación 2026-1'!X:X,C5,'Planificación 2026-1'!F:F,"SUNAMPE",'Planificación 2026-1'!Y:Y,"<>VIRTUAL",'Planificación 2026-1'!I:I,">2") -> 0 | DZ5: =SUMIFS('Planificación 2026-1'!S:S,'Planificación 2026-1'!X:X,C5,'Planificación 2026-1'!F:F,"FILIAL",'Planificación 2026-1'!Y:Y,"VIRTUAL",'Planificación 2026-1'!I:I,">2") -> 0 | EA5: =SUMIFS('Planificación 2026-1'!S:S,'Planificación 2026-1'!X:X,C5,'Planificación 2026-1'!F:F,"FILIAL",'Planificación 2026-1'!Y:Y,"<>VIRTUAL",'Planificación 2026-1'!I:I,">2") -> 0 | EB5: =SUMIFS('Planificación 2026-1'!S:S,'Planificación 2026-1'!X:X,C5,'Planificación 2026-1'!F:F,"PORUMA",'Planificación 2026-1'!Y:Y,"VIRTUAL",'Planificación 2026-1'!I:I,">2") -> 0 | EC5: =SUMIFS('Planificación 2026-1'!S:S,'Planificación 2026-1'!X:X,C5,'Planificación 2026-1'!F:F,"PORUMA",'Planificación 2026-1'!Y:Y,"<>VIRTUAL",'Planificación 2026-1'!I:I,">2") -> 0 | ED5: =SUMIFS('Planificación 2026-1'!S:S,'Planificación 2026-1'!X:X,C5,'Planificación 2026-1'!F:F,"HUAURA",'Planificación 2026-1'!Y:Y,"VIRTUAL",'Planificación 2026-1'!I:I,">2") -> 0 | EE5: =SUMIFS('Planificación 2026-1'!S:S,'Planificación 2026-1'!X:X,C5,'Planificación 2026-1'!F:F,"HUAURA",'Planificación 2026-1'!Y:Y,"<>VIRTUAL",'Planificación 2026-1'!I:I,">2") -> 0 | EF5: =SUMIFS('Planificación 2026-1'!S:S,'Planificación 2026-1'!X:X,C5,'Planificación 2026-1'!F:F,"PRINCIPAL",'Planificación 2026-1'!Y:Y,"VIRTUAL",'Planificación 2026-1'!I:I,"<3") -> 0 | EG5: =SUMIFS('Planificación 2026-1'!S:S,'Planificación 2026-1'!X:X,C5,'Planificación 2026-1'!F:F,"PRINCIPAL",'Planificación 2026-1'!Y:Y,"<>VIRTUAL",'Planificación 2026-1'!I:I,"<3") -> 8 | EH5: =SUMIFS('Planificación 2026-1'!S:S,'Planificación 2026-1'!X:X,C5,'Planificación 2026-1'!F:F,"SUNAMPE",'Planificación 2026-1'!Y:Y,"VIRTUAL",'Planificación 2026-1'!I:I,"<3") -> 4 | EI5: =SUMIFS('Planificación 2026-1'!S:S,'Planificación 2026-1'!X:X,C5,'Planificación 2026-1'!F:F,"SUNAMPE",'Planificación 2026-1'!Y:Y,"<>VIRTUAL",'Planificación 2026-1'!I:I,"<3") -> 28 | EJ5: =SUMIFS('Planificación 2026-1'!S:S,'Planificación 2026-1'!X:X,C5,'Planificación 2026-1'!F:F,"FILIAL",'Planificación 2026-1'!Y:Y,"VIRTUAL",'Planificación 2026-1'!I:I,"<3") -> 0 | EK5: =SUMIFS('Planificación 2026-1'!S:S,'Planificación 2026-1'!X:X,C5,'Planificación 2026-1'!F:F,"FILIAL",'Planificación 2026-1'!Y:Y,"<>VIRTUAL",'Planificación 2026-1'!I:I,"<3") -> 0 | EL5: =SUMIFS('Planificación 2026-1'!S:S,'Planificación 2026-1'!X:X,C5,'Planificación 2026-1'!F:F,"PORUMA",'Planificación 2026-1'!Y:Y,"VIRTUAL",'Planificación 2026-1'!I:I,"<3") -> 0 | EM5: =SUMIFS('Planificación 2026-1'!S:S,'Planificación 2026-1'!X:X,C5,'Planificación 2026-1'!F:F,"PORUMA",'Planificación 2026-1'!Y:Y,"<>VIRTUAL",'Planificación 2026-1'!I:I,"<3") -> 0 | EN5: =SUMIFS('Planificación 2026-1'!S:S,'Planificación 2026-1'!X:X,C5,'Planificación 2026-1'!F:F,"HUAURA",'Planificación 2026-1'!Y:Y,"VIRTUAL",'Planificación 2026-1'!I:I,"<3") -> 0 | EO5: =SUMIFS('Planificación 2026-1'!S:S,'Planificación 2026-1'!X:X,C5,'Planificación 2026-1'!F:F,"HUAURA",'Planificación 2026-1'!Y:Y,"<>VIRTUAL",'Planificación 2026-1'!I:I,"<3") -> 0 | EP5: =EJ5+DZ5+EA5+EK5 -> 0 | EQ5: =EO5+EN5+EE5+ED5 -> 0 | ER5: =EL5+EM5+EC5+EB5 -> 0 | ES5: =EG5+EF5+DW5+DV5 -> 8 | ET5: =EI5+EH5+DY5+DX5 -> 32 | EU5: =SUM(EP5:ET5) -> 40 | EV5: =EXACT(EU5,E5) -> TRUE | EX5: =DV5+DZ5+ED5+EF5+EJ5+EN5+DX5+EH5 -> 4 | EY5: =DW5+EA5+EE5+EG5+EK5+EO5+DY5+EI5 -> 36 | EZ5: =EXACT(SUM(EX5:EY5),E5) -> TRUE | FA5: =IF(AND(DW5=0,EA5=0,EE5=0),"",IF(COUNTIF(DW5:EE5,">0")=1,IF(DW5>0,"SEDE",IF(EA5>0,"FILIAL","HUAURA")),IF(COUNTIF(DW5:EE5,">0")=2,IF(AND(DW5>0,EA5>0),"SEDE-FILIAL",IF(AND(DW5>0,EE5>0),"SEDE-HUAURA","FILIAL-HUAURA")),"SEDE-FILIAL-HUAURA"))) | FB5: =IF(EX5=0,"PRESENCIAL",IF(EY5=0,"VIRTUAL",IF(EX5>EY5,"MAS VIRTUAL",IF(EY5>EX5,"MAS PRESENCIAL","AMBOS")))) -> MAS PRESENCIAL
