Workbook

Sheet RENOVACIÓN TC FCS
B6: PROPUESTA DE RENOVACIÓN DOCENTE TC PARA SEMESTRE ACADÉMICO 2026-1 FACULTAD DE CIENCIAS DE LA SALUD
B8: N° | C8: DNI | D8: APELLIDOS Y NOMBRES | E8: FACULTAD | F8: ESCUELA PROFESIONAL | G8: LOCAL | H8: MODALIDAD | I8: N° HORAS LECTIVAS | J8: N° HORAS NO LECTIVAS | K8: TOAL DE HORAS | L8: NOTA EVALUACIÓN DEL DESEMPEÑO 2025-2 | M8: CARGO | N8: CORREO ELECTRÓNICO INSTITUCIONAL | O8: N° CELULAR | P8: OBSERVACIONES
B9: 1 | C9: 45549528 | D9: ACHARTE CHAMPI WALTER JESUS | E9: FCS | F9: ENFERMERÍA | G9: SEDE | H9: VIRTUAL | I9: 40 | K9: =+I9+J9 -> 40 | L9: 17.51 | N9: walter.acharte@autonomadeica.edu.pe | O9: 969804997
B10: 2 | C10: 40364065 | D10: ACOSTA VILLAVICENCIO BLANCA AURORA | E10: FCS | F10: OBSTETRICIA - EEGG | G10: SEDE | H10: MAS PRESENCIAL | I10: 32 | K10: =+I10+J10 -> 32 | L10: 15.96 | N10: blanca.acosta@autonomadeica.edu.pe | O10: 956 722222
B11: 3 | C11: 43041422 | D11: ANTEZANA CHINQUILLO JOSE GIANCARLO | E11: FCS | F11: MEDICINA HUMANA | G11: PORUMA | H11: PRESENCIAL | I11: 32 | K11: =+I11+J11 -> 32 | L11: 15.44 | N11: jose.antezana@autonomadeica.edu.pe | O11: 984949379
B12: 4 | C12: 42508963 | D12: APOLAYA PAREJA BERTHA ESTHER | E12: FCS | F12: OBSTETRICIA | G12: SEDE | H12: MAS PRESENCIAL | I12: 24 | K12: =+I12+J12 -> 24 | L12: 17.75 | N12: bertha.apolaya@autonomadeica.edu.pe | O12: 923395834
B13: 5 | C13: 21427721 | D13: ARQUIÑEGO SOLAR HENRRY MARCOS | E13: FCS | F13: ENFERMERÍA | G13: FILIAL | H13: MAS VIRTUAL | I13: 30 | K13: =+I13+J13 -> 30 | L13: 15.37 | N13: henrry.arquinego@autonomadeica.edu.pe | O13: 956467500
B14: 6 | C14: 40385643 | D14: ARREDONDO ZELA SONIA OLIVIA | E14: FCS | F14: OBSTETRICIA - EEGG | G14: SEDE | H14: PRESENCIAL | I14: 38 | K14: =+I14+J14 -> 38 | L14: 15.91 | N14: sonia.arredondo@autonomadeica.edu.pe | O14: 978 833677
B15: 7 | C15: 80034938 | D15: ARROYO PACHAS JOSE LUIS | E15: FCS | F15: ENFERMERÍA | G15: SEDE | H15: MAS PRESENCIAL | I15: 32 | K15: =+I15+J15 -> 32 | L15: 14.12 | N15: jose.arroyo@autonomadeica.edu.pe | O15: 965346069
B16: 8 | C16: 21536202 | D16: ATME ROJAS DAVEY RAUL | E16: FCS | F16: PSICOLOGÍA | G16: FILIAL | H16: MAS VIRTUAL | I16: 25 | K16: =+I16+J16 -> 25 | L16: 16.25 | N16: davey.atme@autonomadeica.edu.pe | O16: 956445166_x000D_
B17: 9 | C17: 21836179 | D17: ATUNCAR VASQUEZ RICARDO MANUEL | E17: FCS | F17: OBSTETRICIA | G17: SEDE | H17: MAS PRESENCIAL | I17: 34 | K17: =+I17+J17 -> 34 | L17: 15.73 | N17: ricardo.atuncar@autonomadeica.edu.pe | O17: 955923228
B18: 10 | C18: 8822479 | D18: AYBAR HUAMANI JUSTINIANO | E18: FCS | F18: ENFERMERÍA - EEGG | G18: SEDE | H18: MAS PRESENCIAL | I18: 39 | K18: =+I18+J18 -> 39 | L18: 17.06 | N18: justiniano.aybar@autonomadeica.edu.pe | O18: 995144584
B19: 11 | C19: 21416373 | D19: BARRIOS GABRIEL SONIA EDITH | E19: FCS | F19: MEDICINA HUMANA - EEGG | G19: PORUMA | H19: PRESENCIAL | I19: 30 | K19: =+I19+J19 -> 30 | L19: 15.57 | N19: sonia.barrios@autonomadeica.edu.pe | O19: 966713033
B20: 12 | C20: 15738929 | D20: BAZALAR GANOZA BEATRIZ ROSARIO | E20: FCS | F20: ENFERMERÍA - EEGG | G20: HUAURA | H20: PRESENCIAL | I20: 30 | K20: =+I20+J20 -> 30 | L20: 15.07 | N20: beatriz.bazalar@autonomadeica.edu.pe | O20: 5774800 / 940029503
B21: 13 | C21: 70431834 | D21: BELLIDO LEON FRANK JUNIOR | E21: FCS | F21: ENFERMERÍA | G21: SEDE | H21: PRESENCIAL | I21: 31 | K21: =+I21+J21 -> 31 | L21: 15.69 | N21: frank.bellido@autonomadeica.edu.pe | O21: 945102061
B22: 14 | C22: 72580385 | D22: BENAVIDES ESCRIBA VICTOR MANUEL | E22: FCS | F22: ENFERMERÍA | G22: SEDE | H22: MAS PRESENCIAL | I22: 32 | K22: =+I22+J22 -> 32 | L22: 16.31 | N22: manuel.benavides@autonomadeica.edu.pe | O22: 950357206
B23: 15 | C23: 71819567 | D23: BENDEZU HUAROTO ALEX RAUL | E23: FCS | F23: MEDICINA HUMANA - EEGG | G23: PORUMA | H23: MAS PRESENCIAL | I23: 37 | K23: =+I23+J23 -> 37 | L23: 16.53 | N23: alex.bendezu@autonomadeica.edu.pe | O23: 999558590
B24: 16 | C24: 42825709 | D24: CABRERA PIMENTEL HELGA ROXANA | E24: FCS | F24: ENFERMERÍA | G24: FILIAL | H24: AMBOS | I24: 32 | K24: =+I24+J24 -> 32 | L24: 15.60 | N24: helga.cabrera@autonomadeica.edu.pe | O24: 964743177
B25: 17 | C25: 21440811 | D25: CABRERA VIZARRETA MARTHA LUISA | E25: FCS | F25: MEDICINA HUMANA - EEGG | G25: PORUMA | H25: MAS PRESENCIAL | I25: 33 | K25: =+I25+J25 -> 33 | L25: 16.03 | N25: martha.cabrera@autonomadeica.edu.pe | O25: 976110252
B26: 18 | C26: 21567738 | D26: CAHUANA MUÑOZ BETTY MARISEL | E26: FCS | F26: OBSTETRICIA | G26: FILIAL | H26: PRESENCIAL | I26: 32 | K26: =+I26+J26 -> 32 | L26: 14.69 | N26: betty.cahuana@autonomadeica.edu.pe | O26: 953734738
B27: 19 | C27: 21453025 | D27: CALLAÑAUPA VARGAS JULIA ANTONIA | E27: FCS | F27: MEDICINA HUMANA | G27: SUNAMPE | H27: MAS VIRTUAL | I27: 22 | K27: =+I27+J27 -> 22 | L27: 14.91 | N27: julia.callanaupa@autonomadeica.edu.pe | O27: 955626346
B28: 20 | C28: 40056370 | D28: CAMPOS CARDENAS SANDRA GISELA | E28: FCS | F28: ENFERMERÍA | G28: SEDE | H28: MAS VIRTUAL | I28: 30 | K28: =+I28+J28 -> 30 | L28: 14.24 | N28: sandra.campos@autonomadeica.edu.pe | O28: 951988838
B29: 21 | C29: 46475398 | D29: CANDELA LEVANO CECIL MASSIEL | E29: FCS | F29: ENFERMERÍA | G29: FILIAL | H29: VIRTUAL | I29: 24 | K29: =+I29+J29 -> 24 | L29: 15.82 | N29: cecil.candela@autonomadeica.edu.pe | O29: 949369092
B30: 22 | C30: 21463142 | D30: CARRASCO VASQUEZ JOSE LUIS | E30: FCS | F30: OBSTETRICIA | G30: SEDE | H30: PRESENCIAL | I30: 38 | K30: =+I30+J30 -> 38 | L30: 13.91 | N30: jose.carrasco@autonomadeica.edu.pe | O30: 968974470
B31: 23 | C31: 41845220 | D31: CASTRO VILCAPUMA NATHIA ERIKA | E31: FCS | F31: OBSTETRICIA - EEGG | G31: SEDE | H31: PRESENCIAL | I31: 35 | K31: =+I31+J31 -> 35 | L31: 15.37 | N31: nathia.castro@autonomadeica.edu.pe | O31: 999642883
B32: 24 | C32: 21418654 | D32: CENTENO OCHOA FANNY EDITH | E32: FCS | F32: ENFERMERÍA | G32: FILIAL | H32: MAS VIRTUAL | I32: 28 | K32: =+I32+J32 -> 28 | L32: 14.44 | N32: fanny.centeno@autonomadeica.edu.pe | O32: 947827681
B33: 25 | C33: 45440179 | D33: CHACALTANA CORDERO HILDA GLORIA | E33: FCS | F33: ENFERMERÍA | G33: FILIAL | H33: MAS PRESENCIAL | I33: 32 | K33: =+I33+J33 -> 32 | L33: 16.54 | N33: hilda.chacaltana@autonomadeica.edu.pe | O33: 982739733_x000D_
B34: 26 | C34: 32111220 | D34: COLONIA OSORIO NIEVES PILAR | E34: FCS | F34: ENFERMERÍA - EEGG | G34: HUAURA | H34: PRESENCIAL | I34: 37 | K34: =+I34+J34 -> 37 | L34: 15.83 | N34: nieves.colonia@autonomadeica.edu.pe | O34: 966799630
B35: 27 | C35: 21426247 | D35: COMECA VILDOZO ANGEL ORLANDO | E35: FCS | F35: MEDICINA HUMANA | G35: SUNAMPE | H35: PRESENCIAL | I35: 39 | K35: =+I35+J35 -> 39 | L35: 14.69 | N35: angel.comeca@autonomadeica.edu.pe | O35: 992158166/956620126
B36: 28 | C36: 47849946 | D36: CORDOVA GUTIERREZ MARCO ANDREE | E36: FCS | F36: TECNOLOGÍA MÉDICA | G36: SUNAMPE | H36: MAS PRESENCIAL | I36: 32 | K36: =+I36+J36 -> 32 | L36: 15.84 | N36: marco.cordova@autonomadeica.edu.pe | O36: 934 260 986
B37: 29 | C37: 21533626 | D37: CUBA MAYURI RICHARD ALEJANDRO | E37: FCS | F37: ENFERMERÍA | G37: SEDE | H37: MAS VIRTUAL | I37: 33 | K37: =+I37+J37 -> 33 | L37: 15.56 | N37: richard.cuba@autonomadeica.edu.pe | O37: 942659212
B38: 30 | C38: 73039674 | D38: CUELLO GARCIA MEGALLY FIORELLA | E38: FCS | F38: MEDICINA HUMANA | G38: PORUMA | H38: VIRTUAL | I38: 28 | K38: =+I38+J38 -> 28 | L38: 16.23 | N38: megally.cuello@autonomadeica.edu.pe | O38: 951794771
B39: 31 | C39: 40689619 | D39: DEL PINO ASCONA DENNIS YVONNE | E39: FCS | F39: PSICOLOGÍA | G39: FILIAL | H39: VIRTUAL | I39: 39 | K39: =+I39+J39 -> 39 | L39: 16.47 | N39: dennis.delpino@autonomadeica.edu.pe | O39: 991041688
B40: 32 | C40: 15586796 | D40: DIAZ BAZALAR WILLIAM JESUS | E40: FCS | F40: ENFERMERÍA - EEGG | G40: HUAURA | H40: PRESENCIAL | I40: 32 | K40: =+I40+J40 -> 32 | L40: 14.67 | N40: william.diaz@autonomadeica.edu.pe | O40: 993456461
B41: 34 | C41: 41134475 | D41: DURAND DIEZ FRANCISCO | E41: FCS | F41: MEDICINA HUMANA | G41: PORUMA | H41: MAS VIRTUAL | I41: 36 | K41: =+I41+J41 -> 36 | L41: 15.86 | N41: francisco.durand@autonomadeica.edu.pe | O41: 991602985
B42: 35 | C42: 72254013 | D42: ESPINOZA ALARCON YADY | E42: FCS | F42: ENFERMERÍA | G42: SEDE | H42: VIRTUAL | I42: 40 | K42: =+I42+J42 -> 40 | L42: 18.06 | N42: yady.espinoza@autonomadeica.edu.pe | O42: 925777177
B43: 36 | C43: 42684701 | D43: ESPINOZA BARRIOS LUZ MARIANELA | E43: FCS | F43: ENFERMERÍA | G43: FILIAL | H43: MAS VIRTUAL | I43: 26 | K43: =+I43+J43 -> 26 | L43: 16.35 | N43: luz.espinoza@autonomadeica.edu.pe | O43: 948981510
B44: 37 | C44: 21529591 | D44: ESPINOZA TARQUI MAGDALENA | E44: FCS | F44: ENFERMERÍA | G44: FILIAL | H44: PRESENCIAL | I44: 32 | K44: =+I44+J44 -> 32 | L44: 15.28 | N44: magdalena.espinoza@autonomadeica.edu.pe | O44: 955601089
B45: 38 | C45: 6919367 | D45: GALVAN CANTA MARIA MAGDALENA | E45: FCS | F45: OBSTETRICIA | G45: SEDE | H45: PRESENCIAL | I45: 36 | K45: =+I45+J45 -> 36 | L45: 15.33 | N45: maria.galvan@autonomadeica.edu.pe | O45: 956217730
B46: 39 | C46: 21534061 | D46: GOMEZ HERNANDEZ FREDDY WILFREDO | E46: FCS | F46: MEDICINA HUMANA | G46: PORUMA | H46: VIRTUAL | I46: 26 | K46: =+I46+J46 -> 26 | L46: 15.42 | N46: wilfredo.hernandez@autonomadeica.edu.pe | O46: 961984611
...

Sheet RENOVACIÓN TP FCS
B6: PROPUESTA DE RENOVACIÓN DOCENTE TP PARA SEMESTRE ACADÉMICO 2026-1 FACULTAD DE CIENCIAS DE LA SALUD
B8: N° | C8: DNI | D8: APELLIDOS Y NOMBRES | E8: FACULTAD | F8: ESCUELA PROFESIONAL | G8: LOCAL | H8: MODALIDAD | I8: N° HORAS LECTIVAS | J8: NOTA EVALUACIÓN DEL DESEMPEÑO 2025-2 | K8: CORREO ELECTRÓNICO INSTITUCIONAL | L8: N° CELULAR | M8: OBSERVACIONES
B9: 1 | C9: 45228337 | D9: ALIAGA RUIZ MINA ANGELICA | E9: FCS | F9: PSICOLOGÍA | G9: SEDE | H9: PRESENCIAL | I9: 13 | J9: 15.71 | K9: mina.aliaga@autonomadeica.edu.pe | L9: 936774790
B10: 2 | C10: 21525109 | D10: ALVAREZ GARCIA TERESA ELVIRA | E10: FCS | F10: MEDICINA HUMANA | G10: PORUMA | H10: PRESENCIAL | I10: 17 | J10: 14.27 | K10: teresa.alvarez@autonomadeica.edu.pe | L10: 998672766
B11: 3 | C11: 44371485 | D11: ANCAJIMA RUIZ ANDREA BETTY | E11: FCS | F11: ENFERMERÍA - EEGG | G11: FILIAL | H11: MAS PRESENCIAL | I11: 19 | J11: 16.82 | K11: andrea.ancajima@autonomadeica.edu.pe | L11: 973826973
B12: 4 | C12: 21560679 | D12: ANICAMA BERNAOLA PEDRO ARTURO | E12: FCS | F12: MEDICINA HUMANA | G12: PORUMA | H12: PRESENCIAL | I12: 14 | J12: 15.36 | K12: pedro.anicama@autonomadeica.edu.pe | L12: 959348713
B13: 5 | C13: 22299955 | D13: AQUIJE DAPOZZO EDWAR VIDAL | E13: FCS | F13: ENFERMERÍA | G13: FILIAL | H13: VIRTUAL | I13: 18 | J13: 15.92 | K13: edwar.aquije@autonomadeica.edu.pe | L13: 961510609
B14: 6 | C14: 21546746 | D14: ARIZOLA AGUADO ALICIA ANTOINETTE | E14: FCS | F14: MEDICINA HUMANA | G14: PORUMA | H14: PRESENCIAL | I14: 15 | J14: 15.17 | K14: alicia.arizola@autonomadeica.edu.pe | L14: 950999223
B15: 7 | C15: 42841966 | D15: AROTUMA GRANDA HECTOR JUAN CARLOS | E15: FCS | F15: MEDICINA HUMANA | G15: PORUMA | H15: PRESENCIAL | I15: 10 | J15: 16.46 | K15: hector.arotuma@autonomadeica.edu.pe | L15: 971616753
B16: 8 | C16: 7703595 | D16: ATUNCAR SUENG DORA ROSARIO | E16: FCS | F16: PSICOLOGÍA | G16: SEDE | H16: PRESENCIAL | I16: 14 | J16: 15.19 | K16: dora.atuncar@autonomadeica.edu.pe | L16: 997565823
B17: 9 | C17: 40139812 | D17: BAÑOS RAMOS JUAN CARLOS | E17: FCS | F17: PSICOLOGÍA | G17: SEDE | H17: PRESENCIAL | I17: 14 | J17: 15.01 | K17: juancarlos.ramos@autonomadeica.edu.pe | L17: 987967937
B18: 10 | C18: 21462854 | D18: BARRIENTOS RAMOS VICTOR HUGO | E18: FCS | F18: ENFERMERÍA | G18: FILIAL | H18: VIRTUAL | I18: 15 | J18: 13.02 | K18: victor.barrientos@autonomadeica.edu.pe | L18: 955823795
B19: 11 | C19: 9100625 | D19: BERROSPI VARGAS ANA ELVA | E19: FCS | F19: OBSTETRICIA | G19: FILIAL | H19: MAS PRESENCIAL | I19: 18 | J19: 16.73 | K19: ana.berrospi@autonomadeica.edu.pe | L19: 956001506/956722157
B20: 12 | C20: 41545772 | D20: CABRERA VELASQUEZ MEYLAN ALLIZA | E20: FCS | F20: MEDICINA HUMANA | G20: PORUMA | H20: PRESENCIAL | I20: 10 | J20: 14.05 | K20: meylan.cabrera@autonomadeica.edu.pe | L20: 948423070_x000D_
B21: 13 | C21: 72676034 | D21: CAHUA DIAZ DEYSI MARIBEL | E21: FCS | F21: OBSTETRICIA | G21: FILIAL | H21: MAS PRESENCIAL | I21: 12 | J21: 15.84 | K21: deysi.cahua@autonomadeica.edu.pe | L21: 979042565
B22: 14 | C22: 6160287 | D22: CAMPIAN LAZO YONAL IGNACIO | E22: FCS | F22: MEDICINA HUMANA - EEGG | G22: SUNAMPE | H22: PRESENCIAL | I22: 14 | J22: 15.33 | K22: yonal.campian@autonomadeica.edu.pe | L22: 999749496
B23: 15 | C23: 15727165 | D23: CANALES INGA WENDY VIVIANA | E23: FCS | F23: ENFERMERÍA - EEGG | G23: HUAURA | H23: MAS PRESENCIAL | I23: 16 | J23: 16.24 | K23: viviana.canales@autonomadeica.edu.pe | L23: 988490896
B24: 16 | C24: 6276541 | D24: CANDELA CUBILLAS HUBER AGUSTIN | E24: FCS | F24: PSICOLOGÍA | G24: SEDE | H24: MAS PRESENCIAL | I24: 14 | J24: 15.12 | K24: huber.candela@autonomadeica.edu.pe | L24: 988178147
B25: 17 | C25: 42363036 | D25: CARBONEL RAMIREZ HANS HENRY | E25: FCS | F25: MEDICINA HUMANA | G25: PORUMA | H25: PRESENCIAL | I25: 11 | J25: 13.48 | K25: hans.carbonel@autonomadeica.edu.pe | L25: 959858065
B26: 18 | C26: 10350121 | D26: CARDENAS GALVEZ YESE YOBANA | E26: FCS | F26: ENFERMERÍA | G26: SEDE | H26: VIRTUAL | I26: 12 | J26: 14.30 | K26: yese.cardenas@autonomadeica.edu.pe | L26: 949659055
B27: 19 | C27: 43036474 | D27: CARDENAS LANDEO NANCY | E27: FCS | F27: MEDICINA HUMANA | G27: SUNAMPE | H27: PRESENCIAL | I27: 15 | J27: 13.08 | K27: nancy.cardenas@autonomadeica.edu.pe | L27: 932948721
B28: 20 | C28: 43456897 | D28: CARDENAS ZEDANO WILLIAM JESUS | E28: FCS | F28: PSICOLOGÍA | G28: FILIAL | H28: PRESENCIAL | I28: 15 | J28: 15.53 | K28: willian.cardenas@autonomadeica.edu.pe | L28: 968974470
B29: 21 | C29: 41485219 | D29: CASTILLA TUBILLA JEANINA LISETH | E29: FCS | F29: OBSTETRICIA | G29: SEDE | H29: PRESENCIAL | I29: 12 | J29: 15.67 | K29: jeanina.castilla@autonomadeica.edu.pe | L29: 957905278
B30: 22 | C30: 22309591 | D30: CASTILLO ESPINOZA GUILLERMO EMILIO | E30: FCS | F30: MEDICINA HUMANA | G30: SUNAMPE | H30: PRESENCIAL | I30: 15 | J30: 14.77 | K30: guillermo.castillo@autonomadeica.edu.pe | L30: 984474904
B31: 23 | C31: 7469293 | D31: CASTRO ANTEZANA HARDY TERESA | E31: FCS | F31: OBSTETRICIA | G31: FILIAL | H31: PRESENCIAL | I31: 12 | J31: 14.33 | K31: hardy.castro@autonomadeica.edu.pe
B32: 24 | C32: 21522829 | D32: CHACALTANA ESCATE CARMEN EDELMIRA | E32: FCS | F32: OBSTETRICIA | G32: FILIAL | H32: PRESENCIAL | I32: 16 | J32: 15.13 | K32: carmen.chacaltana@autonomadeica.edu.pe | L32: 978580911
B33: 25 | C33: 70504650 | D33: CHAVARRIA DELGADO JANIS JAVIER TOMAS | E33: FCS | F33: MEDICINA HUMANA | G33: SUNAMPE | H33: PRESENCIAL | I33: 18 | J33: 16.76 | K33: janis.chavarria@autonomadeica.edu.pe | L33: 930516314
B34: 26 | C34: 43429701 | D34: CHECCLLO TENORIO ADIN MEZOLLAM | E34: FCS | F34: PSICOLOGÍA | G34: FILIAL | H34: PRESENCIAL | I34: 17 | J34: 14.36 | K34: adin.checcllo@autonomadeica.edu.pe | L34: 923913515
B35: 27 | C35: 41222348 | D35: COCHACHI PURAY JAQUELINE NOEMI | E35: FCS | F35: ENFERMERÍA - EEGG | G35: FILIAL | H35: PRESENCIAL | I35: 14 | J35: 15.87 | K35: jaqueline.cochachi@autonomadeica.edu.pe | L35: 931900971
B36: 28 | C36: 40965725 | D36: COLQUEPISCO PAUCAR NILO TEODORICO | E36: FCS | F36: ENFERMERÍA - EEGG;PSICOLOGÍA - EEGG;OBSTETRICIA - EEGG | G36: SEDE | H36: PRESENCIAL | I36: 15 | J36: 15.98 | K36: nilo.colquepisco@autonomadeica.edu.pe | L36: 961851421
B37: 29 | C37: 42657141 | D37: CORNEJO PURILLA SUGEY PILAR | E37: FCS | F37: PSICOLOGÍA - EEGG | G37: FILIAL | H37: PRESENCIAL | I37: 12 | J37: 15.79 | K37: sugey.cornejo@autonomadeica.edu.pe | L37: 994331971
B38: 30 | C38: 46941666 | D38: CORREA VERGARA JORGE LUIS | E38: FCS | F38: MEDICINA HUMANA | G38: PORUMA | H38: PRESENCIAL | I38: 11 | J38: 16.29 | K38: jorge.correa@autonomadeica.edu.pe | L38: 949680011_x000D_
B39: 31 | C39: 71472171 | D39: COSIATADO URBANO RAUL JESUS | E39: FCS | F39: PSICOLOGÍA - EEGG | G39: FILIAL | H39: MAS PRESENCIAL | I39: 16 | J39: 16.82 | K39: raul.cosiatado@autonomadeica.edu.pe | L39: 990636567
B40: 32 | C40: 21560357 | D40: CRISOSTOMO POMA PEDRO GUSTAVO | E40: FCS | F40: MEDICINA HUMANA | G40: PORUMA | H40: PRESENCIAL | I40: 16 | J40: 15.50 | K40: pedro.crisostomo@autonomadeica.edu.pe | L40: 939473322
B41: 33 | C41: 70539299 | D41: CUBA CARRILLO FATIMA ELIZABETH | E41: FCS | F41: OBSTETRICIA | G41: FILIAL | H41: MAS PRESENCIAL | I41: 16 | J41: 15.34 | K41: fatima.cuba@autonomadeica.edu.pe | L41: 922933831
B42: 34 | C42: 41430382 | D42: DE LA CRUZ CHIPANA DE RAMIREZ MARIA DEL ROSARIO | E42: FCS | F42: MEDICINA HUMANA - EEGG | G42: PORUMA | H42: PRESENCIAL | I42: 8 | J42: 14.93 | K42: delrosario.delacruz@autonomadeica.edu.pe | L42: 056-403026 / 951530280
B43: 35 | C43: 21547326 | D43: DE LA CRUZ CHIPANA HILDA MILAGRITOS | E43: FCS | F43: PSICOLOGÍA | G43: SEDE | H43: VIRTUAL | I43: 15 | J43: 16.90 | K43: milagritos.delacruz@autonomadeica.edu.pe | L43: 956998231_x000D_
B44: 36 | C44: 21800872 | D44: DEL RIO MENDOZA JENY ROSANNA JULIA | E44: FCS | F44: MEDICINA HUMANA | G44: PORUMA | H44: PRESENCIAL | I44: 11 | J44: 14.22 | K44: jeny.delrio@autonomadeica.edu.pe | L44: 956622171
B45: 37 | C45: 40509747 | D45: DELGADO RIOS FATIMA NATALIA | E45: FCS | F45: JEFE DE PRACTICAS | G45: JEFE DE PRACTICAS | H45: PRESENCIAL | I45: 16 | K45: #N/A | L45: #N/A
B46: 38 | C46: 45813502 | D46: DIAZ RODRIGUEZ JUAN JOSE | E46: FCS | F46: PSICOLOGÍA | G46: FILIAL | H46: MAS VIRTUAL | I46: 13 | J46: 15.06 | K46: juanjose.diaz@autonomadeica.edu.pe | L46: 910548973
...

Sheet RENOVAC TC FICA
B6: PROPUESTA DE RENOVACIÓN DOCENTE TC PARA SEMESTRE ACADÉMICO 2026-1 FACULTAD DE INGENIERÍA, CIENCIAS Y ADMINISTRACIÓN
B8: N° | C8: DNI | D8: APELLIDOS Y NOMBRES | E8: FACULTAD | F8: ESCUELA PROFESIONAL | G8: LOCAL | H8: MODALIDAD | I8: N° HORAS LECTIVAS | J8: N° HORAS NO LECTIVAS | K8: TOAL DE HORAS | L8: NOTA EVALUACIÓN DEL DESEMPEÑO 2025-2 | M8: CARGO | N8: CORREO ELECTRÓNICO INSTITUCIONAL | O8: N° CELULAR | P8: OBSERVACIONES
B9: 1 | C9: 43517817 | D9: DE LA CRUZ SOSA JAKELINE MELINA | E9: FICA | F9: DERECHO - EEGG | G9: HUAURA | H9: PRESENCIAL | I9: 32 | K9: =+I9+J9 -> 32 | L9: 15.76 | N9: jakeline.delacruz@autonomadeica.edu.pe | O9: 951222024 | P9: -
B10: 2 | C10: 40428220 | D10: MANDAMIENTO GRADOS DAMARIS TELMA | E10: FICA | F10: DERECHO - EEGG | G10: HUAURA | H10: PRESENCIAL | I10: 32 | K10: =+I10+J10 -> 32 | L10: 15.89 | N10: damaris.mandamiento@autonomadeica.edu.pe | O10: 992990608 | P10: -
B11: 3 | C11: 21814775 | D11: ALMEYDA AVALOS CESAR AUGUSTO | E11: FICA | F11: DERECHO | G11: SEDE | H11: MAS PRESENCIAL | I11: 33 | K11: =+I11+J11 -> 33 | L11: 16.7 | N11: cesar.almeyda@autonomadeica.edu.pe | O11: 955906921 | P11: -
B12: 4 | E12: FICA
B13: 5 | E13: FICA
B14: 6 | E14: FICA
B15: 7 | E15: FICA
B16: 8 | E16: FICA
B17: 9 | E17: FICA
B18: 10 | E18: FICA
B19: 11 | E19: FICA
B20: 12 | E20: FICA
B21: 13 | E21: FICA
B22: 14 | E22: FICA
B23: 15 | E23: FICA
... B57: 50 | E57: FICA

Sheet RENOVAC TP FICA
B6: PROPUESTA DE RENOVACIÓN DOCENTE TP PARA SEMESTRE ACADÉMICO 2026-1 FACULTAD DE INGENIERÍA, CIENCIAS Y ADMINISTRACIÓN
B8: N° | C8: DNI | D8: APELLIDOS Y NOMBRES | E8: FACULTAD | F8: ESCUELA PROFESIONAL | G8: LOCAL | H8: MODALIDAD | I8: N° HORAS LECTIVAS | J8: NOTA EVALUACIÓN DEL DESEMPEÑO 2025-2 | K8: CORREO ELECTRÓNICO INSTITUCIONAL | L8: N° CELULAR | M8: OBSERVACIONES
B9: 1 | C9: 41239504 | D9: PADILLA HIZO PEDRO HERNAN | E9: FICA | F9: ADMINISTRACION DE EMPRESAS | G9: HUAURA | H9: PRESENCIAL | I9: 16 | J9: 15.14 | K9: pedro.padilla@autonomadeica.edu.pe | L9: 992085961 | M9: -
B10: 2 | C10: 33826021 | D10: PARIHUAMAN QUINDE GERALDINA REBECA | E10: FICA | F10: ADMINISTRACION DE EMPRESAS - EEGG | G10: HUAURA | H10: PRESENCIAL | I10: 15 | J10: 15.29 | K10: geraldina.parihuaman@autonomadeica.edu.pe | L10: 989038202 | M10: -
B11: 3 | C11: 42212783 | D11: PEREZ RETUERTO RONY GEANCARLO | E11: FICA | F11: DERECHO - EEGG | G11: HUAURA | H11: PRESENCIAL | I11: 10 | J11: 14.41 | K11: rony.perez@autonomadeica.edu.pe | L11: 960064109 | M11: -
B12: 4 | C12: 40822577 | D12: PIMENTEL RETUERTO CARMEN ANDREA | E12: FICA | F12: DERECHO - EEGG | G12: HUAURA | H12: PRESENCIAL | I12: 16 | J12: 14.53 | K12: carmen.pimentel@autonomadeica.edu.pe | L12: 957786821 | M12: -
B13: 5 | C13: 08684196 | D13: REQUENA GARCIA MARIA DEL ROSARIO | E13: FICA | F13: ADMINISTRACION DE EMPRESAS - EEGG | G13: HUAURA | H13: PRESENCIAL | I13: 10 | J13: 15.5 | K13: maria.requena@autonomadeica.edu.pe | L13: 940716638 | M13: -
B14: 6 | C14: 41208519 | D14: REYES ROMAN CARLOS ARTURO | E14: FICA | F14: DERECHO - EEGG | G14: HUAURA | H14: PRESENCIAL | I14: 15 | J14: 15.19 | K14: arturo.reyes@autonomadeica.edu.pe | L14: 985001402 | M14: -
B15: 7 | C15: 44398451 | D15: RIOS SANTIAGO WILSON CESAR | E15: FICA | F15: DERECHO - EEGG | G15: HUAURA | H15: PRESENCIAL | I15: 14 | J15: 14.84 | K15: wilson.rios@autonomadeica.edu.pe | L15: 989336775 | M15: -
B16: 8 | C16: 45165102 | D16: SANCHEZ SOTIL KENNICK ENRIQUE | E16: FICA | F16: DERECHO - EEGG | G16: HUAURA | H16: PRESENCIAL | I16: 8 | J16: 14.51 | K16: kennick.sanchez@autonomadeica.edu.pe | L16: 952944920 | M16: -
B17: 9 | C17: 21814921 | D17: AGUADO APOLAYA RAUL HERNANDO | E17: FICA | F17: INGENIERIA INDUSTRIAL | G17: SEDE | H17: PRESENCIAL | I17: 19 | J17: 16.35 | K17: raul.aguado@autonomadeica.edu.pe | L17: 906408102 | M17: -
B18: 10 | C18: 21522173 | D18: AGUIRRE ESPINOZA MONICA WENDY | E18: FICA | F18: DERECHO | G18: FILIAL | H18: VIRTUAL | I18: 16 | J18: 15.61 | K18: monica.aguirre@autonomadeica.edu.pe | L18: 920660685 | M18: -
B19: 11 | C19: 21569287 | D19: ALCANTARA FARFAN JUAN CARLOS | E19: FICA | F19: DERECHO | G19: SEDE | H19: VIRTUAL | I19: 8 | J19: 14.07 | K19: juan.alcantara@autonomadeica.edu.pe | L19: 956083663 | M19: -
B20: 12 | C20: 41461731 | D20: ALFARO CAYLLAHUA CARLOS HUGO | E20: FICA | F20: INGENIERIA CIVIL | G20: FILIAL | H20: PRESENCIAL | I20: 15 | J20: 16.24 | K20: carlos.alfaro@autonomadeica.edu.pe | M20: -
B21: 13
B22: 14
B23: 15
B24: 16
B25: 17
B26: 18
B27: 19
B28: 20
B29: 21
B30: 22
B31: 23
B32: 24
... B137: 129

Sheet CONCURSO
B6: PROPUESTA DE INVITACION DOCENTE TP PARA SEMESTRE ACADÉMICO 2026-1 FACULTAD DE INGENIERÍA, CIENCIAS Y ADMINISTRACIÓN
B8: N° | C8: DNI | D8: APELLIDOS Y NOMBRES | E8: FACULTAD | F8: ESCUELA PROFESIONAL | G8: LOCAL | H8: MODALIDAD | I8: N° HORAS LECTIVAS | J8: ESCUELA PROFESIONAL | K8: LOCAL | L8: MODALIDAD | M8: CORREO ELECTRÓNICO INSTITUCIONAL | N8: N° CELULAR | O8: OBSERVACIONES
B9: 1 | C9: 72176698 | D9: ESPINOZA MORE CARLA MILAGROS | I9: 6 | J9: ADMINISTRACION DE EMPRESAS | K9: HUAURA | L9: VIRTUAL | M9: - | N9: 956383530 | O9: Horas limitadas por disponibilidad docente
B10: 2 | C10: 41807593 | D10: EVANGELISTA HUAYNALAYA FRANCISCO DE JESUS | I10: 12 | J10: DERECHO | K10: HUAURA | L10: PRESENCIAL | M10: - | N10: 940392058 | O10: -
B11: 3 | C11: 75168136 | D11: GAVINO SANCHEZ JOHN STEVENS | I11: 6 | J11: DERECHO - EEGG | K11: HUAURA | L11: PRESENCIAL | M11: - | N11: 906809788 | O11: Horas limitadas por disponibilidad docente
B12: 4 | C12: 42146692 | D12: LINO FLORES LUIS ANTONIO | I12: 8 | J12: ADMINISTRACION DE EMPRESAS - EEGG | K12: HUAURA | L12: PRESENCIAL | M12: - | N12: 984374438 | O12: Horas limitadas por disponibilidad docente
B13: 5 | C13: 43608561 | D13: MENDOZA CASTILLO JUAN JOSE | I13: 5 | J13: ADMINISTRACION DE EMPRESAS | K13: HUAURA | L13: VIRTUAL | M13: - | N13: 964859651 | O13: Horas limitadas por disponibilidad docente
B14: 6 | C14: 15591781 | D14: QUINTEROS NICHO LUIS FERNANDO | I14: 4 | J14: DERECHO - EEGG | K14: HUAURA | L14: PRESENCIAL | M14: - | N14: 970427179 | O14: Horas limitadas por disponibilidad docente
B15: 7 | C15: 15590660 | D15: RODRIGUEZ RAMIREZ MARIA ISABEL | I15: 4 | J15: ADMINISTRACION DE EMPRESAS | K15: HUAURA | L15: PRESENCIAL | M15: - | N15: 987923259 | O15: Horas limitadas por disponibilidad docente
B16: 8 | C16: 15688249 | D16: ROJAS GUZMAN TITO | I16: 9 | J16: ADMINISTRACION DE EMPRESAS | K16: HUAURA | L16: PRESENCIAL | M16: - | N16: 961433324 | O16: Horas limitadas por disponibilidad docente
B17: 9 | C17: 40740790 | D17: SACRAMENTO LAZARO ROSA ALBINA | I17: 20 | J17: DERECHO | K17: HUAURA | L17: PRESENCIAL | M17: - | N17: 924012573 | O17: -
B18: 10 | C18: 15725118 | D18: SAMANAMUD VALENTIN MIGUEL ANGEL MOISES | I18: 4 | J18: ADMINISTRACION DE EMPRESAS | K18: HUAURA | L18: PRESENCIAL | M18: - | N18: 970656047 | O18: Horas limitadas por disponibilidad docente
B19: 11 | C19: 43027985 | D19: TRUJILLO APONTE WAGNER ABRAHAM | I19: 9 | J19: DERECHO | K19: HUAURA | L19: VIRTUAL | M19: - | N19: 964034650 | O19: Horas limitadas por disponibilidad docente
B20: 12 | C20: 70179483 | D20: VILLANUEVA CAMAC GUILLERMO ARTURO | I20: 20 | J20: ADMINISTRACION DE EMPRESAS - EEGG | K20: HUAURA | L20: PRESENCIAL | M20: - | N20: 983861568 | O20: -
... B25: 17 | C25: 16756416 | D25: SALCEDO RODAS PERCY ISMAEL | I25: 18 | J25: ADMINISTRACION DE EMPRESAS | K25: SEDE | L25: VIRTUAL | M25: - | N25: 972627821 | O25: -
B26: 18 | C26: 70108675 | D26: BUITRON LLACSA JOSE MANUEL | I26: 9 | J26: DERECHO - EEGG | K26: SEDE | L26: MAS PRESENCIAL | N26: 977518295 | O26: Horas limitadas por disponibilidad docente
B27: 19 | C27: 46075693 | D27: MORALES CHAVEZ GISSEL JOCELINE | I27: 5 | J27: ADMINISTRACION Y FINANZAS | K27: SEDE | L27: VIRTUAL | N27: 958691349 | O27: Horas limitadas por disponibilidad docente
B28: 20 | C28: 21435528 | D28: ZUMAETA BERAMENDI JACQUELINE DIANA | I28: 8 | J28: ADMINISTRACION Y FINANZAS | K28: SEDE | L28: VIRTUAL | N28: 989365672 | O28: Horas limitadas por disponibilidad docente
B29: 21 | C29: 70786643 | D29: DIAZ VELASQUEZ JULIO CESAR | I29: 12 | J29: ADMINISTRACION Y FINANZAS | K29: FILIAL | L29: VIRTUAL | N29: 924849452 | O29: -
B30: 22 | C30: 46590523 | D30: ROMERO CARAZAS RAFAEL | I30: 5 | J30: ADMINISTRACION Y FINANZAS | K30: SEDE | L30: VIRTUAL | N30: 982315013 | O30: Horas limitadas por disponibilidad docente
B31: 23 | C31: 46825060 | D31: CALLAN BACILIO RICHARD | I31: 5 | J31: ADMINISTRACION Y FINANZAS | K31: FILIAL | L31: VIRTUAL | N31: 946042178 | O31: Horas limitadas por disponibilidad docente
B32: 24 | C32: 72681156 | D32: MAS VILLANUEVA KENY ARNOLD | I32: 5 | J32: CONTABILIDAD | K32: FILIAL | L32: VIRTUAL | N32: 953362861 | O32: Horas limitadas por disponibilidad docente
B33: 25 | C33: 02885494 | D33: QUIROGA PAIVA DAVID EDUARDO | I33: 3 | J33: CONTABILIDAD | K33: FILIAL | L33: VIRTUAL | N33: 933531483 | O33: Horas limitadas por disponibilidad docente
B34: 26 | C34: 45156306 | D34: ZAFRA SALAS MARCO ANDRE | I34: 17 | J34: ADMINISTRACION DE EMPRESAS | K34: SEDE | L34: VIRTUAL | N34: 969551419 | O34: -
B35: 27 | C35: 41519363 | D35: MANRIQUE CERVANTES JOSE ANTONIO | I35: 4 | J35: DERECHO | K35: FILIAL | L35: VIRTUAL | N35: 987202320 | O35: Horas limitadas por disponibilidad docente
B36: 28 | C36: 46730566 | D36: SALAZAR GAMBOA OSCAR FRITZ ALEXANDER | I36: 15 | J36: DERECHO - EEGG | K36: SEDE | L36: VIRTUAL | N36: 983582045 | O36: -
B37: 29 | C37: 41536992 | D37: CABEZA MOLINA LUIS FELIPE | I37: 8 | J37: DERECHO | K37: FILIAL | L37: VIRTUAL | N37: 969042565 | O37: Horas limitadas por disponibilidad docente
B38: 30 | C38: 40105460 | D38: MUÑANTE SIHUES CESAR ARTURO | I38: 10 | J38: DERECHO - EEGG | K38: SEDE | L38: VIRTUAL | N38: 950058593 | O38: Horas limitadas por disponibilidad docente
B39: 31 | C39: 42515290 | D39: PIZARRO OSORIO BETSABE LILIA | I39: 32 | J39: DERECHO | K39: SEDE | L39: MAS PRESENCIAL | N39: 976805104 | O39: -
B40: 32 | C40: 45007560 | D40: ULLOQUE SAMATELO CARLOS AUGUSTO | I40: 8 | J40: DERECHO - EEGG | K40: SEDE | L40: VIRTUAL | N40: 969015640 | O40: Horas limitadas por disponibilidad docente
B41: 33 | C41: 29726614 | D41: BAHAMONDES GARCIA SINOE GEOFREY | I41: 15 | J41: INGENIERIA DE SISTEMAS - EEGG | K41: SEDE | L41: VIRTUAL | N41: 971450905 | O41: -
B42: 34 | C42: 76129345 | D42: VELASQUEZ CHUNGA JOSE LUIS EDUARDO | I42: 8 | J42: INGENIERIA CIVIL - EEGG | K42: SEDE | L42: VIRTUAL | N42: 921933801 | O42: Horas limitadas por disponibilidad docente
B43: 35 | C43: 72049382 | D43: APAZA CHINO GRIMALDO | I43: 10 | J43: DERECHO - EEGG | K43: SEDE | L43: VIRTUAL | N43: 988602424 | O43: Horas limitadas por disponibilidad docente
B44: 36 | C44: 15981186 | D44: MARTINEZ ZULOAGA NORA TERESA | I44: 5 | J44: INGENIERIA DE SISTEMAS - EEGG | K44: SEDE | L44: VIRTUAL | N44: 992296790 | O44: Horas limitadas por disponibilidad docente
B45: 37 | C45: 40583004 | D45: SOTOMAYOR ALBITES GEORGE ANTONHY | I45: 8 | J45: ADMINISTRACION DE EMPRESAS - EEGG | K45: SEDE | L45: VIRTUAL | N45: 992575130 | O45: Horas limitadas por disponibilidad docente
... B47: 39 | C47: 15428250 | D47: CHAVEZ CARRAZCO CECILIA MARCELINA | I47: 10 | J47: INGENIERIA INDUSTRIAL - EEGG | K47: SEDE | L47: PRESENCIAL | N47: 953294332 | O47: Horas limitadas por disponibilidad docente
B48: 40 | C48: 08689170 | D48: ACERO CARDENAS ANA MARIA | I48: 10 | J48: INGENIERIA INDUSTRIAL - EEGG | K48: FILIAL | L48: MAS PRESENCIAL | N48: 991299956 | O48: Horas limitadas por disponibilidad docente
B49: 41 | C49: 45303683 | D49: GUTIERREZ JIMENEZ CINDY FIORELLA | I49: 9 | J49: INGENIERIA CIVIL - EEGG | K49: FILIAL | L49: VIRTUAL | N49: 989918045 | O49: Horas limitadas por disponibilidad docente
B50: 42 | C50: 70277443 | D50: OSCCO INJANTE JOSE LUIS | I50: 9 | J50: CONTABILIDAD - EEGG | K50: FILIAL | L50: MAS VIRTUAL | N50: 943858181 | O50: Horas limitadas por disponibilidad docente
B51: 43 | C51: 43958773 | D51: HUAMANI CANALES ANALI MARIELLA | I51: 5 | J51: INGENIERIA CIVIL | K51: FILIAL | L51: PRESENCIAL | N51: 946862930 | O51: Horas limitadas por disponibilidad docente
...

Sheet INVITACION
B6: PROPUESTA DE INVITACION DOCENTE TP PARA SEMESTRE ACADÉMICO 2026-1 FACULTAD DE INGENIERÍA, CIENCIAS Y ADMINISTRACIÓN
B8: N° | C8: DNI | D8: APELLIDOS Y NOMBRES | E8: FACULTAD | F8: ESCUELA PROFESIONAL | G8: LOCAL | H8: MODALIDAD | I8: N° HORAS LECTIVAS | J8: ESCUELA PROFESIONAL | K8: LOCAL | L8: MODALIDAD | M8: CORREO ELECTRÓNICO INSTITUCIONAL | N8: N° CELULAR | O8: OBSERVACIONES
B9: 1 | C9: 15607309 | D9: BERRIOS VEGA CARMEN LUZ | I9: 12 | J9: DERECHO | K9: HUAURA | L9: PRESENCIAL | M9: - | N9: 968857951 | O9: - | P9: CV
B10: 2 | C10: 29384319 | D10: CHUNG RODRIGUEZ JOSE MARTIN | I10: 18 | J10: DERECHO - EEGG | K10: HUAURA | L10: PRESENCIAL | M10: - | N10: 991165153 | O10: - | P10: CV
B11: 3 | C11: 44006023 | D11: CONDE REYES JORGE LUIS | I11: 8 | J11: DERECHO | K11: HUAURA | L11: PRESENCIAL | M11: - | N11: 989390670 | O11: JUSTIFICAR | P11: CV
B12: 4 | C12: 44822572 | D12: DURAN RIOS SANDRO ANIBAL | I12: 9 | J12: DERECHO | K12: HUAURA | L12: VIRTUAL | M12: - | N12: 944457776 | O12: JUSTIFICAR | P12: CV
B13: 5 | C13: 42711303 | D13: FABIAN SOBERANIS MIGUEL ANGEL | I13: 20 | J13: DERECHO - EEGG | K13: HUAURA | L13: PRESENCIAL | M13: - | N13: 978177488 | O13: - | P13: CV
B14: 7 | C14: 40432935 | D14: MIRANDA BAZALAR ROBERTO WILLIAM | I14: 4 | J14: DERECHO | K14: HUAURA | L14: PRESENCIAL | M14: - | N14: 994985272 | O14: JUSTIFICAR | P14: CV
B15: 8 | C15: 40382257 | D15: REA MORENO FLOR MAGALY | I15: 12 | J15: DERECHO | K15: HUAURA | L15: PRESENCIAL | M15: - | N15: 936649961 | O15: - | P15: CV
B16: 9 | D16: CASTILLON SIGUAS LUIS ALFREDO
B17: 10 | D17: CHANG HERNANDEZ GUILLERMO ANDRES
B18: 11 | D18: FERREYROS YUCRA JAIR EMERSON
B19: 12 | D19: GARAYAR TTITO ANA MELIZA
B20: 13 | D20: HUANCAHUIRE BRAVO CLAUDIO ISAIAS
B21: 14
B22: 15
B23: 16
B24: 17
B25: 18
B26: 19
B27: 20
B28: 21
B29: 22
B30: 23
B31: 24
B32: 25
... B136: 129

Sheet REINCORPORACION
B6: PROPUESTA DE INVITACION DOCENTE TP PARA SEMESTRE ACADÉMICO 2026-1 FACULTAD DE INGENIERÍA, CIENCIAS Y ADMINISTRACIÓN
B8: N° | C8: DNI | D8: APELLIDOS Y NOMBRES | E8: FACULTAD | F8: ESCUELA PROFESIONAL | G8: LOCAL | H8: MODALIDAD | I8: N° HORAS LECTIVAS | J8: ESCUELA PROFESIONAL | K8: LOCAL | L8: MODALIDAD | M8: CORREO ELECTRÓNICO INSTITUCIONAL | N8: N° CELULAR | O8: OBSERVACIONES
B9: 1 | D9: CASTILLO ORMEÑO ENZO RENAN | I9: 18 | J9: INGENIERIA DE SISTEMAS | K9: SEDE | L9: PRESENCIAL | O9: -
B10: 2
B11: 3
B12: 4
B13: 5
B14: 6
B15: 7
B16: 8
B17: 9
B18: 10
B19: 11
B20: 12
B21: 13
... B137: 129

Sheet OGTH
C2: Datos para ser llenados por la OGTH
C3: Datos para ser llenados por Vicerrectorado y/o facultades
B4: INFORMACIÓN DE DOCENTES 2026-I PARA ASIGNACIÓN DE PAGOS
B6: N° | C6: DOCENTES UAI | D6: ALTA RANKMI | E6: ENRROLAR | F6: CONTRATO CREADO EN RANKMI | G6: CONTRATO ENVIADO | H6: CONTRATO FIRMADO | I6: ALTA SUNAT | J6: FOTOCHECK LISTO | K6: ¿SE ENTREGÓ EL FOTOCHECK? | L6: ¿SE CARGÓ DOCUMENTOS DE INGRESO? | M6: ENVIÓ SUS DOCUMENTOS DE INGRESO | N6: DOCENTE / JEFE DE PRÁCTICA | O6: DNI | P6: NUMERO DE CELULAR | Q6: CORREO PERSONAL | R6: CORREO INSTITUCIONAL | S6: HORAS 2025-II | T6: HORAS 2026-I | U6: DEDICACIÓN 2025-II | V6: DEDICACIÓN 2026-I | W6: MODALIDAD DE INGRESO | X6: CATEGORIA | Y6: FECHA DE INGRESO | Z6: RCU DE INGRESO 2026-I | AA6: FECHA DE RCU DE INGRESO | AB6: LOCAL 2025-II | AC6: LOCAL 2026-I | AD6: PROGRAMA ACADEMICO 2025-II | AE6: GRADO ACADEMICO 2025-II | AF6: PROGRAMA ACADEMICO 2026-I | AG6: GRADO ACADEMICO 2026-I | AH6: MODALIDAD 2025-II | AI6: MODALIDAD 2026-I | AK6: SUELDO BASICO | AL6: ASIGNACION FAMILIAR / BONO POR CARGO | AM6: PLUXEE | AN6: TOTAL BRUTO MENSUAL | AP6: VALOR DE HORA | AQ6: SEMANA | AR6: TOTAL MENSUAL | AS6: AF / BONO POR INVESTIGACION | AT6: PLUXEE | AU6: TOTAL BRUTO MENSUAL | AW6: OBSERVACIONES OGTH
B7: 1 | C7: BERRIOS VEGA CARMEN LUZ | N7: DOCENTE | O7: 15607309 | P7: 968857951 | Q7: berriosvegacarmenluz7@gmail.com | R7: - | S7: - | T7: 12 | U7: - | V7: TP | W7: INVITACION | X7: CONTRATADO | AB7: - | AC7: HUAURA | AD7: - | AE7: - | AF7: DERECHO | AG7: MAESTRIA | AH7: - | AI7: PRESENCIAL | AK7: 0 | AL7: 0 | AM7: 0 | AN7: =AK7+AL7+AM7 -> 0 | AP7: 0 | AQ7: =AP7*T7 -> 0 | AR7: =AQ7*4 -> 0 | AS7: 0 | AT7: 0 | AU7: =AR7+AS7+AT7 -> 0
B8: 2 | C8: CHUNG RODRIGUEZ JOSE MARTIN | N8: DOCENTE | O8: 29384319 | P8: 991165153 | Q8: chungjose675@gmail.com | R8: - | S8: - | T8: 18 | U8: - | V8: TP | W8: INVITACION | X8: CONTRATADO | AB8: - | AC8: HUAURA | AD8: - | AE8: - | AF8: DERECHO - EEGG | AG8: MAESTRIA | AH8: - | AI8: PRESENCIAL | AK8: 0 | AL8: 0 | AM8: 0 | AN8: =AK8+AL8+AM8 -> 0 | AP8: 0 | AQ8: =AP8*T8 -> 0 | AR8: =AQ8*4 -> 0 | AS8: 0 | AT8: 0 | AU8: =AR8+AS8+AT8 -> 0
B9: 3 | C9: CONDE REYES JORGE LUIS | N9: DOCENTE | O9: 44006023 | P9: 989390670 | Q9: jorgecondereyes@gmail.com | R9: - | S9: - | T9: 8 | U9: - | V9: TP | W9: INVITACION | X9: CONTRATADO | AB9: - | AC9: HUAURA | AD9: - | AE9: - | AF9: DERECHO | AG9: MAESTRIA | AH9: - | AI9: PRESENCIAL | AK9: 0 | AL9: 0 | AM9: 0 | AN9: =AK9+AL9+AM9 -> 0 | AP9: 0 | AQ9: =AP9*T9 -> 0 | AR9: =AQ9*4 -> 0 | AS9: 0 | AT9: 0 | AU9: =AR9+AS9+AT9 -> 0
B10: 4 | C10: DE LA CRUZ SOSA JAKELINE MELINA | N10: DOCENTE | O10: 43517817 | P10: 951222024 | Q10: jakimeli@outlook.com | R10: jakeline.delacruz@autonomadeica.edu.pe | S10: 37 | T10: 32 | U10: TC | V10: TC | W10: RENOVACION | X10: CONTRATADO | Y10: 45915 | AB10: HUAURA | AC10: HUAURA | AD10: PSICOLOGIA - EEGG | AE10: MAESTRIA | AF10: DERECHO - EEGG | AG10: MAESTRIA | AH10: PRESENCIAL | AI10: PRESENCIAL | AK10: 0 | AL10: 0 | AM10: 0 | AN10: =AK10+AL10+AM10 -> 0 | AP10: 0 | AQ10: =AP10*T10 -> 0 | AR10: =AQ10*4 -> 0 | AS10: 0 | AT10: 0 | AU10: =AR10+AS10+AT10 -> 0
B11: 5 | C11: DURAN RIOS SANDRO ANIBAL | N11: DOCENTE | O11: 44822572 | P11: 944457776 | Q11: durisandroanibal@gmail.com | R11: - | S11: - | T11: 9 | U11: - | V11: TP | W11: INVITACION | X11: CONTRATADO | AB11: - | AC11: HUAURA | AD11: - | AE11: - | AF11: DERECHO | AG11: MAESTRIA | AH11: - | AI11: VIRTUAL | AK11: 0 | AL11: 0 | AM11: 0 | AN11: =AK11+AL11+AM11 -> 0 | AP11: 0 | AQ11: =AP11*T11 -> 0 | AR11: =AQ11*4 -> 0 | AS11: 0 | AT11: 0 | AU11: =AR11+AS11+AT11 -> 0
B12: 6 | C12: ESPINOZA MORE CARLA MILAGROS | N12: DOCENTE | O12: 72176698 | P12: 956383530 | Q12: emc1291@gmail.com | R12: - | S12: - | T12: 6 | U12: - | V12: TP | W12: CONCURSO | X12: CONTRATADO | Y12: 46125 | Z12: RCU 097-2026 | AA12: 46083 | AB12: - | AC12: HUAURA | AD12: - | AE12: - | AF12: ADMINISTRACION DE EMPRESAS | AG12: MAESTRIA | AH12: - | AI12: VIRTUAL | AK12: 0 | AL12: 0 | AM12: 0 | AN12: =AK12+AL12+AM12 -> 0 | AP12: 0 | AQ12: =AP12*T12 -> 0 | AR12: =AQ12*4 -> 0 | AS12: 0 | AT12: 0 | AU12: =AR12+AS12+AT12 -> 0
B13: 7 | C13: EVANGELISTA HUAYNALAYA FRANCISCO DE JESUS | N13: DOCENTE | O13: 41807593 | P13: 940392058 | Q13: fraancisco.evngelista1@gmail.com | R13: - | S13: - | T13: 12 | U13: - | V13: TP | W13: CONCURSO | X13: CONTRATADO | Y13: 46125 | Z13: RCU 097-2026 | AA13: 46083 | AB13: - | AC13: HUAURA | AD13: - | AE13: - | AF13: DERECHO | AG13: MAESTRIA | AH13: - | AI13: PRESENCIAL | AK13: 0 | AL13: 0 | AM13: 0 | AN13: =AK13+AL13+AM13 -> 0 | AP13: 0 | AQ13: =AP13*T13 -> 0 | AR13: =AQ13*4 -> 0 | AS13: 0 | AT13: 0 | AU13: =AR13+AS13+AT13 -> 0
B14: 8 | C14: FABIAN SOBERANIS MIGUEL ANGEL | N14: DOCENTE | O14: 42711303 | P14: 978177488 | Q14: fabiancip304301@gmail.com | R14: - | S14: - | T14: 20 | U14: - | V14: TP | W14: INVITACION | X14: CONTRATADO | AB14: - | AC14: HUAURA | AD14: - | AE14: - | AF14: DERECHO - EEGG | AG14: MAESTRIA | AH14: - | AI14: PRESENCIAL | AK14: 0 | AL14: 0 | AM14: 0 | AN14: =AK14+AL14+AM14 -> 0 | AP14: 0 | AQ14: =AP14*T14 -> 0 | AR14: =AQ14*4 -> 0 | AS14: 0 | AT14: 0 | AU14: =AR14+AS14+AT14 -> 0
B15: 9 | C15: GAVINO SANCHEZ JOHN STEVENS | N15: DOCENTE | O15: 75168136 | P15: 906809788 | Q15: johnstevensgavino1101@gmail.com | R15: - | S15: - | T15: 6 | U15: - | V15: TP | W15: CONCURSO | X15: CONTRATADO | Y15: 46125 | Z15: RCU 097-2026 | AA15: 46083 | AB15: - | AC15: HUAURA | AD15: - | AE15: - | AF15: DERECHO - EEGG | AG15: MAESTRIA | AH15: - | AI15: PRESENCIAL | AK15: 0 | AL15: 0 | AM15: 0 | AN15: =AK15+AL15+AM15 -> 0 | AP15: 0 | AQ15: =AP15*T15 -> 0 | AR15: =AQ15*4 -> 0 | AS15: 0 | AT15: 0 | AU15: =AR15+AS15+AT15 -> 0
B16: 10 | C16: LINO FLORES LUIS ANTONIO | N16: DOCENTE | O16: 42146692 | P16: 984374438 | Q16: luis.lino@cip.org.pe | R16: - | S16: - | T16: 8 | U16: - | V16: TP | W16: CONCURSO | X16: CONTRATADO | Y16: 46125 | Z16: RCU 097-2026 | AA16: 46083 | AB16: - | AC16: HUAURA | AD16: - | AE16: - | AF16: ADMINISTRACION DE EMPRESAS - EEGG | AG16: DOCTOR | AH16: - | AI16: PRESENCIAL | AK16: 0 | AL16: 0 | AM16: 0 | AN16: =AK16+AL16+AM16 -> 0 | AP16: 0 | AQ16: =AP16*T16 -> 0 | AR16: =AQ16*4 -> 0 | AS16: 0 | AT16: 0 | AU16: =AR16+AS16+AT16 -> 0
B17: 11 | C17: MANDAMIENTO GRADOS DAMARIS TELMA | N17: DOCENTE | O17: 40428220 | P17: 992990608 | Q17: damarismandamiento44@gmail.com | R17: damaris.mandamiento@autonomadeica.edu.pe | S17: 16 | T17: 32 | U17: TP | V17: TC | W17: RENOVACION | X17: CONTRATADO | Y17: 45922 | AB17: HUAURA | AC17: HUAURA | AD17: ENFERMERIA - EEGG | AE17: MAESTRIA | AF17: DERECHO - EEGG | AG17: MAESTRIA | AH17: PRESENCIAL | AI17: PRESENCIAL | AK17: 0 | AL17: 0 | AM17: 0 | AN17: =AK17+AL17+AM17 -> 0 | AP17: 0 | AQ17: =AP17*T17 -> 0 | AR17: =AQ17*4 -> 0 | AS17: 0 | AT17: 0 | AU17: =AR17+AS17+AT17 -> 0
B18: 12 | C18: MENDOZA CASTILLO JUAN JOSE | N18: DOCENTE | O18: 43608561 | P18: 964859651 | Q18: mendozacastillojuanjose@gmail.com | R18: - | S18: - | T18: 5 | U18: - | V18: TP | W18: CONCURSO | X18: CONTRATADO | Y18: 46125 | Z18: RCU 097-2026 | AA18: 46083 | AB18: - | AC18: HUAURA | AD18: - | AE18: - | AF18: ADMINISTRACION DE EMPRESAS | AG18: MAESTRIA | AH18: - | AI18: VIRTUAL | AK18: 0 | AL18: 0 | AM18: 0 | AN18: =AK18+AL18+AM18 -> 0 | AP18: 0 | AQ18: =AP18*T18 -> 0 | AR18: =AQ18*4 -> 0 | AS18: 0 | AT18: 0 | AU18: =AR18+AS18+AT18 -> 0
B19: 13 | C19: MIRANDA BAZALAR ROBERTO WILLIAM | N19: DOCENTE | O19: 40432935 | P19: 994985272 | Q19: mirandabazalar19@gmail.com | R19: - | S19: - | T19: 4 | U19: - | V19: TP | W19: INVITACION | X19: CONTRATADO | AB19: - | AC19: HUAURA | AD19: - | AE19: - | AF19: DERECHO | AG19: MAESTRIA | AH19: - | AI19: PRESENCIAL | AK19: 0 | AL19: 0 | AM19: 0 | AN19: =AK19+AL19+AM19 -> 0 | AP19: 0 | AQ19: =AP19*T19 -> 0 | AR19: =AQ19*4 -> 0 | AS19: 0 | AT19: 0 | AU19: =AR19+AS19+AT19 -> 0
B20: 14 | C20: PADILLA HIZO PEDRO HERNAN | N20: DOCENTE | O20: 41239504 | P20: 992085961 | Q20: ppadilla1580@gmail.com | R20: pedro.padilla@autonomadeica.edu.pe | S20: 8 | T20: 16 | U20: TP | V20: TP | W20: RENOVACION | X20: CONTRATADO | Y20: 45771 | AB20: HUAURA | AC20: HUAURA | AD20: ENFERMERIA - EEGG | AE20: MAESTRIA | AF20: ADMINISTRACION DE EMPRESAS - EEGG | AG20: MAESTRIA | AH20: PRESENCIAL | AI20: PRESENCIAL | AK20: 0 | AL20: 0 | AM20: 0 | AN20: =AK20+AL20+AM20 -> 0 | AP20: 0 | AQ20: =AP20*T20 -> 0 | AR20: =AQ20*4 -> 0 | AS20: 0 | AT20: 0 | AU20: =AR20+AS20+AT20 -> 0
B21: 15 | C21: PARIHUAMAN QUINDE GERALDINA REBECA | N21: DOCENTE | O21: 33826021 | P21: 989038202 | Q21: geraldinaparihuaman@gmail.com | R21: geraldina.parihuaman@autonomadeica.edu.pe | S21: 13 | T21: 15 | U21: TP | V21: TP | W21: RENOVACION | X21: CONTRATADO | Y21: 45771 | AB21: HUAURA | AC21: HUAURA | AD21: ENFERMERIA - EEGG | AE21: DOCTOR | AF21: ADMINISTRACION DE EMPRESAS - EEGG | AG21: DOCTOR | AH21: PRESENCIAL | AI21: PRESENCIAL | AK21: 0 | AL21: 0 | AM21: 0 | AN21: =AK21+AL21+AM21 -> 0 | AP21: 0 | AQ21: =AP21*T21 -> 0 | AR21: =AQ21*4 -> 0 | AS21: 0 | AT21: 0 | AU21: =AR21+AS21+AT21 -> 0
B22: 16 | C22: PEREZ RETUERTO RONY GEANCARLO | N22: DOCENTE | O22: 42212783 | P22: 960064109 | Q22: rperezr30@gmail.com | R22: rony.perez@autonomadeica.edu.pe | S22: 15 | T22: 10 | U22: TP | V22: TP | W22: RENOVACION | X22: CONTRATADO | Y22: 45771 | AB22: HUAURA | AC22: HUAURA | AD22: DERECHO - EEGG | AE22: MAESTRIA | AF22: DERECHO - EEGG | AG22: MAESTRIA | AH22: PRESENCIAL | AI22: PRESENCIAL | AK22: 0 | AL22: 0 | AM22: 0 | AN22: =AK22+AL22+AM22 -> 0 | AP22: 0 | AQ22: =AP22*T22 -> 0 | AR22: =AQ22*4 -> 0 | AS22: 0 | AT22: 0 | AU22: =AR22+AS22+AT22 -> 0
B23: 17 | C23: PIMENTEL RETUERTO CARMEN ANDREA | N23: DOCENTE | O23: 40822577 | P23: 957786821 | Q23: hay1sociologa@gmail.com | R23: carmen.pimentel@autonomadeica.edu.pe | S23: 36 | T23: 16 | U23: TC | V23: TP | W23: RENOVACION | X23: CONTRATADO | Y23: 45771 | AB23: HUAURA | AC23: HUAURA | AD23: ENFERMERIA - EEGG | AE23: MAESTRIA | AF23: DERECHO - EEGG | AG23: MAESTRIA | AH23: PRESENCIAL | AI23: PRESENCIAL | AK23: 0 | AL23: 0 | AM23: 0 | AN23: =AK23+AL23+AM23 -> 0 | AP23: 0 | AQ23: =AP23*T23 -> 0 | AR23: =AQ23*4 -> 0 | AS23: 0 | AT23: 0 | AU23: =AR23+AS23+AT23 -> 0
B24: 18 | C24: QUINTEROS NICHO LUIS FERNANDO | N24: DOCENTE | O24: 15591781 | P24: 970427179 | Q24: luisferquinic@gmail.com | R24: - | S24: - | T24: 4 | U24: - | V24: TP | W24: CONCURSO | X24: CONTRATADO | Y24: 46125 | Z24: RCU 097-2026 | AA24: 46083 | AB24: - | AC24: HUAURA | AD24: - | AE24: - | AF24: DERECHO - EEGG | AG24: MAESTRIA | AH24: - | AI24: PRESENCIAL | AK24: 0 | AL24: 0 | AM24: 0 | AN24: =AK24+AL24+AM24 -> 0 | AP24: 0 | AQ24: =AP24*T24 -> 0 | AR24: =AQ24*4 -> 0 | AS24: 0 | AT24: 0 | AU24: =AR24+AS24+AT24 -> 0
B25: 19 | C25: REA MORENO FLOR MAGALY | N25: DOCENTE | O25: 40382257 | P25: 936649961 | Q25: flormagaly021179@gmail.com | R25: - | S25: - | T25: 12 | U25: - | V25: TP | W25: INVITACION | X25: CONTRATADO | AB25: - | AC25: HUAURA | AD25: - | AE25: - | AF25: DERECHO | AG25: MAESTRIA | AH25: - | AI25: PRESENCIAL | AK25: 0 | AL25: 0 | AM25: 0 | AN25: =AK25+AL25+AM25 -> 0 | AP25: 0 | AQ25: =AP25*T25 -> 0 | AR25: =AQ25*4 -> 0 | AS25: 0 | AT25: 0 | AU25: =AR25+AS25+AT25 -> 0
B26: 20 | C26: REQUENA GARCIA MARIA DEL ROSARIO | N26: DOCENTE | O26: 08684196 | P26: 940716638 | Q26: mrequena@unjfsc.edu.pe | R26: maria.requena@autonomadeica.edu.pe | S26: 15 | T26: 10 | U26: TP | V26: TP | W26: RENOVACION | X26: CONTRATADO | Y26: 45782 | AB26: HUAURA | AC26: HUAURA | AD26: DERECHO - EEGG | AE26: MAESTRIA | AF26: ADMINISTRACION DE EMPRESAS - EEGG | AG26: MAESTRIA | AH26: PRESENCIAL | AI26: PRESENCIAL | AK26: 0 | AL26: 0 | AM26: 0 | AN26: =AK26+AL26+AM26 -> 0 | AP26: 0 | AQ26: =AP26*T26 -> 0 | AR26: =AQ26*4 -> 0 | AS26: 0 | AT26: 0 | AU26: =AR26+AS26+AT26 -> 0
B27: 21 | C27: REYES ROMAN CARLOS ARTURO | N27: DOCENTE | O27: 41208519 | P27: 985001402 | Q27: econ.carlosrr@gmail.com | R27: arturo.reyes@autonomadeica.edu.pe | S27: 17 | T27: 15 | U27: TP | V27: TP | W27: RENOVACION | X27: CONTRATADO | Y27: 45922 | AB27: HUAURA | AC27: HUAURA | AD27: ADMINISTRACION DE EMPRESAS - EEGG | AE27: MAESTRIA | AF27: DERECHO - EEGG | AG27: MAESTRIA | AH27: VIRTUAL | AI27: PRESENCIAL | AK27: 0 | AL27: 0 | AM27: 0 | AN27: =AK27+AL27+AM27 -> 0 | AP27: 0 | AQ27: =AP27*T27 -> 0 | AR27: =AQ27*4 -> 0 | AS27: 0 | AT27: 0 | AU27: =AR27+AS27+AT27 -> 0
B28: 22 | C28: RIOS SANTIAGO WILSON CESAR | N28: DOCENTE | O28: 44398451 | P28: 989336775 | Q28: cesarxavy14@gmail.com | R28: wilson.rios@autonomadeica.edu.pe | S28: 13 | T28: 14 | U28: TP | V28: TP | W28: RENOVACION | X28: CONTRATADO | Y28: 45771 | AB28: HUAURA | AC28: HUAURA | AD28: PSICOLOGIA - EEGG | AE28: MAESTRIA | AF28: DERECHO - EEGG | AG28: MAESTRIA | AH28: PRESENCIAL | AI28: PRESENCIAL | AK28: 0 | AL28: 0 | AM28: 0 | AN28: =AK28+AL28+AM28 -> 0 | AP28: 0 | AQ28: =AP28*T28 -> 0 | AR28: =AQ28*4 -> 0 | AS28: 0 | AT28: 0 | AU28: =AR28+AS28+AT28 -> 0
B29: 23 | C29: RODRIGUEZ RAMIREZ MARIA ISABEL | N29: DOCENTE | O29: 15590660 | P29: 987923259 | Q29: rodrisag18@gmail.com | R29: - | S29: - | T29: 4 | U29: - | V29: TP | W29: CONCURSO | X29: CONTRATADO | Y29: 46125 | Z29: RCU 097-2026 | AA29: 46083 | AB29: - | AC29: HUAURA | AD29: - | AE29: - | AF29: ADMINISTRACION DE EMPRESAS | AG29: DOCTOR | AH29: - | AI29: PRESENCIAL | AK29: 0 | AL29: 0 | AM29: 0 | AN29: =AK29+AL29+AM29 -> 0 | AP29: 0 | AQ29: =AP29*T29 -> 0 | AR29: =AQ29*4 -> 0 | AS29: 0 | AT29: 0 | AU29: =AR29+AS29+AT29 -> 0
B30: 24 | C30: ROJAS GUZMAN TITO | N30: DOCENTE | O30: 15688249 | P30: 961433324 | Q30: titorojas189@gmail.com | R30: - | S30: - | T30: 9 | U30: - | V30: TP | W30: CONCURSO | X30: CONTRATADO | Y30: 46125 | Z30: RCU 097-2026 | AA30: 46083 | AB30: - | AC30: HUAURA | AD30: - | AE30: - | AF30: ADMINISTRACION DE EMPRESAS | AG30: DOCTOR | AH30: - | AI30: PRESENCIAL | AK30: 0 | AL30: 0 | AM30: 0 | AN30: =AK30+AL30+AM30 -> 0 | AP30: 0 | AQ30: =AP30*T30 -> 0 | AR30: =AQ30*4 -> 0 | AS30: 0 | AT30: 0 | AU30: =AR30+AS30+AT30 -> 0
B31: 25 | C31: SACRAMENTO LAZARO ROSA ALBINA | N31: DOCENTE | O31: 40740790 | P31: 924012573 | Q31: rosa.sacramento1612@gmail.com | R31: - | S31: - | T31: 20 | U31: - | V31: TP | W31: CONCURSO | X31: CONTRATADO | Y31: 46125 | Z31: RCU 097-2026 | AA31: 46083 | AB31: - | AC31: HUAURA | AD31: - | AE31: - | AF31: DERECHO | AG31: MAESTRIA | AH31: - | AI31: PRESENCIAL | AK31: 0 | AL31: 0 | AM31: 0 | AN31: =AK31+AL31+AM31 -> 0 | AP31: 0 | AQ31: =AP31*T31 -> 0 | AR31: =AQ31*4 -> 0 | AS31: 0 | AT31: 0 | AU31: =AR31+AS31+AT31 -> 0
B32: 26 | C32: SAMANAMUD VALENTIN MIGUEL ANGEL MOISES | N32: DOCENTE | O32: 15725118 | P32: 970656047 | Q32: miguel.samanamud.efcn@gmail.com | R32: - | S32: - | T32: 4 | U32: - | V32: TP | W32: CONCURSO | X32: CONTRATADO | Y32: 46125 | Z32: RCU 097-2026 | AA32: 46083 | AB32: - | AC32: HUAURA | AD32: - | AE32: - | AF32: ADMINISTRACION DE EMPRESAS | AG32: MAESTRIA | AH32: - | AI32: PRESENCIAL | AK32: 0 | AL32: 0 | AM32: 0 | AN32: =AK32+AL32+AM32 -> 0 | AP32: 0 | AQ32: =AP32*T32 -> 0 | AR32: =AQ32*4 -> 0 | AS32: 0 | AT32: 0 | AU32: =AR32+AS32+AT32 -> 0
B33: 27 | C33: SANCHEZ SOTIL KENNICK ENRIQUE | N33: DOCENTE | O33: 45165102 | P33: 952944920 | Q33: folkennick34@gmail.com | R33: kennick.sanchez@autonomadeica.edu.pe | S33: 16 | T33: 8 | U33: TP | V33: TP | W33: RENOVACION | X33: CONTRATADO | Y33: 45771 | AB33: HUAURA | AC33: HUAURA | AD33: ENFERMERIA - EEGG | AE33: MAESTRIA | AF33: DERECHO - EEGG | AG33: DOCTOR | AH33: PRESENCIAL | AI33: PRESENCIAL | AK33: 0 | AL33: 0 | AM33: 0 | AN33: =AK33+AL33+AM33 -> 0 | AP33: 0 | AQ33: =AP33*T33 -> 0 | AR33: =AQ33*4 -> 0 | AS33: 0 | AT33: 0 | AU33: =AR33+AS33+AT33 -> 0
B34: 28 | C34: TRUJILLO APONTE WAGNER ABRAHAM | N34: DOCENTE | O34: 43027985 | P34: 964034650 | Q34: wagnertrujillo7@hotmail.com | R34: - | S34: - | T34: 9 | U34: - | V34: TP | W34: CONCURSO | X34: CONTRATADO | Y34: 46125 | Z34: RCU 097-2026 | AA34: 46083 | AB34: - | AC34: HUAURA | AD34: - | AE34: - | AF34: DERECHO | AG34: MAESTRIA | AH34: - | AI34: VIRTUAL | AK34: 0 | AL34: 0 | AM34: 0 | AN34: =AK34+AL34+AM34 -> 0 | AP34: 0 | AQ34: =AP34*T34 -> 0 | AR34: =AQ34*4 -> 0 | AS34: 0 | AT34: 0 | AU34: =AR34+AS34+AT34 -> 0
B35: 29 | C35: VILLANUEVA CAMAC GUILLERMO ARTURO | N35: DOCENTE | O35: 70179483 | P35: 983861568 | Q35: guille.villa.vc12@gmail.com | R35: - | S35: - | T35: 20 | U35: - | V35: TP | W35: CONCURSO | X35: CONTRATADO | Y35: 46125 | Z35: RCU 097-2026 | AA35: 46083 | AB35: - | AC35: HUAURA | AD35: - | AE35: - | AF35: ADMINISTRACION DE EMPRESAS - EEGG | AG35: MAESTRIA | AH35: - | AI35: PRESENCIAL | AK35: 0 | AL35: 0 | AM35: 0 | AN35: =AK35+AL35+AM35 -> 0 | AP35: 0 | AQ35: =AP35*T35 -> 0 | AR35: =AQ35*4 -> 0 | AS35: 0 | AT35: 0 | AU35: =AR35+AS35+AT35 -> 0
B36: 30 | C36: GUERRERO CERVERA JULIA DEL PILAR | N36: DOCENTE | O36: 15738084 | P36: 996174294 | Q36: j1511guerrero@gmial.com | R36: - | S36: - | T36: 14 | U36: - | V36: TP | W36: CONCURSO | X36: CONTRATADO | Y36: 46125 | Z36: RCU 097-2026 | AA36: 46083 | AB36: - | AC36: HUAURA | AD36: - | AE36: - | AF36: ADMINISTRACION DE EMPRESAS - EEGG | AG36: MAESTRIA | AH36: - | AI36: MAS VIRTUAL | AK36: 0 | AL36: 0 | AM36: 0 | AN36: =AK36+AL36+AM36 -> 0 | AP36: 0 | AQ36: =AP36*T36 -> 0 | AR36: =AQ36*4 -> 0 | AS36: 0 | AT36: 0 | AU36: =AR36+AS36+AT36 -> 0
B37: 31 | C37: ABANTO MERINO LUIS ALFREDO | N37: DOCENTE | O37: 26629386 | P37: 982604568 | Q37: alfredo.abantomerino@gmail.com | R37: - | S37: - | T37: 8 | U37: - | V37: TP | W37: CONCURSO | X37: CONTRATADO | Y37: 46125 | Z37: RCU 116-2026 | AA37: 46105 | AB37: - | AC37: SEDE | AD37: - | AE37: - | AF37: ADMINISTRACION Y FINANZAS | AG37: DOCTOR | AH37: - | AI37: VIRTUAL | AK37: 0 | AL37: 0 | AM37: 0 | AN37: =AK37+AL37+AM37 -> 0 | AP37: 0 | AQ37: =AP37*T37 -> 0 | AR37: =AQ37*4 -> 0 | AS37: 0 | AT37: 0 | AU37: =AR37+AS37+AT37 -> 0
B38: 32 | C38: AGUADO APOLAYA RAUL HERNANDO | N38: DOCENTE | O38: 21814921 | P38: 906408102 | Q38: - | R38: raul.aguado@autonomadeica.edu.pe | S38: 15 | T38: 19 | U38: TP | V38: TP | W38: RENOVACION | X38: CONTRATADO | Y38: 41821 | AB38: SEDE | AC38: SEDE | AD38: INGENIERIA INDUSTRIAL | AE38: MAESTRIA | AF38: INGENIERIA INDUSTRIAL | AG38: MAESTRIA | AH38: PRESENCIAL | AI38: PRESENCIAL | AK38: 0 | AL38: 0 | AM38: 0 | AN38: =AK38+AL38+AM38 -> 0 | AP38: 0 | AQ38: =AP38*T38 -> 0 | AR38: =AQ38*4 -> 0 | AS38: 0 | AT38: 0 | AU38: =AR38+AS38+AT38 -> 0
B39: 33 | C39: AGUIRRE ESPINOZA MONICA WENDY | N39: DOCENTE | O39: 21522173 | P39: 920660685 | Q39: - | R39: monica.aguirre@autonomadeica.edu.pe | S39: 16 | T39: 16 | U39: TP | V39: TP | W39: RENOVACION | X39: CONTRATADO | Y39: 44634 | AB39: FILIAL | AC39: FILIAL | AD39: DERECHO | AE39: DOCTOR | AF39: DERECHO | AG39: DOCTOR | AH39: VIRTUAL | AI39: VIRTUAL | AK39: 0 | AL39: 0 | AM39: 0 | AN39: =AK39+AL39+AM39 -> 0 | AP39: 0 | AQ39: =AP39*T39 -> 0 | AR39: =AQ39*4 -> 0 | AS39: 0 | AT39: 0 | AU39: =AR39+AS39+AT39 -> 0
B40: 34 | C40: ALCANTARA FARFAN JUAN CARLOS | N40: DOCENTE | O40: 21569287 | P40: 956083663 | Q40: - | R40: juan.alcantara@autonomadeica.edu.pe | S40: 9 | T40: 8 | U40: TP | V40: TP | W40: RENOVACION | X40: CONTRATADO | Y40: 45922 | AB40: SEDE | AC40: SEDE | AD40: DERECHO | AE40: MAESTRIA | AF40: DERECHO | AG40: MAESTRIA | AH40: PRESENCIAL | AI40: VIRTUAL | AK40: 0 | AL40: 0 | AM40: 0 | AN40: =AK40+AL40+AM40 -> 0 | AP40: 0 | AQ40: =AP40*T40 -> 0 | AR40: =AQ40*4 -> 0 | AS40: 0 | AT40: 0 | AU40: =AR40+AS40+AT40 -> 0
B41: 35 | C41: GOMERO MANCESIDOR JOHNNY MITCHELL | N41: DOCENTE | O41: 44114929 | P41: 992110895 | Q41: jgomero@unab.ed.pe | R41: - | S41: - | T41: 10 | U41: - | V41: TP | W41: CONCURSO | X41: CONTRATADO | Y41: 46125 | Z41: RCU 116-2026 | AA41: 46105 | AB41: - | AC41: SEDE | AD41: - | AE41: - | AF41: ADMINISTRACION DE EMPRESAS | AG41: DOCTOR | AH41: - | AI41: VIRTUAL | AK41: 0 | AL41: 0 | AM41: 0 | AN41: =AK41+AL41+AM41 -> 0 | AP41: 0 | AQ41: =AP41*T41 -> 0 | AR41: =AQ41*4 -> 0 | AS41: 0 | AT41: 0 | AU41: =AR41+AS41+AT41 -> 0
B42: 36 | C42: RECUAY SALAZAR CARLOS ALBERTO | N42: DOCENTE | O42: 40435228 | P42: 990935896 | Q42: carlos.recuay@gmail.com | R42: - | S42: - | T42: 4 | U42: - | V42: TP | W42: CONCURSO | X42: CONTRATADO | Y42: 46125 | Z42: RCU 116-2026 | AA42: 46105 | AB42: - | AC42: SEDE | AD42: - | AE42: - | AF42: ADMINISTRACION DE EMPRESAS - EEGG | AG42: MAESTRIA | AH42: - | AI42: VIRTUAL | AK42: 0 | AL42: 0 | AM42: 0 | AN42: =AK42+AL42+AM42 -> 0 | AP42: 0 | AQ42: =AP42*T42 -> 0 | AR42: =AQ42*4 -> 0 | AS42: 0 | AT42: 0 | AU42: =AR42+AS42+AT42 -> 0
...

Sheet %D
B4: HUAURA
C5: ADMINISTRACION DE EMPRESAS | D5: DERECHO | E5: TOTAL | F5: %
B6: TC | C6: =+SUM(COUNTIFS(OGTH!$AC:$AC,$B4,OGTH!$AF:$AF,"ADMINISTRACION DE EMPRESAS",OGTH!$V:$V,"TC"),COUNTIFS(OGTH!$AC:$AC,$B4,OGTH!$AF:$AF,"ADMINISTRACION DE EMPRESAS - EEGG",OGTH!$V:$V,"TC")) -> 0 | D6: =+SUM(COUNTIFS(OGTH!$AC:$AC,$B4,OGTH!$AF:$AF,"DERECHO",OGTH!$V:$V,"TC"),COUNTIFS(OGTH!$AC:$AC,$B4,OGTH!$AF:$AF,"DERECHO - EEGG",OGTH!$V:$V,"TC")) -> 2 | E6: =+SUM(C6:D6) -> 2 | F6: =+E6/E8 -> 0.066666667
B7: TP | C7: =+SUM(COUNTIFS(OGTH!$AC:$AC,$B4,OGTH!$AF:$AF,"ADMINISTRACION DE EMPRESAS",OGTH!$V:$V,"TP"),COUNTIFS(OGTH!$AC:$AC,$B4,OGTH!$AF:$AF,"ADMINISTRACION DE EMPRESAS - EEGG",OGTH!$V:$V,"TP")) -> 11 | D7: =+SUM(COUNTIFS(OGTH!$AC:$AC,$B4,OGTH!$AF:$AF,"DERECHO",OGTH!$V:$V,"TP"),COUNTIFS(OGTH!$AC:$AC,$B4,OGTH!$AF:$AF,"DERECHO - EEGG",OGTH!$V:$V,"TP")) -> 17 | E7: =+SUM(C7:D7) -> 28 | F7: =+E7/E8 -> 0.93333333
B8: TOTAL | C8: =+C6+C7 -> 11 | D8: =+D6+D7 -> 19 | E8: =+E6+E7 -> 30 | F8: =+F6+F7 -> 1
B9: %TC | C9: =+C6/C8 -> 0 | D9: =+D6/D8 -> 0.10526316
B10: %TP | C10: =+C7/C8 -> 1 | D10: =+D7/D8 -> 0.89473684
B11: % | C11: =+C9+C10 -> 1 | D11: =+D9+D10 -> 1
B14: FILIAL
C15: ADMINISTRACION DE EMPRESAS | D15: ADMINISTRACION Y FINANZAS | E15: INGENIERIA INDUSTRIAL | F15: CONTABILIDAD | G15: DERECHO | H15: INGENIERIA CIVIL | I15: TOTAL | J15: %
B16: TC | C16: =+SUM(COUNTIFS(OGTH!$AC:$AC,$B14,OGTH!$AF:$AF,"ADMINISTRACION DE EMPRESAS",OGTH!$V:$V,"TC"),COUNTIFS(OGTH!$AC:$AC,$B14,OGTH!$AF:$AF,"ADMINISTRACION DE EMPRESAS - EEGG",OGTH!$V:$V,"TC")) -> 0 | D16: =+SUM(COUNTIFS(OGTH!$AC:$AC,$B14,OGTH!$AF:$AF,"ADMINISTRACION Y FINANZAS",OGTH!$V:$V,"TC"),COUNTIFS(OGTH!$AC:$AC,$B14,OGTH!$AF:$AF,"ADMINISTRACION Y FINANZAS - EEGG",OGTH!$V:$V,"TC")) -> 0 | E16: =+SUM(COUNTIFS(OGTH!$AC:$AC,$B14,OGTH!$AF:$AF,"INGENIERIA INDUSTRIAL",OGTH!$V:$V,"TC"),COUNTIFS(OGTH!$AC:$AC,$B14,OGTH!$AF:$AF,"INGENIERIA INDUSTRIAL - EEGG",OGTH!$V:$V,"TC")) -> 0 | F16: =+SUM(COUNTIFS(OGTH!$AC:$AC,$B14,OGTH!$AF:$AF,"CONTABILIDAD",OGTH!$V:$V,"TC"),COUNTIFS(OGTH!$AC:$AC,$B14,OGTH!$AF:$AF,"CONTABILIDAD - EEGG",OGTH!$V:$V,"TC")) -> 0 | G16: =+SUM(COUNTIFS(OGTH!$AC:$AC,$B14,OGTH!$AF:$AF,"DERECHO",OGTH!$V:$V,"TC"),COUNTIFS(OGTH!$AC:$AC,$B14,OGTH!$AF:$AF,"DERECHO - EEGG",OGTH!$V:$V,"TC")) -> 3 | H16: =+SUM(COUNTIFS(OGTH!$AC:$AC,$B14,OGTH!$AF:$AF,"INGENIERIA CIVIL",OGTH!$V:$V,"TC"),COUNTIFS(OGTH!$AC:$AC,$B14,OGTH!$AF:$AF,"INGENIERIA CIVIL - EEGG",OGTH!$V:$V,"TC")) -> 2 | I16: =+SUM(C16:H16) -> 5 | J16: =+I16/I18 -> 0.12820513
B17: TP | C17: =+SUM(COUNTIFS(OGTH!$AC:$AC,$B14,OGTH!$AF:$AF,"ADMINISTRACION DE EMPRESAS",OGTH!$V:$V,"TP"),COUNTIFS(OGTH!$AC:$AC,$B14,OGTH!$AF:$AF,"ADMINISTRACION DE EMPRESAS - EEGG",OGTH!$V:$V,"TP")) -> 0 | D17: =+SUM(COUNTIFS(OGTH!$AC:$AC,$B14,OGTH!$AF:$AF,"ADMINISTRACION Y FINANZAS",OGTH!$V:$V,"TP"),COUNTIFS(OGTH!$AC:$AC,$B14,OGTH!$AF:$AF,"ADMINISTRACION Y FINANZAS - EEGG",OGTH!$V:$V,"TP")) -> 2 | E17: =+SUM(COUNTIFS(OGTH!$AC:$AC,$B14,OGTH!$AF:$AF,"INGENIERIA INDUSTRIAL",OGTH!$V:$V,"TP"),COUNTIFS(OGTH!$AC:$AC,$B14,OGTH!$AF:$AF,"INGENIERIA INDUSTRIAL - EEGG",OGTH!$V:$V,"TP")) -> 2 | F17: =+SUM(COUNTIFS(OGTH!$AC:$AC,$B14,OGTH!$AF:$AF,"CONTABILIDAD",OGTH!$V:$V,"TP"),COUNTIFS(OGTH!$AC:$AC,$B14,OGTH!$AF:$AF,"CONTABILIDAD - EEGG",OGTH!$V:$V,"TP")) -> 6 | G17: =+SUM(COUNTIFS(OGTH!$AC:$AC,$B14,OGTH!$AF:$AF,"DERECHO",OGTH!$V:$V,"TP"),COUNTIFS(OGTH!$AC:$AC,$B14,OGTH!$AF:$AF,"DERECHO - EEGG",OGTH!$V:$V,"TP")) -> 15 | H17: =+SUM(COUNTIFS(OGTH!$AC:$AC,$B14,OGTH!$AF:$AF,"INGENIERIA CIVIL",OGTH!$V:$V,"TP"),COUNTIFS(OGTH!$AC:$AC,$B14,OGTH!$AF:$AF,"INGENIERIA CIVIL - EEGG",OGTH!$V:$V,"TP")) -> 9 | I17: =+SUM(C17:H17) -> 34 | J17: =+I17/I18 -> 0.87179487
B18: TOTAL | C18: =+C16+C17 -> 0 | D18: =+D16+D17 -> 2 | E18: =+E16+E17 -> 2 | F18: =+F16+F17 -> 6 | G18: =+G16+G17 -> 18 | H18: =+H16+H17 -> 11 | I18: =+I16+I17 -> 39 | J18: =+J16+J17 -> 1
B19: %TC | C19: =+C16/C18 -> #DIV/0! | D19: =+D16/D18 -> 0 | E19: =+E16/E18 -> 0 | F19: =+F16/F18 -> 0 | G19: =+G16/G18 -> 0.16666667 | H19: =+H16/H18 -> 0.18181818
B20: %TP | C20: =+C17/C18 -> #DIV/0! | D20: =+D17/D18 -> 1 | E20: =+E17/E18 -> 1 | F20: =+F17/F18 -> 1 | G20: =+G17/G18 -> 0.83333333 | H20: =+H17/H18 -> 0.81818182
B21: % | C21: =+C19+C20 -> #DIV/0! | D21: =+D19+D20 -> 1 | E21: =+E19+E20 -> 1 | F21: =+F19+F20 -> 1 | G21: =+G19+G20 -> 1 | H21: =+H19+H20 -> 1
B24: SEDE
C25: ADMINISTRACION DE EMPRESAS | D25: ADMINISTRACION Y FINANZAS | E25: INGENIERIA DE SISTEMAS | F25: INGENIERIA INDUSTRIAL | G25: DERECHO | H25: INGENIERIA CIVIL | I25: ARQUITECTURA | J25: TOTAL | K25: %
B26: TC | C26: =+SUM(COUNTIFS(OGTH!$AC:$AC,$B24,OGTH!$AF:$AF,"ADMINISTRACION DE EMPRESAS",OGTH!$V:$V,"TC"),COUNTIFS(OGTH!$AC:$AC,$B24,OGTH!$AF:$AF,"ADMINISTRACION DE EMPRESAS - EEGG",OGTH!$V:$V,"TC")) -> 1 | D26: =+SUM(COUNTIFS(OGTH!$AC:$AC,$B24,OGTH!$AF:$AF,"ADMINISTRACION Y FINANZAS",OGTH!$V:$V,"TC"),COUNTIFS(OGTH!$AC:$AC,$B24,OGTH!$AF:$AF,"ADMINISTRACION Y FINANZAS - EEGG",OGTH!$V:$V,"TC")) -> 3 | E26: =+SUM(COUNTIFS(OGTH!$AC:$AC,$B24,OGTH!$AF:$AF,"INGENIERIA DE SISTEMAS",OGTH!$V:$V,"TC"),COUNTIFS(OGTH!$AC:$AC,$B24,OGTH!$AF:$AF,"INGENIERIA DE SISTEMAS - EEGG",OGTH!$V:$V,"TC")) -> 4 | F26: =+SUM(COUNTIFS(OGTH!$AC:$AC,$B24,OGTH!$AF:$AF,"INGENIERIA INDUSTRIAL",OGTH!$V:$V,"TC"),COUNTIFS(OGTH!$AC:$AC,$B24,OGTH!$AF:$AF,"INGENIERIA INDUSTRIAL - EEGG",OGTH!$V:$V,"TC")) -> 8 | G26: =+SUM(COUNTIFS(OGTH!$AC:$AC,$B24,OGTH!$AF:$AF,"DERECHO",OGTH!$V:$V,"TC"),COUNTIFS(OGTH!$AC:$AC,$B24,OGTH!$AF:$AF,"DERECHO - EEGG",OGTH!$V:$V,"TC")) -> 3 | H26: =+SUM(COUNTIFS(OGTH!$AC:$AC,$B24,OGTH!$AF:$AF,"INGENIERIA CIVIL",OGTH!$V:$V,"TC"),COUNTIFS(OGTH!$AC:$AC,$B24,OGTH!$AF:$AF,"INGENIERIA CIVIL - EEGG",OGTH!$V:$V,"TC")) -> 2 | I26: =+SUM(COUNTIFS(OGTH!$AC:$AC,$B24,OGTH!$AF:$AF,"ARQUITECTURA",OGTH!$V:$V,"TC"),COUNTIFS(OGTH!$AC:$AC,$B24,OGTH!$AF:$AF,"ARQUITECTURA - EEGG",OGTH!$V:$V,"TC")) -> 1 | J26: =+SUM(C26:I26) -> 22 | K26: =+J26/J28 -> 0.2244898
B27: TP | C27: =+SUM(COUNTIFS(OGTH!$AC:$AC,$B24,OGTH!$AF:$AF,"ADMINISTRACION DE EMPRESAS",OGTH!$V:$V,"TP"),COUNTIFS(OGTH!$AC:$AC,$B24,OGTH!$AF:$AF,"ADMINISTRACION DE EMPRESAS - EEGG",OGTH!$V:$V,"TP")) -> 7 | D27: =+SUM(COUNTIFS(OGTH!$AC:$AC,$B24,OGTH!$AF:$AF,"ADMINISTRACION Y FINANZAS",OGTH!$V:$V,"TP"),COUNTIFS(OGTH!$AC:$AC,$B24,OGTH!$AF:$AF,"ADMINISTRACION Y FINANZAS - EEGG",OGTH!$V:$V,"TP")) -> 11 | E27: =+SUM(COUNTIFS(OGTH!$AC:$AC,$B24,OGTH!$AF:$AF,"INGENIERIA DE SISTEMAS",OGTH!$V:$V,"TP"),COUNTIFS(OGTH!$AC:$AC,$B24,OGTH!$AF:$AF,"INGENIERIA DE SISTEMAS - EEGG",OGTH!$V:$V,"TP")) -> 12 | F27: =+SUM(COUNTIFS(OGTH!$AC:$AC,$B24,OGTH!$AF:$AF,"INGENIERIA INDUSTRIAL",OGTH!$V:$V,"TP"),COUNTIFS(OGTH!$AC:$AC,$B24,OGTH!$AF:$AF,"INGENIERIA INDUSTRIAL - EEGG",OGTH!$V:$V,"TP")) -> 27 | G27: =+SUM(COUNTIFS(OGTH!$AC:$AC,$B24,OGTH!$AF:$AF,"DERECHO",OGTH!$V:$V,"TP"),COUNTIFS(OGTH!$AC:$AC,$B24,OGTH!$AF:$AF,"DERECHO - EEGG",OGTH!$V:$V,"TP")) -> 11 | H27: =+SUM(COUNTIFS(OGTH!$AC:$AC,$B24,OGTH!$AF:$AF,"INGENIERIA CIVIL",OGTH!$V:$V,"TP"),COUNTIFS(OGTH!$AC:$AC,$B24,OGTH!$AF:$AF,"INGENIERIA CIVIL - EEGG",OGTH!$V:$V,"TP")) -> 5 | I27: =+SUM(COUNTIFS(OGTH!$AC:$AC,$B24,OGTH!$AF:$AF,"ARQUITECTURA",OGTH!$V:$V,"TP"),COUNTIFS(OGTH!$AC:$AC,$B24,OGTH!$AF:$AF,"ARQUITECTURA - EEGG",OGTH!$V:$V,"TP")) -> 3 | J27: =+SUM(C27:I27) -> 76 | K27: =+J27/J28 -> 0.7755102
B28: TOTAL | C28: =+C26+C27 -> 8 | D28: =+D26+D27 -> 14 | E28: =+E26+E27 -> 16 | F28: =+F26+F27 -> 35 | G28: =+G26+G27 -> 14 | H28: =+H26+H27 -> 7 | I28: =+I26+I27 -> 4 | J28: =+J26+J27 -> 98 | K28: =+K26+K27 -> 1
