Workbook

Sheet Planes y aulas 2026
B2: RESUMEN PLANIFICACIÓN X CICLOS Y SECCIONES 2025-1 | K2: RESUMEN PLANIFICACIÓN X CICLOS Y SECCIONES 2025-2 | T2: RESUMEN PLANIFICACIÓN X CICLOS Y SECCIONES 2026-1
B4: SEMESTRE | C4: PLAN DE ESTUDIOS | D4: CODIGO DE PLAN | E4: LOCAL | F4: COD FACU | G4: PROGRAMA ACADÉMICO | H4: CICLO | I4: SECCIÓN | K4: SEMESTRE | L4: PLAN DE ESTUDIOS | M4: CODIGO DE PLAN | N4: LOCAL | O4: COD FACU | P4: PROGRAMA ACADÉMICO | Q4: CICLO | R4: SECCIÓN | T4: SEMESTRE | U4: PLAN DE ESTUDIOS | V4: CODIGO DE PLAN | W4: LOCAL | X4: COD FACU | Y4: PROGRAMA ACADÉMICO | Z4: CICLO | AA4: SECCIÓN
B5: 2025-1 | C5: RCU N° 344-2024-UAI-CU/P | D5: 20242 | E5: FILIAL | F5: I | G5: AF | H5: 3 | I5: A | K5: 2025-2 | L5: RCU Nº 354-2024-UAI-CU/P | M5: 20242 | N5: HUAURA | O5: FICA | P5: AE | Q5: 2 | R5: A
B6: 2025-1 | C6: RCU N° 249-2019-UAI-CU/P | D6: 202011 | E6: FILIAL | F6: I | G6: AF | H6: 6 | I6: A | K6: 2025-2 | L6: RCU Nº 354-2024-UAI-CU/P | M6: 20242 | N6: HUAURA | O6: FICA | P6: AE | Q6: 3 | R6: A
B7: 2025-1 | C7: RCU N° 249-2019-UAI-CU/P | D7: 202011 | E7: FILIAL | F7: I | G7: AF | H7: 7 | I7: A | K7: 2025-2 | L7: RCU Nº 354-2024-UAI-CU/P | M7: 20242 | N7: PRINCIPAL | O7: FICA | P7: AE | Q7: 2 | R7: A
B8: 2025-1 | C8: RCU N° 533-2024-UAI-CU/P | D8: 20251 | E8: FILIAL | F8: I | G8: CA | H8: 1 | I8: A | K8: 2025-2 | L8: RCU Nº 354-2024-UAI-CU/P | M8: 20242 | N8: PRINCIPAL | O8: FICA | P8: AE | Q8: 2 | R8: B
B9: 2025-1 | C9: RCU Nº 018-2021-UAI-CU/P | D9: 201722 | E9: FILIAL | F9: I | G9: CA | H9: 9 | I9: A | K9: 2025-2 | L9: RCU Nº 354-2024-UAI-CU/P | M9: 20242 | N9: PRINCIPAL | O9: FICA | P9: AE | Q9: 3 | R9: A
B10: 2025-1 | C10: RCU N° 348-2024-UAI-CU/P | D10: 20242 | E10: FILIAL | F10: I | G10: CA | H10: 9 | I10: B | K10: 2025-2 | L10: RCU Nº 354-2024-UAI-CU/P | M10: 20242 | N10: PRINCIPAL | O10: FICA | P10: AE | Q10: 3 | R10: B
B11: 2025-1 | C11: RCU N° 349-2024-UAI-CU/P | D11: 20242 | E11: FILIAL | F11: I | G11: DE | H11: 1 | I11: A | K11: 2025-2 | L11: RCU Nº 532-2024-UAI-CU/P | M11: 20251 | N11: PRINCIPAL | O11: FICA | P11: AE | Q11: 3 | R11: C
B12: 2025-1 | C12: RCU N° 349-2024-UAI-CU/P | D12: 20242 | E12: FILIAL | F12: I | G12: DE | H12: 1 | I12: B | K12: 2025-2 | L12: RCU Nº 354-2024-UAI-CU/P | M12: 20242 | N12: PRINCIPAL | O12: FICA | P12: AE | Q12: 4 | R12: A
B13: 2025-1 | C13: RCU N° 349-2024-UAI-CU/P | D13: 20242 | E13: FILIAL | F13: I | G13: DE | H13: 2 | I13: A | K13: 2025-2 | L13: RCU Nº 344-2024-UAI-CU/P | M13: 20242 | N13: FILIAL | O13: FICA | P13: AF | Q13: 5 | R13: A
B14: 2025-1 | C14: RCU N° 349-2024-UAI-CU/P | D14: 20242 | E14: FILIAL | F14: I | G14: DE | H14: 3 | I14: A | K14: 2025-2 | L14: RCU Nº 249-2019-UAI-CU/P | M14: 202011 | N14: FILIAL | O14: FICA | P14: AF | Q14: 8 | R14: A
B15: 2025-1 | C15: RCU N° 349-2024-UAI-CU/P | D15: 20242 | E15: FILIAL | F15: I | G15: DE | H15: 3 | I15: B | K15: 2025-2 | L15: RCU Nº 249-2019-UAI-CU/P | M15: 202011 | N15: FILIAL | O15: FICA | P15: AF | Q15: 9 | R15: A
B16: 2025-1 | C16: RCU N° 032-2023-UAI-CU/P | D16: 202312 | E16: FILIAL | F16: I | G16: DE | H16: 5 | I16: A | K16: 2025-2 | L16: RCU Nº 344-2024-UAI-CU/P | M16: 20242 | N16: PRINCIPAL | O16: FICA | P16: AF | Q16: 5 | R16: A
... B286: 2025-1 | C286: RCU Nº 069-2025-UAI-CU/P | D286: 20251 | E286: SUNAMPE | F286: S | G286: MH | H286: 3 | I286: C | K286: 2025-2 | L286: RCU Nº 346-2024-UAI-CU/P | M286: 20242 | N286: PRINCIPAL | O286: FCS | P286: PS | Q286: 5 | R286: B
K287: 2025-2 | L287: RCU Nº 346-2024-UAI-CU/P | M287: 20242 | N287: PRINCIPAL | O287: FCS | P287: PS | Q287: 6 | R287: A
H288: 282 | I288: Aulas | K288: 2025-2 | L288: RCU Nº 346-2024-UAI-CU/P | M288: 20242 | N288: PRINCIPAL | O288: FCS | P288: PS | Q288: 7 | R288: A
K289: 2025-2 | L289: RCU Nº 346-2024-UAI-CU/P | M289: 20242 | N289: PRINCIPAL | O289: FCS | P289: PS | Q289: 7 | R289: B
K290: 2025-2 | L290: RCU Nº 249-2019-UAI-CU/P | M290: 202011 | N290: PRINCIPAL | O290: FCS | P290: PS | Q290: 8 | R290: A
K291: 2025-2 | L291: RCU Nº 249-2019-UAI-CU/P | M291: 202011 | N291: PRINCIPAL | O291: FCS | P291: PS | Q291: 8 | R291: X
K292: 2025-2 | L292: RCU Nº 249-2019-UAI-CU/P | M292: 202011 | N292: PRINCIPAL | O292: FCS | P292: PS | Q292: 9 | R292: A
K293: 2025-2 | L293: RCU Nº 249-2019-UAI-CU/P | M293: 202011 | N293: PRINCIPAL | O293: FCS | P293: PS | Q293: 9 | R293: B
K294: 2025-2 | L294: RCU Nº 249-2019-UAI-CU/P | M294: 202011 | N294: PRINCIPAL | O294: FCS | P294: PS | Q294: 9 | R294: C
K295: 2025-2 | L295: RCU Nº 249-2019-UAI-CU/P | M295: 202011 | N295: PRINCIPAL | O295: FCS | P295: PS | Q295: 10 | R295: A
K296: 2025-2 | L296: RCU Nº 364-2024-UAI-CU/P | M296: 20251 | N296: FILIAL | O296: FCS | P296: T1 | Q296: 3 | R296: A
K297: 2025-2 | L297: RCU Nº 364-2024-UAI-CU/P | M297: 20251 | N297: PRINCIPAL | O297: FCS | P297: T1 | Q297: 3 | R297: A
K298: 2025-2 | L298: RCU Nº 365-2024-UAI-CU/P | M298: 20251 | N298: FILIAL | O298: FCS | P298: T2 | Q298: 3 | R298: A
K299: 2025-2 | L299: RCU Nº 366-2024-UAI-CU/P | M299: 20251 | N299: FILIAL | O299: FCS | P299: T3 | Q299: 2 | R299: A
K300: 2025-2 | L300: RCU Nº 366-2024-UAI-CU/P | M300: 20251 | N300: FILIAL | O300: FCS | P300: T3 | Q300: 3 | R300: A
... K307: 2025-2 | L307: RCU Nº 531-2024-UAI-CU/P | M307: 20251 | N307: PRINCIPAL | O307: FCS | P307: T4 | Q307: 3 | R307: D

Sheet EDITABLE
I2: SEDE | Z2: FILIAL | AQ2: SUNAMPE | BH2: HUAURA | BY2: HORAS POR CARRERA | CO2: HORAS POR CARRERA EEGG | EC2: EEGG
B3: N° | C3: DOCENTES UAI | D3: HORAS | E3: DEDICACIÓN | F3: CONDICIÓN | G3: LOCAL 2025-2 | H3: PROGRAMA ACADÉMICO 2025-2 | I3: ADM | J3: ENF | K3: ING SIS | L3: PS | M3: IND AL | N3: IND | O3: CONT | P3: DE | Q3: OBS | R3: MEDICINA | S3: ING CIVIL | T3: ARQUI | U3: LAB. CLIN | V3: TERAPIA FIS. | W3: TERAPIA LEN. | X3: ADM. EMP | Y3: OPTOM. | Z3: ADM | AA3: ENF | AB3: ING SIS | AC3: PS | AD3: IND AL | AE3: IND | AF3: CONT | AG3: DE | AH3: OBS | AI3: MEDICINA | AJ3: ING CIVIL | AK3: ARQUI | AL3: LAB. CLIN | AM3: TERAPIA FIS. | AN3: TERAPIA LEN. | AO3: ADM. EMP | AP3: OPTOM. | AQ3: ADM | AR3: ENF | AS3: ING SIS | AT3: PS | AU3: IND AL | AV3: IND | AW3: CONT | AX3: DE | AY3: OBS | AZ3: MEDICINA | BA3: ING CIVIL | BB3: ARQUI | BC3: LAB. CLIN | BD3: TERAPIA FIS. | BE3: TERAPIA LEN. | BF3: ADM. EMP | BG3: OPTOM. | BH3: ADM | BI3: ENF | BJ3: ING SIS | BK3: PS | BL3: IND AL | BM3: IND | BN3: CONT | BO3: DE | BP3: OBS | BQ3: MEDICINA | BR3: ING CIVIL | BS3: ARQUI | BT3: LAB. CLIN | BU3: TERAPIA FIS. | BV3: TERAPIA LEN. | BW3: ADM. EMP | BX3: OPTOM. | BY3: ADMINISTRACIÓN Y FINANZAS | BZ3: ENFERMERÍA | CA3: INGENIERÍA DE SISTEMAS | CB3: PSICOLOGÍA | CC3: INGENIERÍA INDUSTRIAL | CD3: CONTABILIDAD | CE3: DERECHO | CF3: OBSTETRICIA | CG3: MEDICINA HUMANA | CH3: INGENIERÍA CIVIL | CI3: ARQUITECTURA | CJ3: TECNOLOGÍA MEDICA EN LABORATORIO CLÍNICO Y ANATOMÍA PATOLÓGICA | CK3: TECNOLOGÍA MEDICA EN TERAPIA FÍSICA Y REHABILITACIÓN | CL3: TECNOLOGÍA MEDICA EN TERAPIA DE LENGUAJE | CM3: ADMINISTRACIÓN DE EMPRESAS | CN3: TECNOLOGÍA MEDICA EN OPTOMETRÍA | CO3: ADMINISTRACIÓN Y FINANZAS - EEGG | CP3: ENFERMERÍA - EEGG | CQ3: INGENIERÍA DE SISTEMAS - EEGG | CR3: PSICOLOGÍA - EEGG | CS3: INGENIERÍA INDUSTRIAL - EEGG | CT3: CONTABILIDAD - EEGG | CU3: DERECHO - EEGG | CV3: OBSTETRICIA - EEGG | CW3: MEDICINA HUMANA - EEGG | CX3: INGENIERÍA CIVIL - EEGG | CY3: ARQUITECTURA - EEGG | CZ3: TECNOLOGÍA MEDICA EN LABORATORIO CLÍNICO Y ANATOMÍA PATOLÓGICA - EEGG | DA3: TECNOLOGÍA MEDICA EN TERAPIA FÍSICA Y REHABILITACIÓN - EEGG | DB3: TECNOLOGÍA MEDICA EN TERAPIA DE LENGUAJE - EEGG | DC3: ADMINISTRACIÓN DE EMPRESAS - EEGG | DD3: TECNOLOGÍA MEDICA EN OPTOMETRÍA - EEGG | DE3: SEDE | DF3: HORAS VIRTUAL | DG3: HORAS PRESENCIAL | DH3: HORAS HIBRIDAS | DI3: FILIAL | DJ3: HORAS VIRTUAL | DK3: HORAS PRESENCIAL | DL3: HORAS HIBRIDAS | DM3: SUNAMPE | DN3: HORAS VIRTUAL | DO3: HORAS PRESENCIAL | DP3: HUAURA | DQ3: HORAS VIRTUAL | DR3: HORAS PRESENCIAL | DS3: SEDE-VIRTUAL | DT3: SEDE-PRESENCIAL | DU3: SUNAMPE-VIRTUAL | DV3: SUNAMPE-PRESENCIAL | DW3: FILIAL-VIRTUAL | DX3: FILIAL-PRESENCIAL | DY3: PORUMA-VIRTUAL | DZ3: PORUMA-PRESENCIAL | EA3: HUAURA-VIRTUAL | EB3: HUAURA-PRESENCIAL | EC3: SEDE-VIRTUAL | ED3: SEDE-PRESENCIAL | EE3: SUNAMPE-VIRTUAL | EF3: SUNAMPE-PRESENCIAL | EG3: FILIAL-VIRTUAL | EH3: FILIAL-PRESENCIAL | EI3: PORUMA-VIRTUAL | EJ3: PORUMA-PRESENCIAL | EK3: HUAURA-VIRTUAL | EL3: HUAURA-PRESENCIAL | EN3: VIRTUAL | EO3: PRESENCIAL
B4: 1 | C4: ACEVEDO CRUZ EVELYN CRISPINA | D4: =SUMIF('Planificación 2026-1'!W:W,C4,'Planificación 2026-1'!R:R) -> 0 | E4: TP | F4: RENOVACIÓN | G4: FILIAL | H4: OBSTETRICIA - EEGG | I4: =IF(SUM(COUNTIFS('Planificación 2026-1'!F:F,"PRINCIPAL",'Planificación 2026-1'!W:W,C4,'Planificación 2026-1'!H:H,"AF"))>0,"P01"," ") | J4: =IF(SUM(COUNTIFS('Planificación 2026-1'!F:F,"PRINCIPAL",'Planificación 2026-1'!W:W,C4,'Planificación 2026-1'!H:H,"EN"))>0,"P02"," ") | K4: =IF(SUM(COUNTIFS('Planificación 2026-1'!F:F,"PRINCIPAL",'Planificación 2026-1'!W:W,C4,'Planificación 2026-1'!H:H,"IS"))>0,"P03"," ") | L4: =IF(SUM(COUNTIFS('Planificación 2026-1'!F:F,"PRINCIPAL",'Planificación 2026-1'!W:W,C4,'Planificación 2026-1'!H:H,"PS"))>0,"P04"," ") | N4: =IF(SUM(COUNTIFS('Planificación 2026-1'!F:F,"PRINCIPAL",'Planificación 2026-1'!W:W,C4,'Planificación 2026-1'!H:H,"IN"))>0,"P06"," ") | O4: =IF(SUM(COUNTIFS('Planificación 2026-1'!F:F,"PRINCIPAL",'Planificación 2026-1'!W:W,C4,'Planificación 2026-1'!H:H,"CA"))>0,"P07"," ") | P4: =IF(SUM(COUNTIFS('Planificación 2026-1'!F:F,"PRINCIPAL",'Planificación 2026-1'!W:W,C4,'Planificación 2026-1'!H:H,"DE"))>0,"P08"," ") | Q4: =IF(SUM(COUNTIFS('Planificación 2026-1'!F:F,"PRINCIPAL",'Planificación 2026-1'!W:W,C4,'Planificación 2026-1'!H:H,"OB"))>0,"P09"," ") | R4: =IF(SUM(COUNTIFS('Planificación 2026-1'!F:F,"PRINCIPAL",'Planificación 2026-1'!W:W,C4,'Planificación 2026-1'!H:H,"MH"))>0,"P31"," ") | S4: =IF(SUM(COUNTIFS('Planificación 2026-1'!F:F,"PRINCIPAL",'Planificación 2026-1'!W:W,C4,'Planificación 2026-1'!H:H,"IC"))>0,"P32"," ") | T4: =IF(SUM(COUNTIFS('Planificación 2026-1'!F:F,"PRINCIPAL",'Planificación 2026-1'!W:W,C4,'Planificación 2026-1'!H:H,"AR"))>0,"P34"," ") | U4: =IF(SUM(COUNTIFS('Planificación 2026-1'!F:F,"PRINCIPAL",'Planificación 2026-1'!W:W,C4,'Planificación 2026-1'!H:H,"T1"))>0,"P35"," ") | V4: =IF(SUM(COUNTIFS('Planificación 2026-1'!F:F,"PRINCIPAL",'Planificación 2026-1'!W:W,C4,'Planificación 2026-1'!H:H,"T3"))>0,"P36"," ") | W4: =IF(SUM(COUNTIFS('Planificación 2026-1'!F:F,"PRINCIPAL",'Planificación 2026-1'!W:W,C4,'Planificación 2026-1'!H:H,"T2"))>0,"P37"," ") | X4: =IF(SUM(COUNTIFS('Planificación 2026-1'!F:F,"PRINCIPAL",'Planificación 2026-1'!W:W,C4,'Planificación 2026-1'!H:H,"AE"))>0,"P38"," ") | Y4: =IF(SUM(COUNTIFS('Planificación 2026-1'!F:F,"PRINCIPAL",'Planificación 2026-1'!W:W,C4,'Planificación 2026-1'!H:H,"T4"))>0,"P55"," ") | Z4: =IF(SUM(COUNTIFS('Planificación 2026-1'!F:F,"FILIAL",'Planificación 2026-1'!W:W,C4,'Planificación 2026-1'!H:H,"AF"))>0," P01"," ") | AA4: =IF(SUM(COUNTIFS('Planificación 2026-1'!F:F,"FILIAL",'Planificación 2026-1'!W:W,C4,'Planificación 2026-1'!H:H,"EN"))>0,"P02"," ") | AB4: =IF(SUM(COUNTIFS('Planificación 2026-1'!F:F,"FILIAL",'Planificación 2026-1'!W:W,C4,'Planificación 2026-1'!H:H,"IS"))>0,"P03"," ") | AC4: =IF(SUM(COUNTIFS('Planificación 2026-1'!F:F,"FILIAL",'Planificación 2026-1'!W:W,C4,'Planificación 2026-1'!H:H,"PS"))>0,"P04"," ") | AE4: =IF(SUM(COUNTIFS('Planificación 2026-1'!F:F,"FILIAL",'Planificación 2026-1'!W:W,C4,'Planificación 2026-1'!H:H,"IN"))>0,"P06"," ") | AF4: =IF(SUM(COUNTIFS('Planificación 2026-1'!F:F,"FILIAL",'Planificación 2026-1'!W:W,C4,'Planificación 2026-1'!H:H,"CA"))>0,"P07"," ") | AG4: =IF(SUM(COUNTIFS('Planificación 2026-1'!F:F,"FILIAL",'Planificación 2026-1'!W:W,C4,'Planificación 2026-1'!H:H,"DE"))>0,"P08"," ") | AH4: =IF(SUM(COUNTIFS('Planificación 2026-1'!F:F,"FILIAL",'Planificación 2026-1'!W:W,C4,'Planificación 2026-1'!H:H,"OB"))>0,"P09"," ") | AI4: =IF(SUM(COUNTIFS('Planificación 2026-1'!F:F,"FILIAL",'Planificación 2026-1'!W:W,C4,'Planificación 2026-1'!H:H,"MH"))>0,"P31"," ") | AJ4: =IF(SUM(COUNTIFS('Planificación 2026-1'!F:F,"FILIAL",'Planificación 2026-1'!W:W,C4,'Planificación 2026-1'!H:H,"IC"))>0,"P32"," ") | AK4: =IF(SUM(COUNTIFS('Planificación 2026-1'!F:F,"FILIAL",'Planificación 2026-1'!W:W,C4,'Planificación 2026-1'!H:H,"AR"))>0,"P34"," ") | AL4: =IF(SUM(COUNTIFS('Planificación 2026-1'!F:F,"FILIAL",'Planificación 2026-1'!W:W,C4,'Planificación 2026-1'!H:H,"T1"))>0,"P35"," ") | AM4: =IF(SUM(COUNTIFS('Planificación 2026-1'!F:F,"FILIAL",'Planificación 2026-1'!W:W,C4,'Planificación 2026-1'!H:H,"T3"))>0,"P36"," ") | AN4: =IF(SUM(COUNTIFS('Planificación 2026-1'!F:F,"FILIAL",'Planificación 2026-1'!W:W,C4,'Planificación 2026-1'!H:H,"T2"))>0,"P37"," ") | AO4: =IF(SUM(COUNTIFS('Planificación 2026-1'!F:F,"FILIAL",'Planificación 2026-1'!W:W,C4,'Planificación 2026-1'!H:H,"AE"))>0,"P38"," ") | AP4: =IF(SUM(COUNTIFS('Planificación 2026-1'!F:F,"FILIAL",'Planificación 2026-1'!W:W,C4,'Planificación 2026-1'!H:H,"T4"))>0,"P55"," ") | AQ4: =IF(SUM(COUNTIFS('Planificación 2026-1'!F:F,"SUNAMPE",'Planificación 2026-1'!W:W,C4,'Planificación 2026-1'!H:H,"AF"))>0," P01"," ") | AR4: =IF(SUM(COUNTIFS('Planificación 2026-1'!F:F,"SUNAMPE",'Planificación 2026-1'!W:W,C4,'Planificación 2026-1'!H:H,"EN"))>0,"P02"," ") | AS4: =IF(SUM(COUNTIFS('Planificación 2026-1'!F:F,"SUNAMPE",'Planificación 2026-1'!W:W,C4,'Planificación 2026-1'!H:H,"IS"))>0,"P03"," ") | AT4: =IF(SUM(COUNTIFS('Planificación 2026-1'!F:F,"SUNAMPE",'Planificación 2026-1'!W:W,C4,'Planificación 2026-1'!H:H,"PS"))>0,"P04"," ") | AV4: =IF(SUM(COUNTIFS('Planificación 2026-1'!F:F,"SUNAMPE",'Planificación 2026-1'!W:W,C4,'Planificación 2026-1'!H:H,"IN"))>0,"P06"," ") | AW4: =IF(SUM(COUNTIFS('Planificación 2026-1'!F:F,"SUNAMPE",'Planificación 2026-1'!W:W,C4,'Planificación 2026-1'!H:H,"CA"))>0,"P07"," ") | AX4: =IF(SUM(COUNTIFS('Planificación 2026-1'!F:F,"SUNAMPE",'Planificación 2026-1'!W:W,C4,'Planificación 2026-1'!H:H,"DE"))>0,"P08"," ") | AY4: =IF(SUM(COUNTIFS('Planificación 2026-1'!F:F,"SUNAMPE",'Planificación 2026-1'!W:W,C4,'Planificación 2026-1'!H:H,"OB"))>0,"P09"," ") | AZ4: =IF(SUM(COUNTIFS('Planificación 2026-1'!F:F,"SUNAMPE",'Planificación 2026-1'!W:W,C4,'Planificación 2026-1'!H:H,"MH"))>0,"P31"," ") | BA4: =IF(SUM(COUNTIFS('Planificación 2026-1'!F:F,"SUNAMPE",'Planificación 2026-1'!W:W,C4,'Planificación 2026-1'!H:H,"IC"))>0,"P32"," ") | BB4: =IF(SUM(COUNTIFS('Planificación 2026-1'!F:F,"SUNAMPE",'Planificación 2026-1'!W:W,C4,'Planificación 2026-1'!H:H,"AR"))>0,"P34"," ") | BC4: =IF(SUM(COUNTIFS('Planificación 2026-1'!F:F,"SUNAMPE",'Planificación 2026-1'!W:W,C4,'Planificación 2026-1'!H:H,"T1"))>0,"P35"," ") | BD4: =IF(SUM(COUNTIFS('Planificación 2026-1'!F:F,"SUNAMPE",'Planificación 2026-1'!W:W,C4,'Planificación 2026-1'!H:H,"T3"))>0,"P36"," ") | BE4: =IF(SUM(COUNTIFS('Planificación 2026-1'!F:F,"SUNAMPE",'Planificación 2026-1'!W:W,C4,'Planificación 2026-1'!H:H,"T2"))>0,"P37"," ") | BF4: =IF(SUM(COUNTIFS('Planificación 2026-1'!F:F,"SUNAMPE",'Planificación 2026-1'!W:W,C4,'Planificación 2026-1'!H:H,"AE"))>0,"P38"," ") | BG4: =IF(SUM(COUNTIFS('Planificación 2026-1'!F:F,"SUNAMPE",'Planificación 2026-1'!W:W,C4,'Planificación 2026-1'!H:H,"T4"))>0,"P55"," ") | BH4: =IF(SUM(COUNTIFS('Planificación 2026-1'!F:F,"HUAURA",'Planificación 2026-1'!W:W,C4,'Planificación 2026-1'!H:H,"AF"))>0," P01"," ") | BI4: =IF(SUM(COUNTIFS('Planificación 2026-1'!F:F,"HUAURA",'Planificación 2026-1'!W:W,C4,'Planificación 2026-1'!H:H,"EN"))>0,"P02"," ") | BJ4: =IF(SUM(COUNTIFS('Planificación 2026-1'!F:F,"HUAURA",'Planificación 2026-1'!W:W,C4,'Planificación 2026-1'!H:H,"IS"))>0,"P03"," ") | BK4: =IF(SUM(COUNTIFS('Planificación 2026-1'!F:F,"HUAURA",'Planificación 2026-1'!W:W,C4,'Planificación 2026-1'!H:H,"PS"))>0,"P04"," ") | BM4: =IF(SUM(COUNTIFS('Planificación 2026-1'!F:F,"HUAURA",'Planificación 2026-1'!W:W,C4,'Planificación 2026-1'!H:H,"IN"))>0,"P06"," ") | BN4: =IF(SUM(COUNTIFS('Planificación 2026-1'!F:F,"HUAURA",'Planificación 2026-1'!W:W,C4,'Planificación 2026-1'!H:H,"CA"))>0,"P07"," ") | BO4: =IF(SUM(COUNTIFS('Planificación 2026-1'!F:F,"HUAURA",'Planificación 2026-1'!W:W,C4,'Planificación 2026-1'!H:H,"DE"))>0,"P08"," ") | BP4: =IF(SUM(COUNTIFS('Planificación 2026-1'!F:F,"HUAURA",'Planificación 2026-1'!W:W,C4,'Planificación 2026-1'!H:H,"OB"))>0,"P09"," ") | BQ4: =IF(SUM(COUNTIFS('Planificación 2026-1'!F:F,"HUAURA",'Planificación 2026-1'!W:W,C4,'Planificación 2026-1'!H:H,"MH"))>0,"P31"," ") | BR4: =IF(SUM(COUNTIFS('Planificación 2026-1'!F:F,"HUAURA",'Planificación 2026-1'!W:W,C4,'Planificación 2026-1'!H:H,"IC"))>0,"P32"," ") | BS4: =IF(SUM(COUNTIFS('Planificación 2026-1'!F:F,"HUAURA",'Planificación 2026-1'!W:W,C4,'Planificación 2026-1'!H:H,"AR"))>0,"P34"," ") | BT4: =IF(SUM(COUNTIFS('Planificación 2026-1'!F:F,"HUAURA",'Planificación 2026-1'!W:W,C4,'Planificación 2026-1'!H:H,"T1"))>0,"P35"," ") | BU4: =IF(SUM(COUNTIFS('Planificación 2026-1'!F:F,"HUAURA",'Planificación 2026-1'!W:W,C4,'Planificación 2026-1'!H:H,"T3"))>0,"P36"," ") | BV4: =IF(SUM(COUNTIFS('Planificación 2026-1'!F:F,"HUAURA",'Planificación 2026-1'!W:W,C4,'Planificación 2026-1'!H:H,"T2"))>0,"P37"," ") | BW4: =IF(SUM(COUNTIFS('Planificación 2026-1'!F:F,"HUAURA",'Planificación 2026-1'!W:W,C4,'Planificación 2026-1'!H:H,"AE"))>0,"P38"," ") | BX4: =IF(SUM(COUNTIFS('Planificación 2026-1'!F:F,"HUAURA",'Planificación 2026-1'!W:W,C4,'Planificación 2026-1'!H:H,"T4"))>0,"P55"," ") | BY4: =SUMIFS('Planificación 2026-1'!R:R,'Planificación 2026-1'!W:W,C4,'Planificación 2026-1'!H:H,"AF",'Planificación 2026-1'!I:I,">2") -> 0 | BZ4: =SUMIFS('Planificación 2026-1'!R:R,'Planificación 2026-1'!W:W,C4,'Planificación 2026-1'!H:H,"EN",'Planificación 2026-1'!I:I,">2") -> 0 | CA4: =SUMIFS('Planificación 2026-1'!R:R,'Planificación 2026-1'!W:W,C4,'Planificación 2026-1'!H:H,"IS",'Planificación 2026-1'!I:I,">2") -> 0 | CB4: =SUMIFS('Planificación 2026-1'!R:R,'Planificación 2026-1'!W:W,C4,'Planificación 2026-1'!H:H,"PS",'Planificación 2026-1'!I:I,">2") -> 0 | CC4: =SUMIFS('Planificación 2026-1'!R:R,'Planificación 2026-1'!W:W,C4,'Planificación 2026-1'!H:H,"IN",'Planificación 2026-1'!I:I,">2") -> 0 | CD4: =SUMIFS('Planificación 2026-1'!R:R,'Planificación 2026-1'!W:W,C4,'Planificación 2026-1'!H:H,"CA",'Planificación 2026-1'!I:I,">2") -> 0 | CE4: =SUMIFS('Planificación 2026-1'!R:R,'Planificación 2026-1'!W:W,C4,'Planificación 2026-1'!H:H,"DE",'Planificación 2026-1'!I:I,">2") -> 0 | CF4: =SUMIFS('Planificación 2026-1'!R:R,'Planificación 2026-1'!W:W,C4,'Planificación 2026-1'!H:H,"OB",'Planificación 2026-1'!I:I,">2") -> 0 | CG4: =SUMIFS('Planificación 2026-1'!R:R,'Planificación 2026-1'!W:W,C4,'Planificación 2026-1'!H:H,"MH",'Planificación 2026-1'!I:I,">2") -> 0 | CH4: =SUMIFS('Planificación 2026-1'!R:R,'Planificación 2026-1'!W:W,C4,'Planificación 2026-1'!H:H,"IC",'Planificación 2026-1'!I:I,">2") -> 0 | CI4: =SUMIFS('Planificación 2026-1'!R:R,'Planificación 2026-1'!W:W,C4,'Planificación 2026-1'!H:H,"AR",'Planificación 2026-1'!I:I,">2") -> 0 | CJ4: =SUMIFS('Planificación 2026-1'!R:R,'Planificación 2026-1'!W:W,C4,'Planificación 2026-1'!H:H,"T1",'Planificación 2026-1'!I:I,">2") -> 0 | CK4: =SUMIFS('Planificación 2026-1'!R:R,'Planificación 2026-1'!W:W,C4,'Planificación 2026-1'!H:H,"T3",'Planificación 2026-1'!I:I,">2") -> 0 | CL4: =SUMIFS('Planificación 2026-1'!R:R,'Planificación 2026-1'!W:W,C4,'Planificación 2026-1'!H:H,"T2",'Planificación 2026-1'!I:I,">2") -> 0 | CM4: =SUMIFS('Planificación 2026-1'!R:R,'Planificación 2026-1'!W:W,C4,'Planificación 2026-1'!H:H,"AE",'Planificación 2026-1'!I:I,">2") -> 0 | CN4: =SUMIFS('Planificación 2026-1'!R:R,'Planificación 2026-1'!W:W,C4,'Planificación 2026-1'!H:H,"T4",'Planificación 2026-1'!I:I,">2") -> 0 | CO4: =SUMIFS('Planificación 2026-1'!R:R,'Planificación 2026-1'!W:W,C4,'Planificación 2026-1'!H:H,"AF",'Planificación 2026-1'!I:I,"<3") -> 0 | CP4: =SUMIFS('Planificación 2026-1'!R:R,'Planificación 2026-1'!W:W,C4,'Planificación 2026-1'!H:H,"EN",'Planificación 2026-1'!I:I,"<3") -> 0 | CQ4: =SUMIFS('Planificación 2026-1'!R:R,'Planificación 2026-1'!W:W,C4,'Planificación 2026-1'!H:H,"IS",'Planificación 2026-1'!I:I,"<3") -> 0 | CR4: =SUMIFS('Planificación 2026-1'!R:R,'Planificación 2026-1'!W:W,C4,'Planificación 2026-1'!H:H,"PS",'Planificación 2026-1'!I:I,"<3") -> 0 | CS4: =SUMIFS('Planificación 2026-1'!R:R,'Planificación 2026-1'!W:W,C4,'Planificación 2026-1'!H:H,"IN",'Planificación 2026-1'!I:I,"<3") -> 0 | CT4: =SUMIFS('Planificación 2026-1'!R:R,'Planificación 2026-1'!W:W,C4,'Planificación 2026-1'!H:H,"CA",'Planificación 2026-1'!I:I,"<3") -> 0 | CU4: =SUMIFS('Planificación 2026-1'!R:R,'Planificación 2026-1'!W:W,C4,'Planificación 2026-1'!H:H,"DE",'Planificación 2026-1'!I:I,"<3") -> 0 | CV4: =SUMIFS('Planificación 2026-1'!R:R,'Planificación 2026-1'!W:W,C4,'Planificación 2026-1'!H:H,"OB",'Planificación 2026-1'!I:I,"<3") -> 0 | CW4: =SUMIFS('Planificación 2026-1'!R:R,'Planificación 2026-1'!W:W,C4,'Planificación 2026-1'!H:H,"MH",'Planificación 2026-1'!I:I,"<3") -> 0 | CX4: =SUMIFS('Planificación 2026-1'!R:R,'Planificación 2026-1'!W:W,C4,'Planificación 2026-1'!H:H,"IC",'Planificación 2026-1'!I:I,"<3") -> 0 | CY4: =SUMIFS('Planificación 2026-1'!R:R,'Planificación 2026-1'!W:W,C4,'Planificación 2026-1'!H:H,"AR",'Planificación 2026-1'!I:I,"<3") -> 0 | CZ4: =SUMIFS('Planificación 2026-1'!R:R,'Planificación 2026-1'!W:W,C4,'Planificación 2026-1'!H:H,"T1",'Planificación 2026-1'!I:I,"<3") -> 0 | DA4: =SUMIFS('Planificación 2026-1'!R:R,'Planificación 2026-1'!W:W,C4,'Planificación 2026-1'!H:H,"T3",'Planificación 2026-1'!I:I,"<3") -> 0 | DB4: =SUMIFS('Planificación 2026-1'!R:R,'Planificación 2026-1'!W:W,C4,'Planificación 2026-1'!H:H,"T2",'Planificación 2026-1'!I:I,"<3") -> 0 | DC4: =SUMIFS('Planificación 2026-1'!R:R,'Planificación 2026-1'!W:W,C4,'Planificación 2026-1'!H:H,"AE",'Planificación 2026-1'!I:I,"<3") -> 0 | DD4: =SUMIFS('Planificación 2026-1'!R:R,'Planificación 2026-1'!W:W,C4,'Planificación 2026-1'!H:H,"T4",'Planificación 2026-1'!I:I,"<3") -> 0 | DE4: =TRIM(CONCATENATE(I4,J4,K4,L4,M4,N4,O4,P4,Q4,R4,S4,T4,U4,V4,W4,X4,Y4)) | DF4: =IF(C4="","",SUMIFS('Planificación 2026-1'!R:R,'Planificación 2026-1'!W:W,C4,'Planificación 2026-1'!F:F,"PRINCIPAL",'Planificación 2026-1'!X:X,"VIRTUAL")) -> 0 | DG4: =IF(C4="","",SUMIFS('Planificación 2026-1'!R:R,'Planificación 2026-1'!W:W,C4,'Planificación 2026-1'!F:F,"PRINCIPAL",'Planificación 2026-1'!X:X,"PRESENCIAL")) -> 0 | DH4: =IF(C4="","",SUMIFS('Planificación 2026-1'!R:R,'Planificación 2026-1'!W:W,C4,'Planificación 2026-1'!F:F,"PRINCIPAL",'Planificación 2026-1'!X:X,"HIBRIDO PRESENCIAL")) -> 0 | DI4: =TRIM(CONCATENATE(Z4,AA4,AB4,AC4,AD4,AE4,AF4,AG4,AH4,AI4,AJ4,AK4,AL4,AM4,AN4,AO4,AP4)) | DJ4: =IF(C4="","",SUMIFS('Planificación 2026-1'!R:R,'Planificación 2026-1'!W:W,C4,'Planificación 2026-1'!F:F,"FILIAL",'Planificación 2026-1'!X:X,"VIRTUAL")) -> 0 | DK4: =IF(C4="","",SUMIFS('Planificación 2026-1'!R:R,'Planificación 2026-1'!W:W,C4,'Planificación 2026-1'!F:F,"FILIAL",'Planificación 2026-1'!X:X,"PRESENCIAL")) -> 0 | DL4: =IF(C4="","",SUMIFS('Planificación 2026-1'!R:R,'Planificación 2026-1'!W:W,C4,'Planificación 2026-1'!F:F,"FILIAL",'Planificación 2026-1'!X:X,"HIBRIDO PRESENCIAL")) -> 0 | DM4: =TRIM(CONCATENATE(AQ4,AR4,AS4,AT4,AU4,AV4,AW4,AX4,AY4,AZ4,BA4,BB4,BC4,BD4,BE4,BF4,BG4)) | DN4: =IF(C4="","",SUMIFS('Planificación 2026-1'!R:R,'Planificación 2026-1'!W:W,C4,'Planificación 2026-1'!F:F,"SUNAMPE",'Planificación 2026-1'!X:X,"VIRTUAL")) -> 0 | DO4: =IF(C4="","",SUMIFS('Planificación 2026-1'!R:R,'Planificación 2026-1'!W:W,C4,'Planificación 2026-1'!F:F,"SUNAMPE",'Planificación 2026-1'!X:X,"PRESENCIAL")) -> 0 | DP4: =TRIM(CONCATENATE(BH4,BI4,BJ4,BK4,BL4,BM4,BN4,BO4,BP4,BQ4,BR4,BS4,BT4,BU4,BV4,BW4,BX4)) | DQ4: =IF(C4="","",SUMIFS('Planificación 2026-1'!R:R,'Planificación 2026-1'!W:W,C4,'Planificación 2026-1'!F:F,"HUAURA",'Planificación 2026-1'!X:X,"VIRTUAL")) -> 0 | DR4: =IF(C4="","",SUMIFS('Planificación 2026-1'!R:R,'Planificación 2026-1'!W:W,C4,'Planificación 2026-1'!F:F,"HUAURA",'Planificación 2026-1'!X:X,"PRESENCIAL")) -> 0 | DS4: =SUMIFS('Planificación 2026-1'!R:R,'Planificación 2026-1'!W:W,C4,'Planificación 2026-1'!F:F,"PRINCIPAL",'Planificación 2026-1'!X:X,"VIRTUAL",'Planificación 2026-1'!I:I,">2") -> 0 | DT4: =SUMIFS('Planificación 2026-1'!R:R,'Planificación 2026-1'!W:W,C4,'Planificación 2026-1'!F:F,"PRINCIPAL",'Planificación 2026-1'!X:X,"<>VIRTUAL",'Planificación 2026-1'!I:I,">2") -> 0 | DU4: =SUMIFS('Planificación 2026-1'!R:R,'Planificación 2026-1'!W:W,C4,'Planificación 2026-1'!F:F,"SUNAMPE",'Planificación 2026-1'!X:X,"VIRTUAL",'Planificación 2026-1'!I:I,">2") -> 0 | DV4: =SUMIFS('Planificación 2026-1'!R:R,'Planificación 2026-1'!W:W,C4,'Planificación 2026-1'!F:F,"SUNAMPE",'Planificación 2026-1'!X:X,"<>VIRTUAL",'Planificación 2026-1'!I:I,">2") -> 0 | DW4: =SUMIFS('Planificación 2026-1'!R:R,'Planificación 2026-1'!W:W,C4,'Planificación 2026-1'!F:F,"FILIAL",'Planificación 2026-1'!X:X,"VIRTUAL",'Planificación 2026-1'!I:I,">2") -> 0 | DX4: =SUMIFS('Planificación 2026-1'!R:R,'Planificación 2026-1'!W:W,C4,'Planificación 2026-1'!F:F,"FILIAL",'Planificación 2026-1'!X:X,"<>VIRTUAL",'Planificación 2026-1'!I:I,">2") -> 0 | DY4: =SUMIFS('Planificación 2026-1'!R:R,'Planificación 2026-1'!W:W,C4,'Planificación 2026-1'!F:F,"PORUMA",'Planificación 2026-1'!X:X,"VIRTUAL",'Planificación 2026-1'!I:I,">2") -> 0 | DZ4: =SUMIFS('Planificación 2026-1'!R:R,'Planificación 2026-1'!W:W,C4,'Planificación 2026-1'!F:F,"PORUMA",'Planificación 2026-1'!X:X,"<>VIRTUAL",'Planificación 2026-1'!I:I,">2") -> 0 | EA4: =SUMIFS('Planificación 2026-1'!R:R,'Planificación 2026-1'!W:W,C4,'Planificación 2026-1'!F:F,"HUAURA",'Planificación 2026-1'!X:X,"VIRTUAL",'Planificación 2026-1'!I:I,">2") -> 0 | EB4: =SUMIFS('Planificación 2026-1'!R:R,'Planificación 2026-1'!W:W,C4,'Planificación 2026-1'!F:F,"HUAURA",'Planificación 2026-1'!X:X,"<>VIRTUAL",'Planificación 2026-1'!I:I,">2") -> 0 | EC4: =SUMIFS('Planificación 2026-1'!R:R,'Planificación 2026-1'!W:W,C4,'Planificación 2026-1'!F:F,"PRINCIPAL",'Planificación 2026-1'!X:X,"VIRTUAL",'Planificación 2026-1'!I:I,"<3") -> 0 | ED4: =SUMIFS('Planificación 2026-1'!R:R,'Planificación 2026-1'!W:W,C4,'Planificación 2026-1'!F:F,"PRINCIPAL",'Planificación 2026-1'!X:X,"<>VIRTUAL",'Planificación 2026-1'!I:I,"<3") -> 0 | EE4: =SUMIFS('Planificación 2026-1'!R:R,'Planificación 2026-1'!W:W,C4,'Planificación 2026-1'!F:F,"SUNAMPE",'Planificación 2026-1'!X:X,"VIRTUAL",'Planificación 2026-1'!I:I,"<3") -> 0 | EF4: =SUMIFS('Planificación 2026-1'!R:R,'Planificación 2026-1'!W:W,C4,'Planificación 2026-1'!F:F,"SUNAMPE",'Planificación 2026-1'!X:X,"<>VIRTUAL",'Planificación 2026-1'!I:I,"<3") -> 0 | EG4: =SUMIFS('Planificación 2026-1'!R:R,'Planificación 2026-1'!W:W,C4,'Planificación 2026-1'!F:F,"FILIAL",'Planificación 2026-1'!X:X,"VIRTUAL",'Planificación 2026-1'!I:I,"<3") -> 0 | EH4: =SUMIFS('Planificación 2026-1'!R:R,'Planificación 2026-1'!W:W,C4,'Planificación 2026-1'!F:F,"FILIAL",'Planificación 2026-1'!X:X,"<>VIRTUAL",'Planificación 2026-1'!I:I,"<3") -> 0 | EI4: =SUMIFS('Planificación 2026-1'!R:R,'Planificación 2026-1'!W:W,C4,'Planificación 2026-1'!F:F,"PORUMA",'Planificación 2026-1'!X:X,"VIRTUAL",'Planificación 2026-1'!I:I,"<3") -> 0 | EJ4: =SUMIFS('Planificación 2026-1'!R:R,'Planificación 2026-1'!W:W,C4,'Planificación 2026-1'!F:F,"PORUMA",'Planificación 2026-1'!X:X,"<>VIRTUAL",'Planificación 2026-1'!I:I,"<3") -> 0 | EK4: =SUMIFS('Planificación 2026-1'!R:R,'Planificación 2026-1'!W:W,C4,'Planificación 2026-1'!F:F,"HUAURA",'Planificación 2026-1'!X:X,"VIRTUAL",'Planificación 2026-1'!I:I,"<3") -> 0 | EL4: =SUMIFS('Planificación 2026-1'!R:R,'Planificación 2026-1'!W:W,C4,'Planificación 2026-1'!F:F,"HUAURA",'Planificación 2026-1'!X:X,"<>VIRTUAL",'Planificación 2026-1'!I:I,"<3") -> 0 | EN4: =DS4+DW4+EA4+EC4+EG4+EK4+DU4+EE4 -> 0 | EO4: =DT4+DX4+EB4+ED4+EH4+EL4+DV4+EF4 -> 0 | EP4: =EXACT(SUM(EN4:EO4),D4) -> TRUE | EQ4: =IF(AND(DT4=0,DX4=0,EB4=0),"",IF(COUNTIF(DT4:EB4,">0")=1,IF(DT4>0,"SEDE",IF(DX4>0,"FILIAL","HUAURA")),IF(COUNTIF(DT4:EB4,">0")=2,IF(AND(DT4>0,DX4>0),"SEDE-FILIAL",IF(AND(DT4>0,EB4>0),"SEDE-HUAURA","FILIAL-HUAURA")),"SEDE-FILIAL-HUAURA"))) | ER4: =IF(EN4=0,"PRESENCIAL",IF(EO4=0,"VIRTUAL",IF(EN4>EO4,"MAS VIRTUAL",IF(EO4>EN4,"MAS PRESENCIAL","AMBOS")))) -> PRESENCIAL
B5: 2 | C5: ACHARTE CHAMPI WALTER JESUS | D5: =SUMIF('Planificación 2026-1'!W:W,C5,'Planificación 2026-1'!R:R) -> 0 | E5: TC | F5: RENOVACIÓN | G5: SEDE | H5: ENFERMERÍA | I5: =IF(SUM(COUNTIFS('Planificación 2026-1'!F:F,"PRINCIPAL",'Planificación 2026-1'!W:W,C5,'Planificación 2026-1'!H:H,"AF"))>0,"P01"," ") | J5: =IF(SUM(COUNTIFS('Planificación 2026-1'!F:F,"PRINCIPAL",'Planificación 2026-1'!W:W,C5,'Planificación 2026-1'!H:H,"EN"))>0,"P02"," ") | K5: =IF(SUM(COUNTIFS('Planificación 2026-1'!F:F,"PRINCIPAL",'Planificación 2026-1'!W:W,C5,'Planificación 2026-1'!H:H,"IS"))>0,"P03"," ") | L5: =IF(SUM(COUNTIFS('Planificación 2026-1'!F:F,"PRINCIPAL",'Planificación 2026-1'!W:W,C5,'Planificación 2026-1'!H:H,"PS"))>0,"P04"," ") | N5: =IF(SUM(COUNTIFS('Planificación 2026-1'!F:F,"PRINCIPAL",'Planificación 2026-1'!W:W,C5,'Planificación 2026-1'!H:H,"IN"))>0,"P06"," ") | O5: =IF(SUM(COUNTIFS('Planificación 2026-1'!F:F,"PRINCIPAL",'Planificación 2026-1'!W:W,C5,'Planificación 2026-1'!H:H,"CA"))>0,"P07"," ") | P5: =IF(SUM(COUNTIFS('Planificación 2026-1'!F:F,"PRINCIPAL",'Planificación 2026-1'!W:W,C5,'Planificación 2026-1'!H:H,"DE"))>0,"P08"," ") | Q5: =IF(SUM(COUNTIFS('Planificación 2026-1'!F:F,"PRINCIPAL",'Planificación 2026-1'!W:W,C5,'Planificación 2026-1'!H:H,"OB"))>0,"P09"," ") | R5: =IF(SUM(COUNTIFS('Planificación 2026-1'!F:F,"PRINCIPAL",'Planificación 2026-1'!W:W,C5,'Planificación 2026-1'!H:H,"MH"))>0,"P31"," ") | S5: =IF(SUM(COUNTIFS('Planificación 2026-1'!F:F,"PRINCIPAL",'Planificación 2026-1'!W:W,C5,'Planificación 2026-1'!H:H,"IC"))>0,"P32"," ") | T5: =IF(SUM(COUNTIFS('Planificación 2026-1'!F:F,"PRINCIPAL",'Planificación 2026-1'!W:W,C5,'Planificación 2026-1'!H:H,"AR"))>0,"P34"," ") | U5: =IF(SUM(COUNTIFS('Planificación 2026-1'!F:F,"PRINCIPAL",'Planificación 2026-1'!W:W,C5,'Planificación 2026-1'!H:H,"T1"))>0,"P35"," ") | V5: =IF(SUM(COUNTIFS('Planificación 2026-1'!F:F,"PRINCIPAL",'Planificación 2026-1'!W:W,C5,'Planificación 2026-1'!H:H,"T3"))>0,"P36"," ") | W5: =IF(SUM(COUNTIFS('Planificación 2026-1'!F:F,"PRINCIPAL",'Planificación 2026-1'!W:W,C5,'Planificación 2026-1'!H:H,"T2"))>0,"P37"," ") | X5: =IF(SUM(COUNTIFS('Planificación 2026-1'!F:F,"PRINCIPAL",'Planificación 2026-1'!W:W,C5,'Planificación 2026-1'!H:H,"AE"))>0,"P38"," ") | Y5: =IF(SUM(COUNTIFS('Planificación 2026-1'!F:F,"PRINCIPAL",'Planificación 2026-1'!W:W,C5,'Planificación 2026-1'!H:H,"T4"))>0,"P55"," ") | Z5: =IF(SUM(COUNTIFS('Planificación 2026-1'!F:F,"FILIAL",'Planificación 2026-1'!W:W,C5,'Planificación 2026-1'!H:H,"AF"))>0," P01"," ") | AA5: =IF(SUM(COUNTIFS('Planificación 2026-1'!F:F,"FILIAL",'Planificación 2026-1'!W:W,C5,'Planificación 2026-1'!H:H,"EN"))>0,"P02"," ") | AB5: =IF(SUM(COUNTIFS('Planificación 2026-1'!F:F,"FILIAL",'Planificación 2026-1'!W:W,C5,'Planificación 2026-1'!H:H,"IS"))>0,"P03"," ") | AC5: =IF(SUM(COUNTIFS('Planificación 2026-1'!F:F,"FILIAL",'Planificación 2026-1'!W:W,C5,'Planificación 2026-1'!H:H,"PS"))>0,"P04"," ") | AE5: =IF(SUM(COUNTIFS('Planificación 2026-1'!F:F,"FILIAL",'Planificación 2026-1'!W:W,C5,'Planificación 2026-1'!H:H,"IN"))>0,"P06"," ") | AF5: =IF(SUM(COUNTIFS('Planificación 2026-1'!F:F,"FILIAL",'Planificación 2026-1'!W:W,C5,'Planificación 2026-1'!H:H,"CA"))>0,"P07"," ") | AG5: =IF(SUM(COUNTIFS('Planificación 2026-1'!F:F,"FILIAL",'Planificación 2026-1'!W:W,C5,'Planificación 2026-1'!H:H,"DE"))>0,"P08"," ") | AH5: =IF(SUM(COUNTIFS('Planificación 2026-1'!F:F,"FILIAL",'Planificación 2026-1'!W:W,C5,'Planificación 2026-1'!H:H,"OB"))>0,"P09"," ") | AI5: =IF(SUM(COUNTIFS('Planificación 2026-1'!F:F,"FILIAL",'Planificación 2026-1'!W:W,C5,'Planificación 2026-1'!H:H,"MH"))>0,"P31"," ") | AJ5: =IF(SUM(COUNTIFS('Planificación 2026-1'!F:F,"FILIAL",'Planificación 2026-1'!W:W,C5,'Planificación 2026-1'!H:H,"IC"))>0,"P32"," ") | AK5: =IF(SUM(COUNTIFS('Planificación 2026-1'!F:F,"FILIAL",'Planificación 2026-1'!W:W,C5,'Planificación 2026-1'!H:H,"AR"))>0,"P34"," ") | AL5: =IF(SUM(COUNTIFS('Planificación 2026-1'!F:F,"FILIAL",'Planificación 2026-1'!W:W,C5,'Planificación 2026-1'!H:H,"T1"))>0,"P35"," ") | AM5: =IF(SUM(COUNTIFS('Planificación 2026-1'!F:F,"FILIAL",'Planificación 2026-1'!W:W,C5,'Planificación 2026-1'!H:H,"T3"))>0,"P36"," ") | AN5: =IF(SUM(COUNTIFS('Planificación 2026-1'!F:F,"FILIAL",'Planificación 2026-1'!W:W,C5,'Planificación 2026-1'!H:H,"T2"))>0,"P37"," ") | AO5: =IF(SUM(COUNTIFS('Planificación 2026-1'!F:F,"FILIAL",'Planificación 2026-1'!W:W,C5,'Planificación 2026-1'!H:H,"AE"))>0,"P38"," ") | AP5: =IF(SUM(COUNTIFS('Planificación 2026-1'!F:F,"FILIAL",'Planificación 2026-1'!W:W,C5,'Planificación 2026-1'!H:H,"T4"))>0,"P55"," ") | AQ5: =IF(SUM(COUNTIFS('Planificación 2026-1'!F:F,"SUNAMPE",'Planificación 2026-1'!W:W,C5,'Planificación 2026-1'!H:H,"AF"))>0," P01"," ") | AR5: =IF(SUM(COUNTIFS('Planificación 2026-1'!F:F,"SUNAMPE",'Planificación 2026-1'!W:W,C5,'Planificación 2026-1'!H:H,"EN"))>0,"P02"," ") | AS5: =IF(SUM(COUNTIFS('Planificación 2026-1'!F:F,"SUNAMPE",'Planificación 2026-1'!W:W,C5,'Planificación 2026-1'!H:H,"IS"))>0,"P03"," ") | AT5: =IF(SUM(COUNTIFS('Planificación 2026-1'!F:F,"SUNAMPE",'Planificación 2026-1'!W:W,C5,'Planificación 2026-1'!H:H,"PS"))>0,"P04"," ") | AV5: =IF(SUM(COUNTIFS('Planificación 2026-1'!F:F,"SUNAMPE",'Planificación 2026-1'!W:W,C5,'Planificación 2026-1'!H:H,"IN"))>0,"P06"," ") | AW5: =IF(SUM(COUNTIFS('Planificación 2026-1'!F:F,"SUNAMPE",'Planificación 2026-1'!W:W,C5,'Planificación 2026-1'!H:H,"CA"))>0,"P07"," ") | AX5: =IF(SUM(COUNTIFS('Planificación 2026-1'!F:F,"SUNAMPE",'Planificación 2026-1'!W:W,C5,'Planificación 2026-1'!H:H,"DE"))>0,"P08"," ") | AY5: =IF(SUM(COUNTIFS('Planificación 2026-1'!F:F,"SUNAMPE",'Planificación 2026-1'!W:W,C5,'Planificación 2026-1'!H:H,"OB"))>0,"P09"," ") | AZ5: =IF(SUM(COUNTIFS('Planificación 2026-1'!F:F,"SUNAMPE",'Planificación 2026-1'!W:W,C5,'Planificación 2026-1'!H:H,"MH"))>0,"P31"," ") | BA5: =IF(SUM(COUNTIFS('Planificación 2026-1'!F:F,"SUNAMPE",'Planificación 2026-1'!W:W,C5,'Planificación 2026-1'!H:H,"IC"))>0,"P32"," ") | BB5: =IF(SUM(COUNTIFS('Planificación 2026-1'!F:F,"SUNAMPE",'Planificación 2026-1'!W:W,C5,'Planificación 2026-1'!H:H,"AR"))>0,"P34"," ") | BC5: =IF(SUM(COUNTIFS('Planificación 2026-1'!F:F,"SUNAMPE",'Planificación 2026-1'!W:W,C5,'Planificación 2026-1'!H:H,"T1"))>0,"P35"," ") | BD5: =IF(SUM(COUNTIFS('Planificación 2026-1'!F:F,"SUNAMPE",'Planificación 2026-1'!W:W,C5,'Planificación 2026-1'!H:H,"T3"))>0,"P36"," ") | BE5: =IF(SUM(COUNTIFS('Planificación 2026-1'!F:F,"SUNAMPE",'Planificación 2026-1'!W:W,C5,'Planificación 2026-1'!H:H,"T2"))>0,"P37"," ") | BF5: =IF(SUM(COUNTIFS('Planificación 2026-1'!F:F,"SUNAMPE",'Planificación 2026-1'!W:W,C5,'Planificación 2026-1'!H:H,"AE"))>0,"P38"," ") | BG5: =IF(SUM(COUNTIFS('Planificación 2026-1'!F:F,"SUNAMPE",'Planificación 2026-1'!W:W,C5,'Planificación 2026-1'!H:H,"T4"))>0,"P55"," ") | BH5: =IF(SUM(COUNTIFS('Planificación 2026-1'!F:F,"HUAURA",'Planificación 2026-1'!W:W,C5,'Planificación 2026-1'!H:H,"AF"))>0," P01"," ") | BI5: =IF(SUM(COUNTIFS('Planificación 2026-1'!F:F,"HUAURA",'Planificación 2026-1'!W:W,C5,'Planificación 2026-1'!H:H,"EN"))>0,"P02"," ") | BJ5: =IF(SUM(COUNTIFS('Planificación 2026-1'!F:F,"HUAURA",'Planificación 2026-1'!W:W,C5,'Planificación 2026-1'!H:H,"IS"))>0,"P03"," ") | BK5: =IF(SUM(COUNTIFS('Planificación 2026-1'!F:F,"HUAURA",'Planificación 2026-1'!W:W,C5,'Planificación 2026-1'!H:H,"PS"))>0,"P04"," ") | BM5: =IF(SUM(COUNTIFS('Planificación 2026-1'!F:F,"HUAURA",'Planificación 2026-1'!W:W,C5,'Planificación 2026-1'!H:H,"IN"))>0,"P06"," ") | BN5: =IF(SUM(COUNTIFS('Planificación 2026-1'!F:F,"HUAURA",'Planificación 2026-1'!W:W,C5,'Planificación 2026-1'!H:H,"CA"))>0,"P07"," ") | BO5: =IF(SUM(COUNTIFS('Planificación 2026-1'!F:F,"HUAURA",'Planificación 2026-1'!W:W,C5,'Planificación 2026-1'!H:H,"DE"))>0,"P08"," ") | BP5: =IF(SUM(COUNTIFS('Planificación 2026-1'!F:F,"HUAURA",'Planificación 2026-1'!W:W,C5,'Planificación 2026-1'!H:H,"OB"))>0,"P09"," ") | BQ5: =IF(SUM(COUNTIFS('Planificación 2026-1'!F:F,"HUAURA",'Planificación 2026-1'!W:W,C5,'Planificación 2026-1'!H:H,"MH"))>0,"P31"," ") | BR5: =IF(SUM(COUNTIFS('Planificación 2026-1'!F:F,"HUAURA",'Planificación 2026-1'!W:W,C5,'Planificación 2026-1'!H:H,"IC"))>0,"P32"," ") | BS5: =IF(SUM(COUNTIFS('Planificación 2026-1'!F:F,"HUAURA",'Planificación 2026-1'!W:W,C5,'Planificación 2026-1'!H:H,"AR"))>0,"P34"," ") | BT5: =IF(SUM(COUNTIFS('Planificación 2026-1'!F:F,"HUAURA",'Planificación 2026-1'!W:W,C5,'Planificación 2026-1'!H:H,"T1"))>0,"P35"," ") | BU5: =IF(SUM(COUNTIFS('Planificación 2026-1'!F:F,"HUAURA",'Planificación 2026-1'!W:W,C5,'Planificación 2026-1'!H:H,"T3"))>0,"P36"," ") | BV5: =IF(SUM(COUNTIFS('Planificación 2026-1'!F:F,"HUAURA",'Planificación 2026-1'!W:W,C5,'Planificación 2026-1'!H:H,"T2"))>0,"P37"," ") | BW5: =IF(SUM(COUNTIFS('Planificación 2026-1'!F:F,"HUAURA",'Planificación 2026-1'!W:W,C5,'Planificación 2026-1'!H:H,"AE"))>0,"P38"," ") | BX5: =IF(SUM(COUNTIFS('Planificación 2026-1'!F:F,"HUAURA",'Planificación 2026-1'!W:W,C5,'Planificación 2026-1'!H:H,"T4"))>0,"P55"," ") | BY5: =SUMIFS('Planificación 2026-1'!R:R,'Planificación 2026-1'!W:W,C5,'Planificación 2026-1'!H:H,"AF",'Planificación 2026-1'!I:I,">2") -> 0 | BZ5: =SUMIFS('Planificación 2026-1'!R:R,'Planificación 2026-1'!W:W,C5,'Planificación 2026-1'!H:H,"EN",'Planificación 2026-1'!I:I,">2") -> 0 | CA5: =SUMIFS('Planificación 2026-1'!R:R,'Planificación 2026-1'!W:W,C5,'Planificación 2026-1'!H:H,"IS",'Planificación 2026-1'!I:I,">2") -> 0 | CB5: =SUMIFS('Planificación 2026-1'!R:R,'Planificación 2026-1'!W:W,C5,'Planificación 2026-1'!H:H,"PS",'Planificación 2026-1'!I:I,">2") -> 0 | CC5: =SUMIFS('Planificación 2026-1'!R:R,'Planificación 2026-1'!W:W,C5,'Planificación 2026-1'!H:H,"IN",'Planificación 2026-1'!I:I,">2") -> 0 | CD5: =SUMIFS('Planificación 2026-1'!R:R,'Planificación 2026-1'!W:W,C5,'Planificación 2026-1'!H:H,"CA",'Planificación 2026-1'!I:I,">2") -> 0 | CE5: =SUMIFS('Planificación 2026-1'!R:R,'Planificación 2026-1'!W:W,C5,'Planificación 2026-1'!H:H,"DE",'Planificación 2026-1'!I:I,">2") -> 0 | CF5: =SUMIFS('Planificación 2026-1'!R:R,'Planificación 2026-1'!W:W,C5,'Planificación 2026-1'!H:H,"OB",'Planificación 2026-1'!I:I,">2") -> 0 | CG5: =SUMIFS('Planificación 2026-1'!R:R,'Planificación 2026-1'!W:W,C5,'Planificación 2026-1'!H:H,"MH",'Planificación 2026-1'!I:I,">2") -> 0 | CH5: =SUMIFS('Planificación 2026-1'!R:R,'Planificación 2026-1'!W:W,C5,'Planificación 2026-1'!H:H,"IC",'Planificación 2026-1'!I:I,">2") -> 0 | CI5: =SUMIFS('Planificación 2026-1'!R:R,'Planificación 2026-1'!W:W,C5,'Planificación 2026-1'!H:H,"AR",'Planificación 2026-1'!I:I,">2") -> 0 | CJ5: =SUMIFS('Planificación 2026-1'!R:R,'Planificación 2026-1'!W:W,C5,'Planificación 2026-1'!H:H,"T1",'Planificación 2026-1'!I:I,">2") -> 0 | CK5: =SUMIFS('Planificación 2026-1'!R:R,'Planificación 2026-1'!W:W,C5,'Planificación 2026-1'!H:H,"T3",'Planificación 2026-1'!I:I,">2") -> 0 | CL5: =SUMIFS('Planificación 2026-1'!R:R,'Planificación 2026-1'!W:W,C5,'Planificación 2026-1'!H:H,"T2",'Planificación 2026-1'!I:I,">2") -> 0 | CM5: =SUMIFS('Planificación 2026-1'!R:R,'Planificación 2026-1'!W:W,C5,'Planificación 2026-1'!H:H,"AE",'Planificación 2026-1'!I:I,">2") -> 0 | CN5: =SUMIFS('Planificación 2026-1'!R:R,'Planificación 2026-1'!W:W,C5,'Planificación 2026-1'!H:H,"T4",'Planificación 2026-1'!I:I,">2") -> 0 | CO5: =SUMIFS('Planificación 2026-1'!R:R,'Planificación 2026-1'!W:W,C5,'Planificación 2026-1'!H:H,"AF",'Planificación 2026-1'!I:I,"<3") -> 0 | CP5: =SUMIFS('Planificación 2026-1'!R:R,'Planificación 2026-1'!W:W,C5,'Planificación 2026-1'!H:H,"EN",'Planificación 2026-1'!I:I,"<3") -> 0 | CQ5: =SUMIFS('Planificación 2026-1'!R:R,'Planificación 2026-1'!W:W,C5,'Planificación 2026-1'!H:H,"IS",'Planificación 2026-1'!I:I,"<3") -> 0 | CR5: =SUMIFS('Planificación 2026-1'!R:R,'Planificación 2026-1'!W:W,C5,'Planificación 2026-1'!H:H,"PS",'Planificación 2026-1'!I:I,"<3") -> 0 | CS5: =SUMIFS('Planificación 2026-1'!R:R,'Planificación 2026-1'!W:W,C5,'Planificación 2026-1'!H:H,"IN",'Planificación 2026-1'!I:I,"<3") -> 0 | CT5: =SUMIFS('Planificación 2026-1'!R:R,'Planificación 2026-1'!W:W,C5,'Planificación 2026-1'!H:H,"CA",'Planificación 2026-1'!I:I,"<3") -> 0 | CU5: =SUMIFS('Planificación 2026-1'!R:R,'Planificación 2026-1'!W:W,C5,'Planificación 2026-1'!H:H,"DE",'Planificación 2026-1'!I:I,"<3") -> 0 | CV5: =SUMIFS('Planificación 2026-1'!R:R,'Planificación 2026-1'!W:W,C5,'Planificación 2026-1'!H:H,"OB",'Planificación 2026-1'!I:I,"<3") -> 0 | CW5: =SUMIFS('Planificación 2026-1'!R:R,'Planificación 2026-1'!W:W,C5,'Planificación 2026-1'!H:H,"MH",'Planificación 2026-1'!I:I,"<3") -> 0 | CX5: =SUMIFS('Planificación 2026-1'!R:R,'Planificación 2026-1'!W:W,C5,'Planificación 2026-1'!H:H,"IC",'Planificación 2026-1'!I:I,"<3") -> 0 | CY5: =SUMIFS('Planificación 2026-1'!R:R,'Planificación 2026-1'!W:W,C5,'Planificación 2026-1'!H:H,"AR",'Planificación 2026-1'!I:I,"<3") -> 0 | CZ5: =SUMIFS('Planificación 2026-1'!R:R,'Planificación 2026-1'!W:W,C5,'Planificación 2026-1'!H:H,"T1",'Planificación 2026-1'!I:I,"<3") -> 0 | DA5: =SUMIFS('Planificación 2026-1'!R:R,'Planificación 2026-1'!W:W,C5,'Planificación 2026-1'!H:H,"T3",'Planificación 2026-1'!I:I,"<3") -> 0 | DB5: =SUMIFS('Planificación 2026-1'!R:R,'Planificación 2026-1'!W:W,C5,'Planificación 2026-1'!H:H,"T2",'Planificación 2026-1'!I:I,"<3") -> 0 | DC5: =SUMIFS('Planificación 2026-1'!R:R,'Planificación 2026-1'!W:W,C5,'Planificación 2026-1'!H:H,"AE",'Planificación 2026-1'!I:I,"<3") -> 0 | DD5: =SUMIFS('Planificación 2026-1'!R:R,'Planificación 2026-1'!W:W,C5,'Planificación 2026-1'!H:H,"T4",'Planificación 2026-1'!I:I,"<3") -> 0 | DE5: =TRIM(CONCATENATE(I5,J5,K5,L5,M5,N5,O5,P5,Q5,R5,S5,T5,U5,V5,W5,X5,Y5)) | DF5: =IF(C5="","",SUMIFS('Planificación 2026-1'!R:R,'Planificación 2026-1'!W:W,C5,'Planificación 2026-1'!F:F,"PRINCIPAL",'Planificación 2026-1'!X:X,"VIRTUAL")) -> 0 | DG5: =IF(C5="","",SUMIFS('Planificación 2026-1'!R:R,'Planificación 2026-1'!W:W,C5,'Planificación 2026-1'!F:F,"PRINCIPAL",'Planificación 2026-1'!X:X,"PRESENCIAL")) -> 0 | DH5: =IF(C5="","",SUMIFS('Planificación 2026-1'!R:R,'Planificación 2026-1'!W:W,C5,'Planificación 2026-1'!F:F,"PRINCIPAL",'Planificación 2026-1'!X:X,"HIBRIDO PRESENCIAL")) -> 0 | DI5: =TRIM(CONCATENATE(Z5,AA5,AB5,AC5,AD5,AE5,AF5,AG5,AH5,AI5,AJ5,AK5,AL5,AM5,AN5,AO5,AP5)) | DJ5: =IF(C5="","",SUMIFS('Planificación 2026-1'!R:R,'Planificación 2026-1'!W:W,C5,'Planificación 2026-1'!F:F,"FILIAL",'Planificación 2026-1'!X:X,"VIRTUAL")) -> 0 | DK5: =IF(C5="","",SUMIFS('Planificación 2026-1'!R:R,'Planificación 2026-1'!W:W,C5,'Planificación 2026-1'!F:F,"FILIAL",'Planificación 2026-1'!X:X,"PRESENCIAL")) -> 0 | DL5: =IF(C5="","",SUMIFS('Planificación 2026-1'!R:R,'Planificación 2026-1'!W:W,C5,'Planificación 2026-1'!F:F,"FILIAL",'Planificación 2026-1'!X:X,"HIBRIDO PRESENCIAL")) -> 0 | DM5: =TRIM(CONCATENATE(AQ5,AR5,AS5,AT5,AU5,AV5,AW5,AX5,AY5,AZ5,BA5,BB5,BC5,BD5,BE5,BF5,BG5)) | DN5: =IF(C5="","",SUMIFS('Planificación 2026-1'!R:R,'Planificación 2026-1'!W:W,C5,'Planificación 2026-1'!F:F,"SUNAMPE",'Planificación 2026-1'!X:X,"VIRTUAL")) -> 0 | DO5: =IF(C5="","",SUMIFS('Planificación 2026-1'!R:R,'Planificación 2026-1'!W:W,C5,'Planificación 2026-1'!F:F,"SUNAMPE",'Planificación 2026-1'!X:X,"PRESENCIAL")) -> 0 | DP5: =TRIM(CONCATENATE(BH5,BI5,BJ5,BK5,BL5,BM5,BN5,BO5,BP5,BQ5,BR5,BS5,BT5,BU5,BV5,BW5,BX5)) | DQ5: =IF(C5="","",SUMIFS('Planificación 2026-1'!R:R,'Planificación 2026-1'!W:W,C5,'Planificación 2026-1'!F:F,"HUAURA",'Planificación 2026-1'!X:X,"VIRTUAL")) -> 0 | DR5: =IF(C5="","",SUMIFS('Planificación 2026-1'!R:R,'Planificación 2026-1'!W:W,C5,'Planificación 2026-1'!F:F,"HUAURA",'Planificación 2026-1'!X:X,"PRESENCIAL")) -> 0 | DS5: =SUMIFS('Planificación 2026-1'!R:R,'Planificación 2026-1'!W:W,C5,'Planificación 2026-1'!F:F,"PRINCIPAL",'Planificación 2026-1'!X:X,"VIRTUAL",'Planificación 2026-1'!I:I,">2") -> 0 | DT5: =SUMIFS('Planificación 2026-1'!R:R,'Planificación 2026-1'!W:W,C5,'Planificación 2026-1'!F:F,"PRINCIPAL",'Planificación 2026-1'!X:X,"<>VIRTUAL",'Planificación 2026-1'!I:I,">2") -> 0 | DU5: =SUMIFS('Planificación 2026-1'!R:R,'Planificación 2026-1'!W:W,C5,'Planificación 2026-1'!F:F,"SUNAMPE",'Planificación 2026-1'!X:X,"VIRTUAL",'Planificación 2026-1'!I:I,">2") -> 0 | DV5: =SUMIFS('Planificación 2026-1'!R:R,'Planificación 2026-1'!W:W,C5,'Planificación 2026-1'!F:F,"SUNAMPE",'Planificación 2026-1'!X:X,"<>VIRTUAL",'Planificación 2026-1'!I:I,">2") -> 0 | DW5: =SUMIFS('Planificación 2026-1'!R:R,'Planificación 2026-1'!W:W,C5,'Planificación 2026-1'!F:F,"FILIAL",'Planificación 2026-1'!X:X,"VIRTUAL",'Planificación 2026-1'!I:I,">2") -> 0 | DX5: =SUMIFS('Planificación 2026-1'!R:R,'Planificación 2026-1'!W:W,C5,'Planificación 2026-1'!F:F,"FILIAL",'Planificación 2026-1'!X:X,"<>VIRTUAL",'Planificación 2026-1'!I:I,">2") -> 0 | DY5: =SUMIFS('Planificación 2026-1'!R:R,'Planificación 2026-1'!W:W,C5,'Planificación 2026-1'!F:F,"PORUMA",'Planificación 2026-1'!X:X,"VIRTUAL",'Planificación 2026-1'!I:I,">2") -> 0 | DZ5: =SUMIFS('Planificación 2026-1'!R:R,'Planificación 2026-1'!W:W,C5,'Planificación 2026-1'!F:F,"PORUMA",'Planificación 2026-1'!X:X,"<>VIRTUAL",'Planificación 2026-1'!I:I,">2") -> 0 | EA5: =SUMIFS('Planificación 2026-1'!R:R,'Planificación 2026-1'!W:W,C5,'Planificación 2026-1'!F:F,"HUAURA",'Planificación 2026-1'!X:X,"VIRTUAL",'Planificación 2026-1'!I:I,">2") -> 0 | EB5: =SUMIFS('Planificación 2026-1'!R:R,'Planificación 2026-1'!W:W,C5,'Planificación 2026-1'!F:F,"HUAURA",'Planificación 2026-1'!X:X,"<>VIRTUAL",'Planificación 2026-1'!I:I,">2") -> 0 | EC5: =SUMIFS('Planificación 2026-1'!R:R,'Planificación 2026-1'!W:W,C5,'Planificación 2026-1'!F:F,"PRINCIPAL",'Planificación 2026-1'!X:X,"VIRTUAL",'Planificación 2026-1'!I:I,"<3") -> 0 | ED5: =SUMIFS('Planificación 2026-1'!R:R,'Planificación 2026-1'!W:W,C5,'Planificación 2026-1'!F:F,"PRINCIPAL",'Planificación 2026-1'!X:X,"<>VIRTUAL",'Planificación 2026-1'!I:I,"<3") -> 0 | EE5: =SUMIFS('Planificación 2026-1'!R:R,'Planificación 2026-1'!W:W,C5,'Planificación 2026-1'!F:F,"SUNAMPE",'Planificación 2026-1'!X:X,"VIRTUAL",'Planificación 2026-1'!I:I,"<3") -> 0 | EF5: =SUMIFS('Planificación 2026-1'!R:R,'Planificación 2026-1'!W:W,C5,'Planificación 2026-1'!F:F,"SUNAMPE",'Planificación 2026-1'!X:X,"<>VIRTUAL",'Planificación 2026-1'!I:I,"<3") -> 0 | EG5: =SUMIFS('Planificación 2026-1'!R:R,'Planificación 2026-1'!W:W,C5,'Planificación 2026-1'!F:F,"FILIAL",'Planificación 2026-1'!X:X,"VIRTUAL",'Planificación 2026-1'!I:I,"<3") -> 0 | EH5: =SUMIFS('Planificación 2026-1'!R:R,'Planificación 2026-1'!W:W,C5,'Planificación 2026-1'!F:F,"FILIAL",'Planificación 2026-1'!X:X,"<>VIRTUAL",'Planificación 2026-1'!I:I,"<3") -> 0 | EI5: =SUMIFS('Planificación 2026-1'!R:R,'Planificación 2026-1'!W:W,C5,'Planificación 2026-1'!F:F,"PORUMA",'Planificación 2026-1'!X:X,"VIRTUAL",'Planificación 2026-1'!I:I,"<3") -> 0 | EJ5: =SUMIFS('Planificación 2026-1'!R:R,'Planificación 2026-1'!W:W,C5,'Planificación 2026-1'!F:F,"PORUMA",'Planificación 2026-1'!X:X,"<>VIRTUAL",'Planificación 2026-1'!I:I,"<3") -> 0 | EK5: =SUMIFS('Planificación 2026-1'!R:R,'Planificación 2026-1'!W:W,C5,'Planificación 2026-1'!F:F,"HUAURA",'Planificación 2026-1'!X:X,"VIRTUAL",'Planificación 2026-1'!I:I,"<3") -> 0 | EL5: =SUMIFS('Planificación 2026-1'!R:R,'Planificación 2026-1'!W:W,C5,'Planificación 2026-1'!F:F,"HUAURA",'Planificación 2026-1'!X:X,"<>VIRTUAL",'Planificación 2026-1'!I:I,"<3") -> 0 | EN5: =DS5+DW5+EA5+EC5+EG5+EK5+DU5+EE5 -> 0 | EO5: =DT5+DX5+EB5+ED5+EH5+EL5+DV5+EF5 -> 0 | EP5: =EXACT(SUM(EN5:EO5),D5) -> TRUE | EQ5: =IF(AND(DT5=0,DX5=0,EB5=0),"",IF(COUNTIF(DT5:EB5,">0")=1,IF(DT5>0,"SEDE",IF(DX5>0,"FILIAL","HUAURA")),IF(COUNTIF(DT5:EB5,">0")=2,IF(AND(DT5>0,DX5>0),"SEDE-FILIAL",IF(AND(DT5>0,EB5>0),"SEDE-HUAURA","FILIAL-HUAURA")),"SEDE-FILIAL-HUAURA"))) | ER5: =IF(EN5=0,"PRESENCIAL",IF(EO5=0,"VIRTUAL",IF(EN5>EO5,"MAS VIRTUAL",IF(EO5>EN5,"MAS PRESENCIAL","AMBOS")))) -> PRESENCIAL
