Workbook

Sheet Hoja2
G1: DOCENTES | H1: HORAS EEGG | I1: HORAS FCS | J1: HORAS TOTAL
E2: ACHARTE CHAMPI WALTER JESUS | G2: ACHARTE CHAMPI WALTER JESUS | H2: =SUMIFS('Planificación 2026-1'!$R:$R,'Planificación 2026-1'!$W:$W,G2,'Planificación 2026-1'!$H:$H,"<=2") -> 0 | I2: =SUMIFS('Planificación 2026-1'!$R:$R,'Planificación 2026-1'!$W:$W,G2,'Planificación 2026-1'!$H:$H,">=3") -> 40 | J2: =SUMIFS('Planificación 2026-1'!$R:$R,'Planificación 2026-1'!$W:$W,G2) -> 40
E3: ACOSTA VILLAVICENCIO BLANCA AURORA | G3: ACOSTA VILLAVICENCIO BLANCA AURORA | H3: =SUMIFS('Planificación 2026-1'!$R:$R,'Planificación 2026-1'!$W:$W,G3,'Planificación 2026-1'!$H:$H,"<=2") -> 40 | I3: =SUMIFS('Planificación 2026-1'!$R:$R,'Planificación 2026-1'!$W:$W,G3,'Planificación 2026-1'!$H:$H,">=3") -> 0 | J3: =SUMIFS('Planificación 2026-1'!$R:$R,'Planificación 2026-1'!$W:$W,G3) -> 40
E4: ALIAGA RUIZ MINA ANGELICA | G4: ALIAGA RUIZ MINA ANGELICA | H4: =SUMIFS('Planificación 2026-1'!$R:$R,'Planificación 2026-1'!$W:$W,G4,'Planificación 2026-1'!$H:$H,"<=2") -> 0 | I4: =SUMIFS('Planificación 2026-1'!$R:$R,'Planificación 2026-1'!$W:$W,G4,'Planificación 2026-1'!$H:$H,">=3") -> 13 | J4: =SUMIFS('Planificación 2026-1'!$R:$R,'Planificación 2026-1'!$W:$W,G4) -> 13
E5: ALMEYDA CARBAJAL JOSE ARMANDO | G5: ALVAREZ GARCIA TERESA ELVIRA | H5: =SUMIFS('Planificación 2026-1'!$R:$R,'Planificación 2026-1'!$W:$W,G5,'Planificación 2026-1'!$H:$H,"<=2") -> 4 | I5: =SUMIFS('Planificación 2026-1'!$R:$R,'Planificación 2026-1'!$W:$W,G5,'Planificación 2026-1'!$H:$H,">=3") -> 13 | J5: =SUMIFS('Planificación 2026-1'!$R:$R,'Planificación 2026-1'!$W:$W,G5) -> 17
E6: ANCAJIMA RUIZ ANDREA BETTY | G6: ANCAJIMA RUIZ ANDREA BETTY | H6: =SUMIFS('Planificación 2026-1'!$R:$R,'Planificación 2026-1'!$W:$W,G6,'Planificación 2026-1'!$H:$H,"<=2") -> 15 | I6: =SUMIFS('Planificación 2026-1'!$R:$R,'Planificación 2026-1'!$W:$W,G6,'Planificación 2026-1'!$H:$H,">=3") -> 0 | J6: =SUMIFS('Planificación 2026-1'!$R:$R,'Planificación 2026-1'!$W:$W,G6) -> 15
E7: ANICAMA BERNAOLA PEDRO ARTURO | G7: ANICAMA BERNAOLA PEDRO ARTURO | H7: =SUMIFS('Planificación 2026-1'!$R:$R,'Planificación 2026-1'!$W:$W,G7,'Planificación 2026-1'!$H:$H,"<=2") -> 0 | I7: =SUMIFS('Planificación 2026-1'!$R:$R,'Planificación 2026-1'!$W:$W,G7,'Planificación 2026-1'!$H:$H,">=3") -> 14 | J7: =SUMIFS('Planificación 2026-1'!$R:$R,'Planificación 2026-1'!$W:$W,G7) -> 14
E8: ANTEZANA CHINQUILLO JOSE GIANCARLO | G8: ANTEZANA CHINQUILLO JOSE GIANCARLO | H8: =SUMIFS('Planificación 2026-1'!$R:$R,'Planificación 2026-1'!$W:$W,G8,'Planificación 2026-1'!$H:$H,"<=2") -> 8 | I8: =SUMIFS('Planificación 2026-1'!$R:$R,'Planificación 2026-1'!$W:$W,G8,'Planificación 2026-1'!$H:$H,">=3") -> 28 | J8: =SUMIFS('Planificación 2026-1'!$R:$R,'Planificación 2026-1'!$W:$W,G8) -> 36
E9: ANYOSA ORE MASSIEL | G9: APOLAYA PAREJA BERTHA ESTHER | H9: =SUMIFS('Planificación 2026-1'!$R:$R,'Planificación 2026-1'!$W:$W,G9,'Planificación 2026-1'!$H:$H,"<=2") -> 0 | I9: =SUMIFS('Planificación 2026-1'!$R:$R,'Planificación 2026-1'!$W:$W,G9,'Planificación 2026-1'!$H:$H,">=3") -> 24 | J9: =SUMIFS('Planificación 2026-1'!$R:$R,'Planificación 2026-1'!$W:$W,G9) -> 24
E10: APOLAYA PAREJA BERTHA ESTHER | G10: AQUIJE DAPOZZO EDWAR VIDAL | H10: =SUMIFS('Planificación 2026-1'!$R:$R,'Planificación 2026-1'!$W:$W,G10,'Planificación 2026-1'!$H:$H,"<=2") -> 0 | I10: =SUMIFS('Planificación 2026-1'!$R:$R,'Planificación 2026-1'!$W:$W,G10,'Planificación 2026-1'!$H:$H,">=3") -> 18 | J10: =SUMIFS('Planificación 2026-1'!$R:$R,'Planificación 2026-1'!$W:$W,G10) -> 18
E11: AQUIJE DAPOZZO EDWAR VIDAL | G11: ARIZOLA AGUADO ALICIA ANTOINETTE | H11: =SUMIFS('Planificación 2026-1'!$R:$R,'Planificación 2026-1'!$W:$W,G11,'Planificación 2026-1'!$H:$H,"<=2") -> 0 | I11: =SUMIFS('Planificación 2026-1'!$R:$R,'Planificación 2026-1'!$W:$W,G11,'Planificación 2026-1'!$H:$H,">=3") -> 15 | J11: =SUMIFS('Planificación 2026-1'!$R:$R,'Planificación 2026-1'!$W:$W,G11) -> 15
E12: ALVAREZ GARCIA TERESA | G12: AROTUMA GRANDA HECTOR JUAN CARLOS | H12: =SUMIFS('Planificación 2026-1'!$R:$R,'Planificación 2026-1'!$W:$W,G12,'Planificación 2026-1'!$H:$H,"<=2") -> 0 | I12: =SUMIFS('Planificación 2026-1'!$R:$R,'Planificación 2026-1'!$W:$W,G12,'Planificación 2026-1'!$H:$H,">=3") -> 10 | J12: =SUMIFS('Planificación 2026-1'!$R:$R,'Planificación 2026-1'!$W:$W,G12) -> 10
E13: ALVAREZ GARCIA TERESA ELVIRA | G13: ARQUIÑEGO SOLAR HENRRY MARCOS | H13: =SUMIFS('Planificación 2026-1'!$R:$R,'Planificación 2026-1'!$W:$W,G13,'Planificación 2026-1'!$H:$H,"<=2") -> 0 | I13: =SUMIFS('Planificación 2026-1'!$R:$R,'Planificación 2026-1'!$W:$W,G13,'Planificación 2026-1'!$H:$H,">=3") -> 30 | J13: =SUMIFS('Planificación 2026-1'!$R:$R,'Planificación 2026-1'!$W:$W,G13) -> 30
E14: ARIZOLA AGUADO ALICIA ANTOINETTE | G14: ARREDONDO ZELA SONIA OLIVIA | H14: =SUMIFS('Planificación 2026-1'!$R:$R,'Planificación 2026-1'!$W:$W,G14,'Planificación 2026-1'!$H:$H,"<=2") -> 38 | I14: =SUMIFS('Planificación 2026-1'!$R:$R,'Planificación 2026-1'!$W:$W,G14,'Planificación 2026-1'!$H:$H,">=3") -> 0 | J14: =SUMIFS('Planificación 2026-1'!$R:$R,'Planificación 2026-1'!$W:$W,G14) -> 38 | K14: si
E15: AROTUMA GRANDA HECTOR JUAN CARLOS | G15: ARROYO PACHAS JOSE LUIS | H15: =SUMIFS('Planificación 2026-1'!$R:$R,'Planificación 2026-1'!$W:$W,G15,'Planificación 2026-1'!$H:$H,"<=2") -> 0 | I15: =SUMIFS('Planificación 2026-1'!$R:$R,'Planificación 2026-1'!$W:$W,G15,'Planificación 2026-1'!$H:$H,">=3") -> 32 | J15: =SUMIFS('Planificación 2026-1'!$R:$R,'Planificación 2026-1'!$W:$W,G15) -> 32
E16: ARQUIÑEGO SOLAR HENRRY MARCOS | G16: ATME ROJAS DAVEY RAUL | H16: =SUMIFS('Planificación 2026-1'!$R:$R,'Planificación 2026-1'!$W:$W,G16,'Planificación 2026-1'!$H:$H,"<=2") -> 0 | I16: =SUMIFS('Planificación 2026-1'!$R:$R,'Planificación 2026-1'!$W:$W,G16,'Planificación 2026-1'!$H:$H,">=3") -> 25 | J16: =SUMIFS('Planificación 2026-1'!$R:$R,'Planificación 2026-1'!$W:$W,G16) -> 25
E17: ARROYO PACHAS JOSE LUIS | G17: ATUNCAR SUENG DORA ROSARIO | H17: =SUMIFS('Planificación 2026-1'!$R:$R,'Planificación 2026-1'!$W:$W,G17,'Planificación 2026-1'!$H:$H,"<=2") -> 0 | I17: =SUMIFS('Planificación 2026-1'!$R:$R,'Planificación 2026-1'!$W:$W,G17,'Planificación 2026-1'!$H:$H,">=3") -> 14 | J17: =SUMIFS('Planificación 2026-1'!$R:$R,'Planificación 2026-1'!$W:$W,G17) -> 14
E18: ATME ROJAS DAVEY RAUL | G18: ATUNCAR VASQUEZ RICARDO MANUEL | H18: =SUMIFS('Planificación 2026-1'!$R:$R,'Planificación 2026-1'!$W:$W,G18,'Planificación 2026-1'!$H:$H,"<=2") -> 0 | I18: =SUMIFS('Planificación 2026-1'!$R:$R,'Planificación 2026-1'!$W:$W,G18,'Planificación 2026-1'!$H:$H,">=3") -> 34 | J18: =SUMIFS('Planificación 2026-1'!$R:$R,'Planificación 2026-1'!$W:$W,G18) -> 34
E19: ATUNCAR SUENG DORA ROSARIO | G19: AYBAR HUAMANI JUSTINIANO | H19: =SUMIFS('Planificación 2026-1'!$R:$R,'Planificación 2026-1'!$W:$W,G19,'Planificación 2026-1'!$H:$H,"<=2") -> 39 | I19: =SUMIFS('Planificación 2026-1'!$R:$R,'Planificación 2026-1'!$W:$W,G19,'Planificación 2026-1'!$H:$H,">=3") -> 0 | J19: =SUMIFS('Planificación 2026-1'!$R:$R,'Planificación 2026-1'!$W:$W,G19) -> 39 | K19: si
E20: ATUNCAR VASQUEZ RICARDO MANUEL | G20: BALBUENA CONISLLA KATHERINE ROXANA | H20: =SUMIFS('Planificación 2026-1'!$R:$R,'Planificación 2026-1'!$W:$W,G20,'Planificación 2026-1'!$H:$H,"<=2") -> 0 | I20: =SUMIFS('Planificación 2026-1'!$R:$R,'Planificación 2026-1'!$W:$W,G20,'Planificación 2026-1'!$H:$H,">=3") -> 0 | J20: =SUMIFS('Planificación 2026-1'!$R:$R,'Planificación 2026-1'!$W:$W,G20) -> 0
E21: BALBUENA CONISLLA KATHERINE ROXANA | G21: BAÑOS RAMOS JUAN CARLOS | H21: =SUMIFS('Planificación 2026-1'!$R:$R,'Planificación 2026-1'!$W:$W,G21,'Planificación 2026-1'!$H:$H,"<=2") -> 0 | I21: =SUMIFS('Planificación 2026-1'!$R:$R,'Planificación 2026-1'!$W:$W,G21,'Planificación 2026-1'!$H:$H,">=3") -> 14 | J21: =SUMIFS('Planificación 2026-1'!$R:$R,'Planificación 2026-1'!$W:$W,G21) -> 14
E22: BAÑOS RAMOS JUAN CARLOS | G22: BARRIENTOS PEREZ TEREZA NICOLLE | H22: =SUMIFS('Planificación 2026-1'!$R:$R,'Planificación 2026-1'!$W:$W,G22,'Planificación 2026-1'!$H:$H,"<=2") -> 0 | I22: =SUMIFS('Planificación 2026-1'!$R:$R,'Planificación 2026-1'!$W:$W,G22,'Planificación 2026-1'!$H:$H,">=3") -> 19 | J22: =SUMIFS('Planificación 2026-1'!$R:$R,'Planificación 2026-1'!$W:$W,G22) -> 19
E23: BARRIENTOS PEREZ TEREZA NICOLLE | G23: BARRIENTOS RAMOS VICTOR HUGO | H23: =SUMIFS('Planificación 2026-1'!$R:$R,'Planificación 2026-1'!$W:$W,G23,'Planificación 2026-1'!$H:$H,"<=2") -> 0 | I23: =SUMIFS('Planificación 2026-1'!$R:$R,'Planificación 2026-1'!$W:$W,G23,'Planificación 2026-1'!$H:$H,">=3") -> 15 | J23: =SUMIFS('Planificación 2026-1'!$R:$R,'Planificación 2026-1'!$W:$W,G23) -> 15
E24: BARRIENTOS RAMOS VICTOR HUGO | G24: BARRIOS GABRIEL SONIA EDITH | H24: =SUMIFS('Planificación 2026-1'!$R:$R,'Planificación 2026-1'!$W:$W,G24,'Planificación 2026-1'!$H:$H,"<=2") -> 35 | I24: =SUMIFS('Planificación 2026-1'!$R:$R,'Planificación 2026-1'!$W:$W,G24,'Planificación 2026-1'!$H:$H,">=3") -> 0 | J24: =SUMIFS('Planificación 2026-1'!$R:$R,'Planificación 2026-1'!$W:$W,G24) -> 35
E25: BARRIOS GABRIEL SONIA EDITH | G25: BAZALAR GANOZA BEATRIZ ROSARIO | H25: =SUMIFS('Planificación 2026-1'!$R:$R,'Planificación 2026-1'!$W:$W,G25,'Planificación 2026-1'!$H:$H,"<=2") -> 30 | I25: =SUMIFS('Planificación 2026-1'!$R:$R,'Planificación 2026-1'!$W:$W,G25,'Planificación 2026-1'!$H:$H,">=3") -> 0 | J25: =SUMIFS('Planificación 2026-1'!$R:$R,'Planificación 2026-1'!$W:$W,G25) -> 30 | K25: si
E26: BELLIDO LEON FRANK JUNIOR | G26: BELLIDO LEON FRANK JUNIOR | H26: =SUMIFS('Planificación 2026-1'!$R:$R,'Planificación 2026-1'!$W:$W,G26,'Planificación 2026-1'!$H:$H,"<=2") -> 0 | I26: =SUMIFS('Planificación 2026-1'!$R:$R,'Planificación 2026-1'!$W:$W,G26,'Planificación 2026-1'!$H:$H,">=3") -> 31 | J26: =SUMIFS('Planificación 2026-1'!$R:$R,'Planificación 2026-1'!$W:$W,G26) -> 31
E27: BENAVIDES ESCRIBA VICTOR MANUEL | G27: BENAVIDES ESCRIBA VICTOR MANUEL | H27: =SUMIFS('Planificación 2026-1'!$R:$R,'Planificación 2026-1'!$W:$W,G27,'Planificación 2026-1'!$H:$H,"<=2") -> 0 | I27: =SUMIFS('Planificación 2026-1'!$R:$R,'Planificación 2026-1'!$W:$W,G27,'Planificación 2026-1'!$H:$H,">=3") -> 32 | J27: =SUMIFS('Planificación 2026-1'!$R:$R,'Planificación 2026-1'!$W:$W,G27) -> 32
E28: BENDEZU HUAROTO ALEX RAUL | G28: BENDEZU HUAROTO ALEX RAUL | H28: =SUMIFS('Planificación 2026-1'!$R:$R,'Planificación 2026-1'!$W:$W,G28,'Planificación 2026-1'!$H:$H,"<=2") -> 33 | I28: =SUMIFS('Planificación 2026-1'!$R:$R,'Planificación 2026-1'!$W:$W,G28,'Planificación 2026-1'!$H:$H,">=3") -> 0 | J28: =SUMIFS('Planificación 2026-1'!$R:$R,'Planificación 2026-1'!$W:$W,G28) -> 33
E29: BERROSPI VARGAS ANA ELVA | G29: BERROSPI VARGAS ANA ELVA | H29: =SUMIFS('Planificación 2026-1'!$R:$R,'Planificación 2026-1'!$W:$W,G29,'Planificación 2026-1'!$H:$H,"<=2") -> 0 | I29: =SUMIFS('Planificación 2026-1'!$R:$R,'Planificación 2026-1'!$W:$W,G29,'Planificación 2026-1'!$H:$H,">=3") -> 18 | J29: =SUMIFS('Planificación 2026-1'!$R:$R,'Planificación 2026-1'!$W:$W,G29) -> 18
E30: CABRERA PIMENTEL HELGA ROXANA | G30: BRIZUELA LOPEZ MARIELLA PILAR | H30: =SUMIFS('Planificación 2026-1'!$R:$R,'Planificación 2026-1'!$W:$W,G30,'Planificación 2026-1'!$H:$H,"<=2") -> 0 | I30: =SUMIFS('Planificación 2026-1'!$R:$R,'Planificación 2026-1'!$W:$W,G30,'Planificación 2026-1'!$H:$H,">=3") -> 0 | J30: =SUMIFS('Planificación 2026-1'!$R:$R,'Planificación 2026-1'!$W:$W,G30) -> 0
E31: CABRERA VELASQUEZ MEYLAN ALLIZA | G31: CABRERA PIMENTEL HELGA ROXANA | H31: =SUMIFS('Planificación 2026-1'!$R:$R,'Planificación 2026-1'!$W:$W,G31,'Planificación 2026-1'!$H:$H,"<=2") -> 0 | I31: =SUMIFS('Planificación 2026-1'!$R:$R,'Planificación 2026-1'!$W:$W,G31,'Planificación 2026-1'!$H:$H,">=3") -> 30 | J31: =SUMIFS('Planificación 2026-1'!$R:$R,'Planificación 2026-1'!$W:$W,G31) -> 30
E32: CABRERA VIZARRETA MARTHA LUISA | G32: CABRERA VELASQUEZ MEYLAN ALLIZA | H32: =SUMIFS('Planificación 2026-1'!$R:$R,'Planificación 2026-1'!$W:$W,G32,'Planificación 2026-1'!$H:$H,"<=2") -> 0 | I32: =SUMIFS('Planificación 2026-1'!$R:$R,'Planificación 2026-1'!$W:$W,G32,'Planificación 2026-1'!$H:$H,">=3") -> 16 | J32: =SUMIFS('Planificación 2026-1'!$R:$R,'Planificación 2026-1'!$W:$W,G32) -> 16
E33: CAHUA DIAZ DEYSI MARIBEL | G33: CABRERA VIZARRETA MARTHA LUISA | H33: =SUMIFS('Planificación 2026-1'!$R:$R,'Planificación 2026-1'!$W:$W,G33,'Planificación 2026-1'!$H:$H,"<=2") -> 29 | I33: =SUMIFS('Planificación 2026-1'!$R:$R,'Planificación 2026-1'!$W:$W,G33,'Planificación 2026-1'!$H:$H,">=3") -> 8 | J33: =SUMIFS('Planificación 2026-1'!$R:$R,'Planificación 2026-1'!$W:$W,G33) -> 37
E34: CAHUANA MUÑOZ BETTY MARISEL | G34: CAHUA DIAZ DEYSI MARIBEL | H34: =SUMIFS('Planificación 2026-1'!$R:$R,'Planificación 2026-1'!$W:$W,G34,'Planificación 2026-1'!$H:$H,"<=2") -> 0 | I34: =SUMIFS('Planificación 2026-1'!$R:$R,'Planificación 2026-1'!$W:$W,G34,'Planificación 2026-1'!$H:$H,">=3") -> 12 | J34: =SUMIFS('Planificación 2026-1'!$R:$R,'Planificación 2026-1'!$W:$W,G34) -> 12
E35: CALLAÑAUPA VARGAS JULIA ANTONIA | G35: CAHUANA MUÑOZ BETTY MARISEL | H35: =SUMIFS('Planificación 2026-1'!$R:$R,'Planificación 2026-1'!$W:$W,G35,'Planificación 2026-1'!$H:$H,"<=2") -> 0 | I35: =SUMIFS('Planificación 2026-1'!$R:$R,'Planificación 2026-1'!$W:$W,G35,'Planificación 2026-1'!$H:$H,">=3") -> 32 | J35: =SUMIFS('Planificación 2026-1'!$R:$R,'Planificación 2026-1'!$W:$W,G35) -> 32
E36: CAMPOS CARDENAS SANDRA GISELA | G36: CALLAÑAUPA VARGAS JULIA ANTONIA | H36: =SUMIFS('Planificación 2026-1'!$R:$R,'Planificación 2026-1'!$W:$W,G36,'Planificación 2026-1'!$H:$H,"<=2") -> 0 | I36: =SUMIFS('Planificación 2026-1'!$R:$R,'Planificación 2026-1'!$W:$W,G36,'Planificación 2026-1'!$H:$H,">=3") -> 26 | J36: =SUMIFS('Planificación 2026-1'!$R:$R,'Planificación 2026-1'!$W:$W,G36) -> 26
E37: CANDELA CUBILLAS HUBER AGUSTIN | G37: CAMPIAN LAZO YONAL IGNACIO | H37: =SUMIFS('Planificación 2026-1'!$R:$R,'Planificación 2026-1'!$W:$W,G37,'Planificación 2026-1'!$H:$H,"<=2") -> 14 | I37: =SUMIFS('Planificación 2026-1'!$R:$R,'Planificación 2026-1'!$W:$W,G37,'Planificación 2026-1'!$H:$H,">=3") -> 0 | J37: =SUMIFS('Planificación 2026-1'!$R:$R,'Planificación 2026-1'!$W:$W,G37) -> 14
... E229: ZEGARRA ZEBALLOS MARIELA ROSARIO | G229: URBANO LUCANA SEFERINA SARAFINA | H229: =SUMIFS('Planificación 2026-1'!$R:$R,'Planificación 2026-1'!$W:$W,G229,'Planificación 2026-1'!$H:$H,"<=2") -> 15 | I229: =SUMIFS('Planificación 2026-1'!$R:$R,'Planificación 2026-1'!$W:$W,G229,'Planificación 2026-1'!$H:$H,">=3") -> 0 | J229: =SUMIFS('Planificación 2026-1'!$R:$R,'Planificación 2026-1'!$W:$W,G229) -> 15
G230: VALDIVIEZO GUEVARA MARLITT | H230: =SUMIFS('Planificación 2026-1'!$R:$R,'Planificación 2026-1'!$W:$W,G230,'Planificación 2026-1'!$H:$H,"<=2") -> 38 | I230: =SUMIFS('Planificación 2026-1'!$R:$R,'Planificación 2026-1'!$W:$W,G230,'Planificación 2026-1'!$H:$H,">=3") -> 0 | J230: =SUMIFS('Planificación 2026-1'!$R:$R,'Planificación 2026-1'!$W:$W,G230) -> 38
G231: VALDIVIEZO GUEVARA MARLITT | H231: =SUMIFS('Planificación 2026-1'!$R:$R,'Planificación 2026-1'!$W:$W,G231,'Planificación 2026-1'!$H:$H,"<=2") -> 0 | I231: =SUMIFS('Planificación 2026-1'!$R:$R,'Planificación 2026-1'!$W:$W,G231,'Planificación 2026-1'!$H:$H,">=3") -> 0 | J231: =SUMIFS('Planificación 2026-1'!$R:$R,'Planificación 2026-1'!$W:$W,G231) -> 0
...

Sheet Docentes
B2: REGISTRO DE DOCENTES CON CARGA ACADÉMICA 2025-2
B4: N° | C4: DNI | D4: APELLIDOS Y NOMBRE DOCENTE 2025-2 | E4: CONDICIÓN | G4: LOCAL 2025-2 | H4: CONDICIÓN | I4: PROGRAMA ACADÉMICO 2025-2 | J4: DEDICACIÓN 2025-2 | K4: HORAS 2025-2 | L4: LOCAL 2026-1 | M4: CONDICIÓN 2026-1 | N4: PROGRAMA ACADÉMICO 2026-1 | O4: DEDICACIÓN 2026-1 | P4: HORAS 2026-1 | R4: RESPONSABLE DE UNIDAD / DOCENTE INVESTIGADOR (ESCRIBIR AREA Y ESCUELA | S4: OBSERVACIONES
B5: 1 | C5: 45549528 | D5: ACHARTE CHAMPI WALTER JESUS | E5: DOCENTE | F5: RENOVACIÓN | G5: SEDE | H5: DOCENTE | I5: ENFERMERÍA | J5: TC | K5: 40 | L5: =VLOOKUP(D5,EDITABLE!C:H,5,FALSE) -> SEDE | N5: =VLOOKUP(D5,EDITABLE!C:H,6,FALSE) -> ENFERMERÍA | P5: =SUMIFS('Planificación 2026-1'!$R:$R,'Planificación 2026-1'!$W:$W,D5) -> 40
B6: 2 | C6: 40364065 | D6: ACOSTA VILLAVICENCIO BLANCA AURORA | E6: DOCENTE | F6: RENOVACIÓN | G6: SEDE | H6: DOCENTE | I6: PSICOLOGÍA - EEGG | J6: TC | K6: 38 | L6: =VLOOKUP(D6,EDITABLE!C:H,5,FALSE) -> SEDE | N6: =VLOOKUP(D6,EDITABLE!C:H,6,FALSE) -> OBSTETRICIA - EEGG | P6: =SUMIFS('Planificación 2026-1'!$R:$R,'Planificación 2026-1'!$W:$W,D6) -> 40
B7: 3 | C7: 45228337 | D7: ALIAGA RUIZ MINA ANGELICA | E7: DOCENTE | F7: RENOVACIÓN | G7: SEDE | H7: DOCENTE | I7: PSICOLOGÍA | J7: TP | K7: 10 | L7: =VLOOKUP(D7,EDITABLE!C:H,5,FALSE) -> SEDE | N7: =VLOOKUP(D7,EDITABLE!C:H,6,FALSE) -> PSICOLOGÍA | P7: =SUMIFS('Planificación 2026-1'!$R:$R,'Planificación 2026-1'!$W:$W,D7) -> 13
B8: 4 | C8: 21525109 | D8: ALVAREZ GARCIA TERESA ELVIRA | E8: DOCENTE | F8: RENOVACIÓN | G8: FILIAL | H8: DOCENTE | I8: MEDICINA HUMANA | J8: TP | K8: 8 | L8: =VLOOKUP(D8,EDITABLE!C:H,5,FALSE) -> PORUMA | N8: =VLOOKUP(D8,EDITABLE!C:H,6,FALSE) -> MEDICINA HUMANA | P8: =SUMIFS('Planificación 2026-1'!$R:$R,'Planificación 2026-1'!$W:$W,D8) -> 17
B9: 5 | C9: 44371485 | D9: ANCAJIMA RUIZ ANDREA BETTY | E9: DOCENTE | F9: RENOVACIÓN | G9: FILIAL | H9: DOCENTE | I9: DERECHO - EEGG | J9: TP | K9: 15 | L9: =VLOOKUP(D9,EDITABLE!C:H,5,FALSE) -> FILIAL | N9: =VLOOKUP(D9,EDITABLE!C:H,6,FALSE) -> ENFERMERÍA - EEGG | P9: =SUMIFS('Planificación 2026-1'!$R:$R,'Planificación 2026-1'!$W:$W,D9) -> 15
B10: 6 | C10: 21560679 | D10: ANICAMA BERNAOLA PEDRO ARTURO | E10: DOCENTE | F10: INVITACIÓN | G10: FILIAL | H10: DOCENTE | I10: MEDICINA HUMANA | J10: TP | K10: 15 | L10: =VLOOKUP(D10,EDITABLE!C:H,5,FALSE) -> PORUMA | N10: =VLOOKUP(D10,EDITABLE!C:H,6,FALSE) -> MEDICINA HUMANA | P10: =SUMIFS('Planificación 2026-1'!$R:$R,'Planificación 2026-1'!$W:$W,D10) -> 14
B11: 7 | C11: 43041422 | D11: ANTEZANA CHINQUILLO JOSE GIANCARLO | E11: DOCENTE | F11: RENOVACIÓN | G11: FILIAL | H11: DOCENTE | I11: ENFERMERÍA | J11: TP | K11: 14 | L11: =VLOOKUP(D11,EDITABLE!C:H,5,FALSE) -> PORUMA | N11: =VLOOKUP(D11,EDITABLE!C:H,6,FALSE) -> MEDICINA HUMANA | P11: =SUMIFS('Planificación 2026-1'!$R:$R,'Planificación 2026-1'!$W:$W,D11) -> 36
B12: 8 | C12: 42508963 | D12: APOLAYA PAREJA BERTHA ESTHER | E12: DOCENTE | F12: RENOVACIÓN | G12: SEDE | H12: DOCENTE | I12: OBSTETRICIA | J12: TC | K12: 27 | L12: =VLOOKUP(D12,EDITABLE!C:H,5,FALSE) -> SEDE | N12: =VLOOKUP(D12,EDITABLE!C:H,6,FALSE) -> OBSTETRICIA | P12: =SUMIFS('Planificación 2026-1'!$R:$R,'Planificación 2026-1'!$W:$W,D12) -> 24 | R12: RESPONSABLE DE UNIDAD DE INVESTIGACION Y RESPONSABILIDAD SOCIAL OBSTETRICIA
B13: 9 | C13: 22299955 | D13: AQUIJE DAPOZZO EDWAR VIDAL | E13: DOCENTE | F13: RENOVACIÓN | G13: FILIAL | H13: DOCENTE | I13: OBSTETRICIA | J13: TP | K13: 8 | L13: =VLOOKUP(D13,EDITABLE!C:H,5,FALSE) -> FILIAL | N13: =VLOOKUP(D13,EDITABLE!C:H,6,FALSE) -> ENFERMERÍA | P13: =SUMIFS('Planificación 2026-1'!$R:$R,'Planificación 2026-1'!$W:$W,D13) -> 18
B14: 10 | C14: 21546746 | D14: ARIZOLA AGUADO ALICIA ANTOINETTE | E14: DOCENTE | F14: RENOVACIÓN | G14: FILIAL | H14: DOCENTE | I14: MEDICINA HUMANA | J14: TP | K14: 15 | L14: =VLOOKUP(D14,EDITABLE!C:H,5,FALSE) -> PORUMA | N14: =VLOOKUP(D14,EDITABLE!C:H,6,FALSE) -> MEDICINA HUMANA | P14: =SUMIFS('Planificación 2026-1'!$R:$R,'Planificación 2026-1'!$W:$W,D14) -> 15
B15: 11 | C15: 42841966 | D15: AROTUMA GRANDA HECTOR JUAN CARLOS | E15: DOCENTE | F15: CONCURSO | G15: FILIAL | H15: DOCENTE | I15: MEDICINA HUMANA | J15: TP | K15: 10 | L15: =VLOOKUP(D15,EDITABLE!C:H,5,FALSE) -> PORUMA | N15: =VLOOKUP(D15,EDITABLE!C:H,6,FALSE) -> MEDICINA HUMANA | P15: =SUMIFS('Planificación 2026-1'!$R:$R,'Planificación 2026-1'!$W:$W,D15) -> 10
B16: 12 | C16: 21427721 | D16: ARQUIÑEGO SOLAR HENRRY MARCOS | E16: DOCENTE | F16: RENOVACIÓN | G16: FILIAL | H16: DOCENTE | I16: ENFERMERÍA | J16: TC | K16: 38 | L16: =VLOOKUP(D16,EDITABLE!C:H,5,FALSE) -> FILIAL | N16: =VLOOKUP(D16,EDITABLE!C:H,6,FALSE) -> ENFERMERÍA | P16: =SUMIFS('Planificación 2026-1'!$R:$R,'Planificación 2026-1'!$W:$W,D16) -> 30
B17: 13 | C17: 40385643 | D17: ARREDONDO ZELA SONIA OLIVIA | E17: DOCENTE | F17: RENOVACIÓN | G17: SEDE | H17: DOCENTE | I17: DERECHO - EEGG | J17: TP | K17: 15 | L17: =VLOOKUP(D17,EDITABLE!C:H,5,FALSE) -> SEDE | N17: =VLOOKUP(D17,EDITABLE!C:H,6,FALSE) -> OBSTETRICIA - EEGG | P17: =SUMIFS('Planificación 2026-1'!$R:$R,'Planificación 2026-1'!$W:$W,D17) -> 38
B18: 14 | C18: 80034938 | D18: ARROYO PACHAS JOSE LUIS | E18: DOCENTE | F18: RENOVACIÓN | G18: SEDE | H18: DOCENTE | I18: ENFERMERÍA | J18: TC | K18: 34 | L18: =VLOOKUP(D18,EDITABLE!C:H,5,FALSE) -> SEDE | N18: =VLOOKUP(D18,EDITABLE!C:H,6,FALSE) -> ENFERMERÍA | P18: =SUMIFS('Planificación 2026-1'!$R:$R,'Planificación 2026-1'!$W:$W,D18) -> 32
B19: 15 | C19: 21536202 | D19: ATME ROJAS DAVEY RAUL | E19: DOCENTE | F19: RENOVACIÓN | G19: FILIAL | H19: DOCENTE | I19: PSICOLOGÍA | J19: TC | K19: 32 | L19: =VLOOKUP(D19,EDITABLE!C:H,5,FALSE) -> FILIAL | N19: =VLOOKUP(D19,EDITABLE!C:H,6,FALSE) -> PSICOLOGÍA | P19: =SUMIFS('Planificación 2026-1'!$R:$R,'Planificación 2026-1'!$W:$W,D19) -> 25 | R19: RESPONSABLE DE UNIDAD DE INVESTIGACION Y RESPONSABILIDAD SOCIAL PSICOLOGÍA
B20: 16 | C20: 07703595 | D20: ATUNCAR SUENG DORA ROSARIO | E20: DOCENTE | F20: CONCURSO | G20: SEDE | H20: DOCENTE | I20: PSICOLOGÍA | J20: TP | K20: 8 | L20: =VLOOKUP(D20,EDITABLE!C:H,5,FALSE) -> SEDE | N20: =VLOOKUP(D20,EDITABLE!C:H,6,FALSE) -> PSICOLOGÍA | P20: =SUMIFS('Planificación 2026-1'!$R:$R,'Planificación 2026-1'!$W:$W,D20) -> 14
B21: 17 | C21: 21836179 | D21: ATUNCAR VASQUEZ RICARDO MANUEL | E21: DOCENTE | F21: RENOVACIÓN | G21: SEDE | H21: DOCENTE | I21: PSICOLOGÍA | J21: TP | K21: 12 | L21: =VLOOKUP(D21,EDITABLE!C:H,5,FALSE) -> SEDE | N21: =VLOOKUP(D21,EDITABLE!C:H,6,FALSE) -> OBSTETRICIA | P21: =SUMIFS('Planificación 2026-1'!$R:$R,'Planificación 2026-1'!$W:$W,D21) -> 34
B22: 18 | C22: 08822479 | D22: AYBAR HUAMANI JUSTINIANO | E22: DOCENTE | F22: CONCURSO | G22: SEDE | H22: DOCENTE | I22: ADMINISTRACIÓN DE EMPRESAS | J22: TP | K22: 13 | L22: =VLOOKUP(D22,EDITABLE!C:H,5,FALSE) -> SEDE | N22: =VLOOKUP(D22,EDITABLE!C:H,6,FALSE) -> ENFERMERÍA - EEGG | P22: =SUMIFS('Planificación 2026-1'!$R:$R,'Planificación 2026-1'!$W:$W,D22) -> 39
B23: 19 | C23: 70314211 | D23: BALBUENA CONISLLA KATHERINE ROXANA | E23: DOCENTE | F23: RENOVACIÓN | G23: FILIAL | H23: DOCENTE | I23: ENFERMERÍA | J23: TP | K23: 5 | L23: =VLOOKUP(D23,EDITABLE!C:H,5,FALSE) -> #N/A | N23: =VLOOKUP(D23,EDITABLE!C:H,6,FALSE) -> #N/A | P23: =SUMIFS('Planificación 2026-1'!$R:$R,'Planificación 2026-1'!$W:$W,D23) -> 0
B24: 20 | C24: 40139812 | D24: BAÑOS RAMOS JUAN CARLOS | E24: DOCENTE | F24: RENOVACIÓN | G24: SEDE | H24: DOCENTE | I24: PSICOLOGÍA | J24: TC | K24: 36 | L24: =VLOOKUP(D24,EDITABLE!C:H,5,FALSE) -> SEDE | N24: =VLOOKUP(D24,EDITABLE!C:H,6,FALSE) -> PSICOLOGÍA | P24: =SUMIFS('Planificación 2026-1'!$R:$R,'Planificación 2026-1'!$W:$W,D24) -> 14
B25: 21 | C25: 72226049 | D25: BARRIENTOS PEREZ TEREZA NICOLLE | E25: DOCENTE | F25: RENOVACIÓN | G25: SEDE | H25: DOCENTE | I25: PSICOLOGÍA | J25: TC | K25: 28 | L25: =VLOOKUP(D25,EDITABLE!C:H,5,FALSE) -> FILIAL | N25: =VLOOKUP(D25,EDITABLE!C:H,6,FALSE) -> PSICOLOGÍA | P25: =SUMIFS('Planificación 2026-1'!$R:$R,'Planificación 2026-1'!$W:$W,D25) -> 19
B26: 22 | C26: 21462854 | D26: BARRIENTOS RAMOS VICTOR HUGO | E26: DOCENTE | F26: CONCURSO | G26: FILIAL | H26: DOCENTE | I26: ENFERMERÍA - EEGG | J26: TP | K26: 15 | L26: =VLOOKUP(D26,EDITABLE!C:H,5,FALSE) -> FILIAL | N26: =VLOOKUP(D26,EDITABLE!C:H,6,FALSE) -> ENFERMERÍA | P26: =SUMIFS('Planificación 2026-1'!$R:$R,'Planificación 2026-1'!$W:$W,D26) -> 15
B27: 23 | C27: 21416373 | D27: BARRIOS GABRIEL SONIA EDITH | E27: DOCENTE | F27: RENOVACIÓN | G27: FILIAL | H27: DOCENTE | I27: INGENIERÍA CIVIL - EEGG | J27: TC | K27: 39 | L27: =VLOOKUP(D27,EDITABLE!C:H,5,FALSE) -> PORUMA | N27: =VLOOKUP(D27,EDITABLE!C:H,6,FALSE) -> MEDICINA HUMANA - EEGG | P27: =SUMIFS('Planificación 2026-1'!$R:$R,'Planificación 2026-1'!$W:$W,D27) -> 35
B28: 24 | C28: 15738929 | D28: BAZALAR GANOZA BEATRIZ ROSARIO | E28: DOCENTE | F28: RENOVACIÓN | G28: HUAURA | H28: DOCENTE | I28: ENFERMERÍA - EEGG | J28: TC | K28: 39 | L28: =VLOOKUP(D28,EDITABLE!C:H,5,FALSE) -> HUAURA | N28: =VLOOKUP(D28,EDITABLE!C:H,6,FALSE) -> ENFERMERÍA - EEGG | P28: =SUMIFS('Planificación 2026-1'!$R:$R,'Planificación 2026-1'!$W:$W,D28) -> 30
B29: 25 | C29: 70431834 | D29: BELLIDO LEON FRANK JUNIOR | E29: DOCENTE | F29: RENOVACIÓN | G29: SEDE | H29: DOCENTE | I29: ENFERMERÍA | J29: TC | K29: 36 | L29: =VLOOKUP(D29,EDITABLE!C:H,5,FALSE) -> SEDE | N29: =VLOOKUP(D29,EDITABLE!C:H,6,FALSE) -> ENFERMERÍA | P29: =SUMIFS('Planificación 2026-1'!$R:$R,'Planificación 2026-1'!$W:$W,D29) -> 31
B30: 26 | C30: 72580385 | D30: BENAVIDES ESCRIBA VICTOR MANUEL | E30: DOCENTE | F30: RENOVACIÓN | G30: FILIAL | H30: DOCENTE | I30: ENFERMERÍA | J30: TC | K30: 30 | L30: =VLOOKUP(D30,EDITABLE!C:H,5,FALSE) -> SEDE | N30: =VLOOKUP(D30,EDITABLE!C:H,6,FALSE) -> ENFERMERÍA | P30: =SUMIFS('Planificación 2026-1'!$R:$R,'Planificación 2026-1'!$W:$W,D30) -> 32
B31: 27 | C31: 71819567 | D31: BENDEZU HUAROTO ALEX RAUL | E31: DOCENTE | F31: RENOVACIÓN | G31: FILIAL | H31: DOCENTE | I31: MEDICINA HUMANA - EEGG | J31: TC | K31: 31 | L31: =VLOOKUP(D31,EDITABLE!C:H,5,FALSE) -> PORUMA | N31: =VLOOKUP(D31,EDITABLE!C:H,6,FALSE) -> MEDICINA HUMANA - EEGG | P31: =SUMIFS('Planificación 2026-1'!$R:$R,'Planificación 2026-1'!$W:$W,D31) -> 33
B32: 28 | C32: 9100625 | D32: BERROSPI VARGAS ANA ELVA | E32: DOCENTE | F32: RENOVACIÓN | G32: FILIAL | H32: DOCENTE | I32: OBSTETRICIA | J32: TP | K32: 14 | L32: =VLOOKUP(D32,EDITABLE!C:H,5,FALSE) -> FILIAL | N32: =VLOOKUP(D32,EDITABLE!C:H,6,FALSE) -> OBSTETRICIA | P32: =SUMIFS('Planificación 2026-1'!$R:$R,'Planificación 2026-1'!$W:$W,D32) -> 18
B33: 29 | C33: 9640297 | D33: BRIZUELA LOPEZ MARIELLA PILAR | E33: DOCENTE | F33: RENOVACIÓN | G33: FILIAL | H33: DOCENTE | I33: CONTABILIDAD - EEGG | J33: TP | K33: 10 | L33: =VLOOKUP(D33,EDITABLE!C:H,5,FALSE) -> #N/A | N33: =VLOOKUP(D33,EDITABLE!C:H,6,FALSE) -> #N/A | P33: =SUMIFS('Planificación 2026-1'!$R:$R,'Planificación 2026-1'!$W:$W,D33) -> 0
B34: 30 | C34: 42825709 | D34: CABRERA PIMENTEL HELGA ROXANA | E34: DOCENTE | F34: RENOVACIÓN | G34: FILIAL | H34: DOCENTE | I34: ENFERMERÍA | J34: TC | K34: 30 | L34: =VLOOKUP(D34,EDITABLE!C:H,5,FALSE) -> FILIAL | N34: =VLOOKUP(D34,EDITABLE!C:H,6,FALSE) -> ENFERMERÍA | P34: =SUMIFS('Planificación 2026-1'!$R:$R,'Planificación 2026-1'!$W:$W,D34) -> 30
... B38: 34 | C38: 21567738 | D38: CAHUANA MUÑOZ BETTY MARISEL | E38: DOCENTE | F38: RENOVACIÓN | G38: FILIAL | H38: DOCENTE | I38: OBSTETRICIA | J38: TC | K38: 32 | L38: =VLOOKUP(D38,EDITABLE!C:H,5,FALSE) -> FILIAL | N38: =VLOOKUP(D38,EDITABLE!C:H,6,FALSE) -> OBSTETRICIA | P38: =SUMIFS('Planificación 2026-1'!$R:$R,'Planificación 2026-1'!$W:$W,D38) -> 32
B39: 35 | C39: 21453025 | D39: CALLAÑAUPA VARGAS JULIA ANTONIA | E39: DOCENTE | F39: RENOVACIÓN | G39: FILIAL | H39: DOCENTE | I39: MEDICINA HUMANA | J39: TC | K39: 31 | L39: =VLOOKUP(D39,EDITABLE!C:H,5,FALSE) -> SUNAMPE | N39: =VLOOKUP(D39,EDITABLE!C:H,6,FALSE) -> MEDICINA HUMANA | P39: =SUMIFS('Planificación 2026-1'!$R:$R,'Planificación 2026-1'!$W:$W,D39) -> 26 | R39: DOCENTE DE APOYO PSICOLOGÍA
B40: 36 | C40: 6160287 | D40: CAMPIAN LAZO YONAL IGNACIO | E40: DOCENTE | F40: RENOVACIÓN | G40: SUNAMPE | H40: DOCENTE | I40: MEDICINA HUMANA - EEGG | J40: TP | K40: 16 | L40: =VLOOKUP(D40,EDITABLE!C:H,5,FALSE) -> SUNAMPE | N40: =VLOOKUP(D40,EDITABLE!C:H,6,FALSE) -> MEDICINA HUMANA - EEGG | P40: =SUMIFS('Planificación 2026-1'!$R:$R,'Planificación 2026-1'!$W:$W,D40) -> 14
B41: 37 | C41: 40056370 | D41: CAMPOS CARDENAS SANDRA GISELA | E41: DOCENTE | F41: RENOVACIÓN | G41: SEDE | H41: DOCENTE | I41: ENFERMERÍA | J41: TC | K41: 32 | L41: =VLOOKUP(D41,EDITABLE!C:H,5,FALSE) -> SEDE | N41: =VLOOKUP(D41,EDITABLE!C:H,6,FALSE) -> ENFERMERÍA | P41: =SUMIFS('Planificación 2026-1'!$R:$R,'Planificación 2026-1'!$W:$W,D41) -> 30
B42: 38 | C42: 15727165 | D42: CANALES INGA WENDY VIVIANA | E42: DOCENTE | F42: INVITACIÓN | G42: HUAURA | H42: DOCENTE | I42: DERECHO - EEGG | J42: TP | K42: 18 | L42: =VLOOKUP(D42,EDITABLE!C:H,5,FALSE) -> HUAURA | N42: =VLOOKUP(D42,EDITABLE!C:H,6,FALSE) -> ENFERMERÍA - EEGG | P42: =SUMIFS('Planificación 2026-1'!$R:$R,'Planificación 2026-1'!$W:$W,D42) -> 12
B43: 39 | C43: 6276541 | D43: CANDELA CUBILLAS HUBER AGUSTIN | E43: DOCENTE | F43: RENOVACIÓN | G43: SEDE | H43: DOCENTE | I43: PSICOLOGÍA | J43: TP | K43: 13 | L43: =VLOOKUP(D43,EDITABLE!C:H,5,FALSE) -> SEDE | N43: =VLOOKUP(D43,EDITABLE!C:H,6,FALSE) -> PSICOLOGÍA | P43: =SUMIFS('Planificación 2026-1'!$R:$R,'Planificación 2026-1'!$W:$W,D43) -> 14
B44: 40 | C44: 46475398 | D44: CANDELA LEVANO CECIL MASSIEL | E44: DOCENTE | F44: RENOVACIÓN | G44: FILIAL | H44: DOCENTE | I44: ENFERMERÍA | J44: TC | K44: 28 | L44: =VLOOKUP(D44,EDITABLE!C:H,5,FALSE) -> FILIAL | N44: =VLOOKUP(D44,EDITABLE!C:H,6,FALSE) -> ENFERMERÍA | P44: =SUMIFS('Planificación 2026-1'!$R:$R,'Planificación 2026-1'!$W:$W,D44) -> 24 | R44: RESPONSABLE DE LA UNIDAD DE INVESTIGACIÓN Y RESPONSABILIDAD SOCIAL DE ENFERMERÍA
B45: 41 | C45: 42363036 | D45: CARBONEL RAMIREZ HANS HENRY | E45: DOCENTE | F45: RENOVACIÓN | G45: FILIAL | H45: DOCENTE | I45: MEDICINA HUMANA | J45: TP | K45: 10 | L45: =VLOOKUP(D45,EDITABLE!C:H,5,FALSE) -> PORUMA | N45: =VLOOKUP(D45,EDITABLE!C:H,6,FALSE) -> MEDICINA HUMANA | P45: =SUMIFS('Planificación 2026-1'!$R:$R,'Planificación 2026-1'!$W:$W,D45) -> 11
...

Sheet EDITABLE
I2: SEDE | Z2: FILIAL | AQ2: SUNAMPE | BH2: HUAURA | BY2: HORAS POR CARRERA | CO2: HORAS POR CARRERA EEGG | EC2: EEGG
B3: N° | C3: DOCENTES UAI | D3: HORAS | E3: DEDICACIÓN | F3: CONDICIÓN | G3: LOCAL 2025-2 | H3: PROGRAMA ACADÉMICO 2025-2 | I3: ADM | J3: ENF | K3: ING SIS | L3: PS | M3: IND AL | N3: IND | O3: CONT | P3: DE | Q3: OBS | R3: MEDICINA | S3: ING CIVIL | T3: ARQUI | U3: LAB. CLIN | V3: TERAPIA FIS. | W3: TERAPIA LEN. | X3: ADM. EMP | Y3: OPTOM. | Z3: ADM | AA3: ENF | AB3: ING SIS | AC3: PS | AD3: IND AL | AE3: IND | AF3: CONT | AG3: DE | AH3: OBS | AI3: MEDICINA | AJ3: ING CIVIL | AK3: ARQUI | AL3: LAB. CLIN | AM3: TERAPIA FIS. | AN3: TERAPIA LEN. | AO3: ADM. EMP | AP3: OPTOM. | AQ3: ADM | AR3: ENF | AS3: ING SIS | AT3: PS | AU3: IND AL | AV3: IND | AW3: CONT | AX3: DE | AY3: OBS | AZ3: MEDICINA | BA3: ING CIVIL | BB3: ARQUI | BC3: LAB. CLIN | BD3: TERAPIA FIS. | BE3: TERAPIA LEN. | BF3: ADM. EMP | BG3: OPTOM. | BH3: ADM | BI3: ENF | BJ3: ING SIS | BK3: PS | BL3: IND AL | BM3: IND | BN3: CONT | BO3: DE | BP3: OBS | BQ3: MEDICINA | BR3: ING CIVIL | BS3: ARQUI | BT3: LAB. CLIN | BU3: TERAPIA FIS. | BV3: TERAPIA LEN. | BW3: ADM. EMP | BX3: OPTOM. | BY3: ADMINISTRACIÓN Y FINANZAS | BZ3: ENFERMERÍA | CA3: INGENIERÍA DE SISTEMAS | CB3: PSICOLOGÍA | CC3: INGENIERÍA INDUSTRIAL | CD3: CONTABILIDAD | CE3: DERECHO | CF3: OBSTETRICIA | CG3: MEDICINA HUMANA | CH3: INGENIERÍA CIVIL | CI3: ARQUITECTURA | CJ3: TECNOLOGÍA MEDICA EN LABORATORIO CLÍNICO Y ANATOMÍA PATOLÓGICA | CK3: TECNOLOGÍA MEDICA EN TERAPIA FÍSICA Y REHABILITACIÓN | CL3: TECNOLOGÍA MEDICA EN TERAPIA DE LENGUAJE | CM3: ADMINISTRACIÓN DE EMPRESAS | CN3: TECNOLOGÍA MEDICA EN OPTOMETRÍA | CO3: ADMINISTRACIÓN Y FINANZAS - EEGG | CP3: ENFERMERÍA - EEGG | CQ3: INGENIERÍA DE SISTEMAS - EEGG | CR3: PSICOLOGÍA - EEGG | CS3: INGENIERÍA INDUSTRIAL - EEGG | CT3: CONTABILIDAD - EEGG | CU3: DERECHO - EEGG | CV3: OBSTETRICIA - EEGG | CW3: MEDICINA HUMANA - EEGG | CX3: INGENIERÍA CIVIL - EEGG | CY3: ARQUITECTURA - EEGG | CZ3: TECNOLOGÍA MEDICA EN LABORATORIO CLÍNICO Y ANATOMÍA PATOLÓGICA - EEGG | DA3: TECNOLOGÍA MEDICA EN TERAPIA FÍSICA Y REHABILITACIÓN - EEGG | DB3: TECNOLOGÍA MEDICA EN TERAPIA DE LENGUAJE - EEGG | DC3: ADMINISTRACIÓN DE EMPRESAS - EEGG | DD3: TECNOLOGÍA MEDICA EN OPTOMETRÍA - EEGG | DE3: SEDE | DF3: HORAS VIRTUAL | DG3: HORAS PRESENCIAL | DH3: HORAS HIBRIDAS | DI3: FILIAL | DJ3: HORAS VIRTUAL | DK3: HORAS PRESENCIAL | DL3: HORAS HIBRIDAS | DM3: SUNAMPE | DN3: HORAS VIRTUAL | DO3: HORAS PRESENCIAL | DP3: HUAURA | DQ3: HORAS VIRTUAL | DR3: HORAS PRESENCIAL | DS3: SEDE-VIRTUAL | DT3: SEDE-PRESENCIAL | DU3: SUNAMPE-VIRTUAL | DV3: SUNAMPE-PRESENCIAL | DW3: FILIAL-VIRTUAL | DX3: FILIAL-PRESENCIAL | DY3: PORUMA-VIRTUAL | DZ3: PORUMA-PRESENCIAL | EA3: HUAURA-VIRTUAL | EB3: HUAURA-PRESENCIAL | EC3: SEDE-VIRTUAL | ED3: SEDE-PRESENCIAL | EE3: SUNAMPE-VIRTUAL | EF3: SUNAMPE-PRESENCIAL | EG3: FILIAL-VIRTUAL | EH3: FILIAL-PRESENCIAL | EI3: PORUMA-VIRTUAL | EJ3: PORUMA-PRESENCIAL | EK3: HUAURA-VIRTUAL | EL3: HUAURA-PRESENCIAL | EM3: FILIAL | EN3: HUAURA | EO3: PORUMA | EP3: SEDE | EQ3: SUNAMPE | ES3: VIRTUAL | ET3: PRESENCIAL
B4: 1 | C4: ACHARTE CHAMPI WALTER JESUS | D4: =SUMIF('Planificación 2026-1'!W:W,C4,'Planificación 2026-1'!R:R) -> 40 | E4: TC | F4: RENOVACIÓN | G4: SEDE | H4: ENFERMERÍA | I4: =IF(SUM(COUNTIFS('Planificación 2026-1'!E:E,"PRINCIPAL",'Planificación 2026-1'!W:W,C4,'Planificación 2026-1'!G:G,"AF"))>0,"P01"," ") | J4: =IF(SUM(COUNTIFS('Planificación 2026-1'!E:E,"PRINCIPAL",'Planificación 2026-1'!W:W,C4,'Planificación 2026-1'!G:G,"EN"))>0,"P02"," ") -> P02 | K4: =IF(SUM(COUNTIFS('Planificación 2026-1'!E:E,"PRINCIPAL",'Planificación 2026-1'!W:W,C4,'Planificación 2026-1'!G:G,"IS"))>0,"P03"," ") | L4: =IF(SUM(COUNTIFS('Planificación 2026-1'!E:E,"PRINCIPAL",'Planificación 2026-1'!W:W,C4,'Planificación 2026-1'!G:G,"PS"))>0,"P04"," ") | N4: =IF(SUM(COUNTIFS('Planificación 2026-1'!E:E,"PRINCIPAL",'Planificación 2026-1'!W:W,C4,'Planificación 2026-1'!G:G,"IN"))>0,"P06"," ") | O4: =IF(SUM(COUNTIFS('Planificación 2026-1'!E:E,"PRINCIPAL",'Planificación 2026-1'!W:W,C4,'Planificación 2026-1'!G:G,"CA"))>0,"P07"," ") | P4: =IF(SUM(COUNTIFS('Planificación 2026-1'!E:E,"PRINCIPAL",'Planificación 2026-1'!W:W,C4,'Planificación 2026-1'!G:G,"DE"))>0,"P08"," ") | Q4: =IF(SUM(COUNTIFS('Planificación 2026-1'!E:E,"PRINCIPAL",'Planificación 2026-1'!W:W,C4,'Planificación 2026-1'!G:G,"OB"))>0,"P09"," ") | R4: =IF(SUM(COUNTIFS('Planificación 2026-1'!E:E,"PRINCIPAL",'Planificación 2026-1'!W:W,C4,'Planificación 2026-1'!G:G,"MH"))>0,"P31"," ") | S4: =IF(SUM(COUNTIFS('Planificación 2026-1'!E:E,"PRINCIPAL",'Planificación 2026-1'!W:W,C4,'Planificación 2026-1'!G:G,"IC"))>0,"P32"," ") | T4: =IF(SUM(COUNTIFS('Planificación 2026-1'!E:E,"PRINCIPAL",'Planificación 2026-1'!W:W,C4,'Planificación 2026-1'!G:G,"AR"))>0,"P34"," ") | U4: =IF(SUM(COUNTIFS('Planificación 2026-1'!E:E,"PRINCIPAL",'Planificación 2026-1'!W:W,C4,'Planificación 2026-1'!G:G,"T1"))>0,"P35"," ") | V4: =IF(SUM(COUNTIFS('Planificación 2026-1'!E:E,"PRINCIPAL",'Planificación 2026-1'!W:W,C4,'Planificación 2026-1'!G:G,"T3"))>0,"P36"," ") | W4: =IF(SUM(COUNTIFS('Planificación 2026-1'!E:E,"PRINCIPAL",'Planificación 2026-1'!W:W,C4,'Planificación 2026-1'!G:G,"T2"))>0,"P37"," ") | X4: =IF(SUM(COUNTIFS('Planificación 2026-1'!E:E,"PRINCIPAL",'Planificación 2026-1'!W:W,C4,'Planificación 2026-1'!G:G,"AE"))>0,"P38"," ") | Y4: =IF(SUM(COUNTIFS('Planificación 2026-1'!E:E,"PRINCIPAL",'Planificación 2026-1'!W:W,C4,'Planificación 2026-1'!G:G,"T4"))>0,"P55"," ") | Z4: =IF(SUM(COUNTIFS('Planificación 2026-1'!E:E,"FILIAL",'Planificación 2026-1'!W:W,C4,'Planificación 2026-1'!G:G,"AF"))>0," P01"," ") | AA4: =IF(SUM(COUNTIFS('Planificación 2026-1'!E:E,"FILIAL",'Planificación 2026-1'!W:W,C4,'Planificación 2026-1'!G:G,"EN"))>0,"P02"," ") -> P02 | AB4: =IF(SUM(COUNTIFS('Planificación 2026-1'!E:E,"FILIAL",'Planificación 2026-1'!W:W,C4,'Planificación 2026-1'!G:G,"IS"))>0,"P03"," ") | AC4: =IF(SUM(COUNTIFS('Planificación 2026-1'!E:E,"FILIAL",'Planificación 2026-1'!W:W,C4,'Planificación 2026-1'!G:G,"PS"))>0,"P04"," ") | AE4: =IF(SUM(COUNTIFS('Planificación 2026-1'!E:E,"FILIAL",'Planificación 2026-1'!W:W,C4,'Planificación 2026-1'!G:G,"IN"))>0,"P06"," ") | AF4: =IF(SUM(COUNTIFS('Planificación 2026-1'!E:E,"FILIAL",'Planificación 2026-1'!W:W,C4,'Planificación 2026-1'!G:G,"CA"))>0,"P07"," ") | AG4: =IF(SUM(COUNTIFS('Planificación 2026-1'!E:E,"FILIAL",'Planificación 2026-1'!W:W,C4,'Planificación 2026-1'!G:G,"DE"))>0,"P08"," ") | AH4: =IF(SUM(COUNTIFS('Planificación 2026-1'!E:E,"FILIAL",'Planificación 2026-1'!W:W,C4,'Planificación 2026-1'!G:G,"OB"))>0,"P09"," ") | AI4: =IF(SUM(COUNTIFS('Planificación 2026-1'!E:E,"FILIAL",'Planificación 2026-1'!W:W,C4,'Planificación 2026-1'!G:G,"MH"))>0,"P31"," ") | AJ4: =IF(SUM(COUNTIFS('Planificación 2026-1'!E:E,"FILIAL",'Planificación 2026-1'!W:W,C4,'Planificación 2026-1'!G:G,"IC"))>0,"P32"," ") | AK4: =IF(SUM(COUNTIFS('Planificación 2026-1'!E:E,"FILIAL",'Planificación 2026-1'!W:W,C4,'Planificación 2026-1'!G:G,"AR"))>0,"P34"," ") | AL4: =IF(SUM(COUNTIFS('Planificación 2026-1'!E:E,"FILIAL",'Planificación 2026-1'!W:W,C4,'Planificación 2026-1'!G:G,"T1"))>0,"P35"," ") | AM4: =IF(SUM(COUNTIFS('Planificación 2026-1'!E:E,"FILIAL",'Planificación 2026-1'!W:W,C4,'Planificación 2026-1'!G:G,"T3"))>0,"P36"," ") | AN4: =IF(SUM(COUNTIFS('Planificación 2026-1'!E:E,"FILIAL",'Planificación 2026-1'!W:W,C4,'Planificación 2026-1'!G:G,"T2"))>0,"P37"," ") | AO4: =IF(SUM(COUNTIFS('Planificación 2026-1'!E:E,"FILIAL",'Planificación 2026-1'!W:W,C4,'Planificación 2026-1'!G:G,"AE"))>0,"P38"," ") | AP4: =IF(SUM(COUNTIFS('Planificación 2026-1'!E:E,"FILIAL",'Planificación 2026-1'!W:W,C4,'Planificación 2026-1'!G:G,"T4"))>0,"P55"," ") | AQ4: =IF(SUM(COUNTIFS('Planificación 2026-1'!E:E,"SUNAMPE",'Planificación 2026-1'!W:W,C4,'Planificación 2026-1'!G:G,"AF"))>0," P01"," ") | AR4: =IF(SUM(COUNTIFS('Planificación 2026-1'!E:E,"SUNAMPE",'Planificación 2026-1'!W:W,C4,'Planificación 2026-1'!G:G,"EN"))>0,"P02"," ") | AS4: =IF(SUM(COUNTIFS('Planificación 2026-1'!E:E,"SUNAMPE",'Planificación 2026-1'!W:W,C4,'Planificación 2026-1'!G:G,"IS"))>0,"P03"," ") | AT4: =IF(SUM(COUNTIFS('Planificación 2026-1'!E:E,"SUNAMPE",'Planificación 2026-1'!W:W,C4,'Planificación 2026-1'!G:G,"PS"))>0,"P04"," ") | AV4: =IF(SUM(COUNTIFS('Planificación 2026-1'!E:E,"SUNAMPE",'Planificación 2026-1'!W:W,C4,'Planificación 2026-1'!G:G,"IN"))>0,"P06"," ") | AW4: =IF(SUM(COUNTIFS('Planificación 2026-1'!E:E,"SUNAMPE",'Planificación 2026-1'!W:W,C4,'Planificación 2026-1'!G:G,"CA"))>0,"P07"," ") | AX4: =IF(SUM(COUNTIFS('Planificación 2026-1'!E:E,"SUNAMPE",'Planificación 2026-1'!W:W,C4,'Planificación 2026-1'!G:G,"DE"))>0,"P08"," ") | AY4: =IF(SUM(COUNTIFS('Planificación 2026-1'!E:E,"SUNAMPE",'Planificación 2026-1'!W:W,C4,'Planificación 2026-1'!G:G,"OB"))>0,"P09"," ") | AZ4: =IF(SUM(COUNTIFS('Planificación 2026-1'!E:E,"SUNAMPE",'Planificación 2026-1'!W:W,C4,'Planificación 2026-1'!G:G,"MH"))>0,"P31"," ") | BA4: =IF(SUM(COUNTIFS('Planificación 2026-1'!E:E,"SUNAMPE",'Planificación 2026-1'!W:W,C4,'Planificación 2026-1'!G:G,"IC"))>0,"P32"," ") | BB4: =IF(SUM(COUNTIFS('Planificación 2026-1'!E:E,"SUNAMPE",'Planificación 2026-1'!W:W,C4,'Planificación 2026-1'!G:G,"AR"))>0,"P34"," ") | BC4: =IF(SUM(COUNTIFS('Planificación 2026-1'!E:E,"SUNAMPE",'Planificación 2026-1'!W:W,C4,'Planificación 2026-1'!G:G,"T1"))>0,"P35"," ") | BD4: =IF(SUM(COUNTIFS('Planificación 2026-1'!E:E,"SUNAMPE",'Planificación 2026-1'!W:W,C4,'Planificación 2026-1'!G:G,"T3"))>0,"P36"," ") | BE4: =IF(SUM(COUNTIFS('Planificación 2026-1'!E:E,"SUNAMPE",'Planificación 2026-1'!W:W,C4,'Planificación 2026-1'!G:G,"T2"))>0,"P37"," ") | BF4: =IF(SUM(COUNTIFS('Planificación 2026-1'!E:E,"SUNAMPE",'Planificación 2026-1'!W:W,C4,'Planificación 2026-1'!G:G,"AE"))>0,"P38"," ") | BG4: =IF(SUM(COUNTIFS('Planificación 2026-1'!E:E,"SUNAMPE",'Planificación 2026-1'!W:W,C4,'Planificación 2026-1'!G:G,"T4"))>0,"P55"," ") | BH4: =IF(SUM(COUNTIFS('Planificación 2026-1'!E:E,"HUAURA",'Planificación 2026-1'!W:W,C4,'Planificación 2026-1'!G:G,"AF"))>0," P01"," ") | BI4: =IF(SUM(COUNTIFS('Planificación 2026-1'!E:E,"HUAURA",'Planificación 2026-1'!W:W,C4,'Planificación 2026-1'!G:G,"EN"))>0,"P02"," ") | BJ4: =IF(SUM(COUNTIFS('Planificación 2026-1'!E:E,"HUAURA",'Planificación 2026-1'!W:W,C4,'Planificación 2026-1'!G:G,"IS"))>0,"P03"," ") | BK4: =IF(SUM(COUNTIFS('Planificación 2026-1'!E:E,"HUAURA",'Planificación 2026-1'!W:W,C4,'Planificación 2026-1'!G:G,"PS"))>0,"P04"," ") | BM4: =IF(SUM(COUNTIFS('Planificación 2026-1'!E:E,"HUAURA",'Planificación 2026-1'!W:W,C4,'Planificación 2026-1'!G:G,"IN"))>0,"P06"," ") | BN4: =IF(SUM(COUNTIFS('Planificación 2026-1'!E:E,"HUAURA",'Planificación 2026-1'!W:W,C4,'Planificación 2026-1'!G:G,"CA"))>0,"P07"," ") | BO4: =IF(SUM(COUNTIFS('Planificación 2026-1'!E:E,"HUAURA",'Planificación 2026-1'!W:W,C4,'Planificación 2026-1'!G:G,"DE"))>0,"P08"," ") | BP4: =IF(SUM(COUNTIFS('Planificación 2026-1'!E:E,"HUAURA",'Planificación 2026-1'!W:W,C4,'Planificación 2026-1'!G:G,"OB"))>0,"P09"," ") | BQ4: =IF(SUM(COUNTIFS('Planificación 2026-1'!E:E,"HUAURA",'Planificación 2026-1'!W:W,C4,'Planificación 2026-1'!G:G,"MH"))>0,"P31"," ") | BR4: =IF(SUM(COUNTIFS('Planificación 2026-1'!E:E,"HUAURA",'Planificación 2026-1'!W:W,C4,'Planificación 2026-1'!G:G,"IC"))>0,"P32"," ") | BS4: =IF(SUM(COUNTIFS('Planificación 2026-1'!E:E,"HUAURA",'Planificación 2026-1'!W:W,C4,'Planificación 2026-1'!G:G,"AR"))>0,"P34"," ") | BT4: =IF(SUM(COUNTIFS('Planificación 2026-1'!E:E,"HUAURA",'Planificación 2026-1'!W:W,C4,'Planificación 2026-1'!G:G,"T1"))>0,"P35"," ") | BU4: =IF(SUM(COUNTIFS('Planificación 2026-1'!E:E,"HUAURA",'Planificación 2026-1'!W:W,C4,'Planificación 2026-1'!G:G,"T3"))>0,"P36"," ") | BV4: =IF(SUM(COUNTIFS('Planificación 2026-1'!E:E,"HUAURA",'Planificación 2026-1'!W:W,C4,'Planificación 2026-1'!G:G,"T2"))>0,"P37"," ") | BW4: =IF(SUM(COUNTIFS('Planificación 2026-1'!E:E,"HUAURA",'Planificación 2026-1'!W:W,C4,'Planificación 2026-1'!G:G,"AE"))>0,"P38"," ") | BX4: =IF(SUM(COUNTIFS('Planificación 2026-1'!E:E,"HUAURA",'Planificación 2026-1'!W:W,C4,'Planificación 2026-1'!G:G,"T4"))>0,"P55"," ") | BY4: =SUMIFS('Planificación 2026-1'!R:R,'Planificación 2026-1'!W:W,C4,'Planificación 2026-1'!G:G,"AF",'Planificación 2026-1'!H:H,">2") -> 0 | BZ4: =SUMIFS('Planificación 2026-1'!R:R,'Planificación 2026-1'!W:W,C4,'Planificación 2026-1'!G:G,"EN",'Planificación 2026-1'!H:H,">2") -> 40 | CA4: =SUMIFS('Planificación 2026-1'!R:R,'Planificación 2026-1'!W:W,C4,'Planificación 2026-1'!G:G,"IS",'Planificación 2026-1'!H:H,">2") -> 0 | CB4: =SUMIFS('Planificación 2026-1'!R:R,'Planificación 2026-1'!W:W,C4,'Planificación 2026-1'!G:G,"PS",'Planificación 2026-1'!H:H,">2") -> 0 | CC4: =SUMIFS('Planificación 2026-1'!R:R,'Planificación 2026-1'!W:W,C4,'Planificación 2026-1'!G:G,"IN",'Planificación 2026-1'!H:H,">2") -> 0 | CD4: =SUMIFS('Planificación 2026-1'!R:R,'Planificación 2026-1'!W:W,C4,'Planificación 2026-1'!G:G,"CA",'Planificación 2026-1'!H:H,">2") -> 0 | CE4: =SUMIFS('Planificación 2026-1'!R:R,'Planificación 2026-1'!W:W,C4,'Planificación 2026-1'!G:G,"DE",'Planificación 2026-1'!H:H,">2") -> 0 | CF4: =SUMIFS('Planificación 2026-1'!R:R,'Planificación 2026-1'!W:W,C4,'Planificación 2026-1'!G:G,"OB",'Planificación 2026-1'!H:H,">2") -> 0 | CG4: =SUMIFS('Planificación 2026-1'!R:R,'Planificación 2026-1'!W:W,C4,'Planificación 2026-1'!G:G,"MH",'Planificación 2026-1'!H:H,">2") -> 0 | CH4: =SUMIFS('Planificación 2026-1'!R:R,'Planificación 2026-1'!W:W,C4,'Planificación 2026-1'!G:G,"IC",'Planificación 2026-1'!H:H,">2") -> 0 | CI4: =SUMIFS('Planificación 2026-1'!R:R,'Planificación 2026-1'!W:W,C4,'Planificación 2026-1'!G:G,"AR",'Planificación 2026-1'!H:H,">2") -> 0 | CJ4: =SUMIFS('Planificación 2026-1'!R:R,'Planificación 2026-1'!W:W,C4,'Planificación 2026-1'!G:G,"T1",'Planificación 2026-1'!H:H,">2") -> 0 | CK4: =SUMIFS('Planificación 2026-1'!R:R,'Planificación 2026-1'!W:W,C4,'Planificación 2026-1'!G:G,"T3",'Planificación 2026-1'!H:H,">2") -> 0 | CL4: =SUMIFS('Planificación 2026-1'!R:R,'Planificación 2026-1'!W:W,C4,'Planificación 2026-1'!G:G,"T2",'Planificación 2026-1'!H:H,">2") -> 0 | CM4: =SUMIFS('Planificación 2026-1'!R:R,'Planificación 2026-1'!W:W,C4,'Planificación 2026-1'!G:G,"AE",'Planificación 2026-1'!H:H,">2") -> 0 | CN4: =SUMIFS('Planificación 2026-1'!R:R,'Planificación 2026-1'!W:W,C4,'Planificación 2026-1'!G:G,"T4",'Planificación 2026-1'!H:H,">2") -> 0 | CO4: =SUMIFS('Planificación 2026-1'!R:R,'Planificación 2026-1'!W:W,C4,'Planificación 2026-1'!G:G,"AF",'Planificación 2026-1'!H:H,"<3") -> 0 | CP4: =SUMIFS('Planificación 2026-1'!R:R,'Planificación 2026-1'!W:W,C4,'Planificación 2026-1'!G:G,"EN",'Planificación 2026-1'!H:H,"<3") -> 0 | CQ4: =SUMIFS('Planificación 2026-1'!R:R,'Planificación 2026-1'!W:W,C4,'Planificación 2026-1'!G:G,"IS",'Planificación 2026-1'!H:H,"<3") -> 0 | CR4: =SUMIFS('Planificación 2026-1'!R:R,'Planificación 2026-1'!W:W,C4,'Planificación 2026-1'!G:G,"PS",'Planificación 2026-1'!H:H,"<3") -> 0 | CS4: =SUMIFS('Planificación 2026-1'!R:R,'Planificación 2026-1'!W:W,C4,'Planificación 2026-1'!G:G,"IN",'Planificación 2026-1'!H:H,"<3") -> 0 | CT4: =SUMIFS('Planificación 2026-1'!R:R,'Planificación 2026-1'!W:W,C4,'Planificación 2026-1'!G:G,"CA",'Planificación 2026-1'!H:H,"<3") -> 0 | CU4: =SUMIFS('Planificación 2026-1'!R:R,'Planificación 2026-1'!W:W,C4,'Planificación 2026-1'!G:G,"DE",'Planificación 2026-1'!H:H,"<3") -> 0 | CV4: =SUMIFS('Planificación 2026-1'!R:R,'Planificación 2026-1'!W:W,C4,'Planificación 2026-1'!G:G,"OB",'Planificación 2026-1'!H:H,"<3") -> 0 | CW4: =SUMIFS('Planificación 2026-1'!R:R,'Planificación 2026-1'!W:W,C4,'Planificación 2026-1'!G:G,"MH",'Planificación 2026-1'!H:H,"<3") -> 0 | CX4: =SUMIFS('Planificación 2026-1'!R:R,'Planificación 2026-1'!W:W,C4,'Planificación 2026-1'!G:G,"IC",'Planificación 2026-1'!H:H,"<3") -> 0 | CY4: =SUMIFS('Planificación 2026-1'!R:R,'Planificación 2026-1'!W:W,C4,'Planificación 2026-1'!G:G,"AR",'Planificación 2026-1'!H:H,"<3") -> 0 | CZ4: =SUMIFS('Planificación 2026-1'!R:R,'Planificación 2026-1'!W:W,C4,'Planificación 2026-1'!G:G,"T1",'Planificación 2026-1'!H:H,"<3") -> 0 | DA4: =SUMIFS('Planificación 2026-1'!R:R,'Planificación 2026-1'!W:W,C4,'Planificación 2026-1'!G:G,"T3",'Planificación 2026-1'!H:H,"<3") -> 0 | DB4: =SUMIFS('Planificación 2026-1'!R:R,'Planificación 2026-1'!W:W,C4,'Planificación 2026-1'!G:G,"T2",'Planificación 2026-1'!H:H,"<3") -> 0 | DC4: =SUMIFS('Planificación 2026-1'!R:R,'Planificación 2026-1'!W:W,C4,'Planificación 2026-1'!G:G,"AE",'Planificación 2026-1'!H:H,"<3") -> 0 | DD4: =SUMIFS('Planificación 2026-1'!R:R,'Planificación 2026-1'!W:W,C4,'Planificación 2026-1'!G:G,"T4",'Planificación 2026-1'!H:H,"<3") -> 0 | DE4: =TRIM(CONCATENATE(I4,J4,K4,L4,M4,N4,O4,P4,Q4,R4,S4,T4,U4,V4,W4,X4,Y4)) -> P02 | DF4: =IF(C4="","",SUMIFS('Planificación 2026-1'!R:R,'Planificación 2026-1'!W:W,C4,'Planificación 2026-1'!E:E,"PRINCIPAL",'Planificación 2026-1'!X:X,"VIRTUAL")) -> 32 | DG4: =IF(C4="","",SUMIFS('Planificación 2026-1'!R:R,'Planificación 2026-1'!W:W,C4,'Planificación 2026-1'!E:E,"PRINCIPAL",'Planificación 2026-1'!X:X,"PRESENCIAL")) -> 0 | DH4: =IF(C4="","",SUMIFS('Planificación 2026-1'!R:R,'Planificación 2026-1'!W:W,C4,'Planificación 2026-1'!E:E,"PRINCIPAL",'Planificación 2026-1'!X:X,"HIBRIDO PRESENCIAL")) -> 0 | DI4: =TRIM(CONCATENATE(Z4,AA4,AB4,AC4,AD4,AE4,AF4,AG4,AH4,AI4,AJ4,AK4,AL4,AM4,AN4,AO4,AP4)) -> P02 | DJ4: =IF(C4="","",SUMIFS('Planificación 2026-1'!R:R,'Planificación 2026-1'!W:W,C4,'Planificación 2026-1'!E:E,"FILIAL",'Planificación 2026-1'!X:X,"VIRTUAL")) -> 8 | DK4: =IF(C4="","",SUMIFS('Planificación 2026-1'!R:R,'Planificación 2026-1'!W:W,C4,'Planificación 2026-1'!E:E,"FILIAL",'Planificación 2026-1'!X:X,"PRESENCIAL")) -> 0 | DL4: =IF(C4="","",SUMIFS('Planificación 2026-1'!R:R,'Planificación 2026-1'!W:W,C4,'Planificación 2026-1'!E:E,"FILIAL",'Planificación 2026-1'!X:X,"HIBRIDO PRESENCIAL")) -> 0 | DM4: =TRIM(CONCATENATE(AQ4,AR4,AS4,AT4,AU4,AV4,AW4,AX4,AY4,AZ4,BA4,BB4,BC4,BD4,BE4,BF4,BG4)) | DN4: =IF(C4="","",SUMIFS('Planificación 2026-1'!R:R,'Planificación 2026-1'!W:W,C4,'Planificación 2026-1'!E:E,"SUNAMPE",'Planificación 2026-1'!X:X,"VIRTUAL")) -> 0 | DO4: =IF(C4="","",SUMIFS('Planificación 2026-1'!R:R,'Planificación 2026-1'!W:W,C4,'Planificación 2026-1'!E:E,"SUNAMPE",'Planificación 2026-1'!X:X,"PRESENCIAL")) -> 0 | DP4: =TRIM(CONCATENATE(BH4,BI4,BJ4,BK4,BL4,BM4,BN4,BO4,BP4,BQ4,BR4,BS4,BT4,BU4,BV4,BW4,BX4)) | DQ4: =IF(C4="","",SUMIFS('Planificación 2026-1'!R:R,'Planificación 2026-1'!W:W,C4,'Planificación 2026-1'!E:E,"HUAURA",'Planificación 2026-1'!X:X,"VIRTUAL")) -> 0 | DR4: =IF(C4="","",SUMIFS('Planificación 2026-1'!R:R,'Planificación 2026-1'!W:W,C4,'Planificación 2026-1'!E:E,"HUAURA",'Planificación 2026-1'!X:X,"PRESENCIAL")) -> 0 | DS4: =SUMIFS('Planificación 2026-1'!R:R,'Planificación 2026-1'!W:W,C4,'Planificación 2026-1'!E:E,"PRINCIPAL",'Planificación 2026-1'!X:X,"VIRTUAL",'Planificación 2026-1'!H:H,">2") -> 32 | DT4: =SUMIFS('Planificación 2026-1'!R:R,'Planificación 2026-1'!W:W,C4,'Planificación 2026-1'!E:E,"PRINCIPAL",'Planificación 2026-1'!X:X,"<>VIRTUAL",'Planificación 2026-1'!H:H,">2") -> 0 | DU4: =SUMIFS('Planificación 2026-1'!R:R,'Planificación 2026-1'!W:W,C4,'Planificación 2026-1'!E:E,"SUNAMPE",'Planificación 2026-1'!X:X,"VIRTUAL",'Planificación 2026-1'!H:H,">2") -> 0 | DV4: =SUMIFS('Planificación 2026-1'!R:R,'Planificación 2026-1'!W:W,C4,'Planificación 2026-1'!E:E,"SUNAMPE",'Planificación 2026-1'!X:X,"<>VIRTUAL",'Planificación 2026-1'!H:H,">2") -> 0 | DW4: =SUMIFS('Planificación 2026-1'!R:R,'Planificación 2026-1'!W:W,C4,'Planificación 2026-1'!E:E,"FILIAL",'Planificación 2026-1'!X:X,"VIRTUAL",'Planificación 2026-1'!H:H,">2") -> 8 | DX4: =SUMIFS('Planificación 2026-1'!R:R,'Planificación 2026-1'!W:W,C4,'Planificación 2026-1'!E:E,"FILIAL",'Planificación 2026-1'!X:X,"<>VIRTUAL",'Planificación 2026-1'!H:H,">2") -> 0 | DY4: =SUMIFS('Planificación 2026-1'!R:R,'Planificación 2026-1'!W:W,C4,'Planificación 2026-1'!E:E,"PORUMA",'Planificación 2026-1'!X:X,"VIRTUAL",'Planificación 2026-1'!H:H,">2") -> 0 | DZ4: =SUMIFS('Planificación 2026-1'!R:R,'Planificación 2026-1'!W:W,C4,'Planificación 2026-1'!E:E,"PORUMA",'Planificación 2026-1'!X:X,"<>VIRTUAL",'Planificación 2026-1'!H:H,">2") -> 0 | EA4: =SUMIFS('Planificación 2026-1'!R:R,'Planificación 2026-1'!W:W,C4,'Planificación 2026-1'!E:E,"HUAURA",'Planificación 2026-1'!X:X,"VIRTUAL",'Planificación 2026-1'!H:H,">2") -> 0 | EB4: =SUMIFS('Planificación 2026-1'!R:R,'Planificación 2026-1'!W:W,C4,'Planificación 2026-1'!E:E,"HUAURA",'Planificación 2026-1'!X:X,"<>VIRTUAL",'Planificación 2026-1'!H:H,">2") -> 0 | EC4: =SUMIFS('Planificación 2026-1'!R:R,'Planificación 2026-1'!W:W,C4,'Planificación 2026-1'!E:E,"PRINCIPAL",'Planificación 2026-1'!X:X,"VIRTUAL",'Planificación 2026-1'!H:H,"<3") -> 0 | ED4: =SUMIFS('Planificación 2026-1'!R:R,'Planificación 2026-1'!W:W,C4,'Planificación 2026-1'!E:E,"PRINCIPAL",'Planificación 2026-1'!X:X,"<>VIRTUAL",'Planificación 2026-1'!H:H,"<3") -> 0 | EE4: =SUMIFS('Planificación 2026-1'!R:R,'Planificación 2026-1'!W:W,C4,'Planificación 2026-1'!E:E,"SUNAMPE",'Planificación 2026-1'!X:X,"VIRTUAL",'Planificación 2026-1'!H:H,"<3") -> 0 | EF4: =SUMIFS('Planificación 2026-1'!R:R,'Planificación 2026-1'!W:W,C4,'Planificación 2026-1'!E:E,"SUNAMPE",'Planificación 2026-1'!X:X,"<>VIRTUAL",'Planificación 2026-1'!H:H,"<3") -> 0 | EG4: =SUMIFS('Planificación 2026-1'!R:R,'Planificación 2026-1'!W:W,C4,'Planificación 2026-1'!E:E,"FILIAL",'Planificación 2026-1'!X:X,"VIRTUAL",'Planificación 2026-1'!H:H,"<3") -> 0 | EH4: =SUMIFS('Planificación 2026-1'!R:R,'Planificación 2026-1'!W:W,C4,'Planificación 2026-1'!E:E,"FILIAL",'Planificación 2026-1'!X:X,"<>VIRTUAL",'Planificación 2026-1'!H:H,"<3") -> 0 | EI4: =SUMIFS('Planificación 2026-1'!R:R,'Planificación 2026-1'!W:W,C4,'Planificación 2026-1'!E:E,"PORUMA",'Planificación 2026-1'!X:X,"VIRTUAL",'Planificación 2026-1'!H:H,"<3") -> 0 | EJ4: =SUMIFS('Planificación 2026-1'!R:R,'Planificación 2026-1'!W:W,C4,'Planificación 2026-1'!E:E,"PORUMA",'Planificación 2026-1'!X:X,"<>VIRTUAL",'Planificación 2026-1'!H:H,"<3") -> 0 | EK4: =SUMIFS('Planificación 2026-1'!R:R,'Planificación 2026-1'!W:W,C4,'Planificación 2026-1'!E:E,"HUAURA",'Planificación 2026-1'!X:X,"VIRTUAL",'Planificación 2026-1'!H:H,"<3") -> 0 | EL4: =SUMIFS('Planificación 2026-1'!R:R,'Planificación 2026-1'!W:W,C4,'Planificación 2026-1'!E:E,"HUAURA",'Planificación 2026-1'!X:X,"<>VIRTUAL",'Planificación 2026-1'!H:H,"<3") -> 0 | EM4: =EG4+DW4+DX4+EH4 -> 8 | EN4: =EL4+EK4+EB4+EA4 -> 0 | EO4: =EI4+EJ4+DZ4+DY4 -> 0 | EP4: =ED4+EC4+DT4+DS4 -> 32 | EQ4: =EF4+EE4+DV4+DU4 -> 0 | ES4: =DS4+DW4+EA4+EC4+EG4+EK4+DU4+EE4 -> 40 | ET4: =DT4+DX4+EB4+ED4+EH4+EL4+DV4+EF4 -> 0 | EU4: =EXACT(SUM(ES4:ET4),D4) -> TRUE | EV4: =IF(AND(DT4=0,DX4=0,EB4=0),"",IF(COUNTIF(DS4:EB4,">0")=1,IF(DT4+DS4>0,"SEDE",IF(DX4+DW4>0,"FILIAL","HUAURA")),IF(COUNTIF(DS4:EB4,">0")=2,IF(AND(DT4+DS4>0,DX4+DW4>0),"SEDE-FILIAL",IF(AND(DT4>0,EB4>0),"SEDE-HUAURA","FILIAL-HUAURA")),"SEDE-FILIAL-HUAURA"))) | EW4: =IF(ES4=0,"PRESENCIAL",IF(ET4=0,"VIRTUAL",IF(ES4>ET4,"MAS VIRTUAL",IF(ET4>ES4,"MAS PRESENCIAL","AMBOS")))) -> VIRTUAL
